Workbook

Sheet AMAN
B4: MATIERES | C4: Annuel | D4: TRIM 1 | E4: TRIM 2 | F4: TRIM 3 | G4: Coef | H4: Moy × Coef | I4: Moy Gle Classe | K4: Rang | L4: Appréciations
B5: Allemand | C5: =F5 -> 10 | F5: 10 | G5: 2 | H5: =C5*G5 -> 20 | L5: =IF(C5<11,"NA",IF(C5<15,"ECA",IF(C5<18,"A",IF(C5<20,"A+")))) -> NA | O5: =D5*G5 -> 0 | P5: =E5*G5 -> 0 | Q5: =G5*F5 -> 20
B6: Anglais | C6: =(D6+F6+E6)/3 -> 6.6 | D6: 6.55 | E6: 7.5 | F6: 5.75 | G6: 3 | H6: =C6*G6 -> 19.8 | L6: =IF(C6<11,"NA",IF(C6<15,"ECA",IF(C6<18,"A",IF(C6<20,"A+")))) -> NA | O6: =D6*G6 -> 19.65 | P6: =E6*G6 -> 22.5 | Q6: =G6*F6 -> 17.25
B7: Cor Orthographique/ Dictée | C7: =(D7+F7+E7)/3 -> 6.0083333 | D7: 7.6 | E7: 5.8 | F7: 4.625 | G7: 1 | H7: =C7*G7 -> 6.0083333 | L7: =IF(C7<11,"NA",IF(C7<15,"ECA",IF(C7<18,"A",IF(C7<20,"A+")))) -> NA | O7: =D7*G7 -> 7.6 | P7: =E7*G7 -> 5.8 | Q7: =G7*F7 -> 4.625
B8: Espagnol | C8: =F8 -> 15 | F8: 15 | G8: 2 | H8: =C8*G8 -> 30 | L8: =IF(C8<11,"NA",IF(C8<15,"ECA",IF(C8<18,"A",IF(C8<20,"A+")))) -> A | O8: =D8*G8 -> 0 | P8: =E8*G8 -> 0 | Q8: =G8*F8 -> 30
B9: Etude de Texte | C9: =(D9+F9+E9)/3 -> 8.6883333 | D9: 9.6 | E9: 9.215 | F9: 7.25 | G9: 2 | H9: =C9*G9 -> 17.376667 | L9: =IF(C9<11,"NA",IF(C9<15,"ECA",IF(C9<18,"A",IF(C9<20,"A+")))) -> NA | O9: =D9*G9 -> 19.2 | P9: =E9*G9 -> 18.43 | Q9: =G9*F9 -> 14.5
B10: Expression Ecrite | C10: =(D10+F10+E10)/3 -> 9.3883333 | D10: 8 | E10: 10.665 | F10: 9.5 | G10: 1 | H10: =C10*G10 -> 9.3883333 | L10: =IF(C10<11,"NA",IF(C10<15,"ECA",IF(C10<18,"A",IF(C10<20,"A+")))) -> NA | O10: =D10*G10 -> 8 | P10: =E10*G10 -> 10.665 | Q10: =G10*F10 -> 9.5
B11: Total du GROUPE I :
B12: Moyenne du Groupe : | C12: =(SUM(H5:H10)/SUM(G5:G10)) -> 9.3248485 | G12: Rang de l’élève :
B14: ECM | C14: =(D14+F14+E14)/3 -> 11.166667 | D14: 11.1 | E14: 11.4 | F14: 11 | G14: 2 | H14: =C14*G14 -> 22.333333 | L14: =IF(C14<11,"NA",IF(C14<15,"ECA",IF(C14<18,"A",IF(C14<20,"A+")))) -> ECA | O14: =D14*G14 -> 22.2 | P14: =E14*G14 -> 22.8 | Q14: =G14*F14 -> 22
B15: Géographie | C15: =(D15+F15+E15)/3 -> 11.166667 | D15: 8.75 | E15: 13.5 | F15: 11.25 | G15: 1.5 | H15: =C15*G15 -> 16.75 | L15: =IF(C15<11,"NA",IF(C15<15,"ECA",IF(C15<18,"A",IF(C15<20,"A+")))) -> ECA | O15: =D15*G15 -> 13.125 | P15: =E15*G15 -> 20.25 | Q15: =G15*F15 -> 16.875
B16: Histoire | C16: =(D16+F16+E16)/3 -> 9.0916667 | D16: 8.275 | E16: 9.125 | F16: 9.875 | G16: 1.5 | H16: =C16*G16 -> 13.6375 | L16: =IF(C16<11,"NA",IF(C16<15,"ECA",IF(C16<18,"A",IF(C16<20,"A+")))) -> NA | O16: =D16*G16 -> 12.4125 | P16: =E16*G16 -> 13.6875 | Q16: =G16*F16 -> 14.8125
B17: LCN | C17: =(D17+F17+E17)/3 -> 7.3166667 | D17: 7.45 | E17: 7.5 | F17: 7 | G17: 1 | H17: =C17*G17 -> 7.3166667 | L17: =IF(C17<11,"NA",IF(C17<15,"ECA",IF(C17<18,"A",IF(C17<20,"A+")))) -> NA | O17: =D17*G17 -> 7.45 | P17: =E17*G17 -> 7.5 | Q17: =G17*F17 -> 7
B18: Total du GROUPE II :
B19: Moyenne du Groupe : | C19: =(SUM(H14:H17)/SUM(G14:G17)) -> 10.00625 | G19: Rang de l’élève :
B21: Informatique | C21: =(D21+F21+E21)/3 -> 5.5833333 | D21: 8.625 | E21: =(F21+G21)/2 -> 3.375 | F21: 4.75 | G21: 2 | H21: =C21*G21 -> 11.166667 | L21: =IF(C21<11,"NA",IF(C21<15,"ECA",IF(C21<18,"A",IF(C21<20,"A+")))) -> NA | O21: =D21*G21 -> 17.25 | P21: =E21*G21 -> 6.75 | Q21: =G21*F21 -> 9.5
B22: Mathématiques | C22: =(D22+F22+E22)/3 -> 8.3833333 | D22: 7.7 | E22: =(F22+G22)/2 -> 7.15 | F22: 10.3 | G22: 4 | H22: =C22*G22 -> 33.533333 | L22: =IF(C22<11,"NA",IF(C22<15,"ECA",IF(C22<18,"A",IF(C22<20,"A+")))) -> NA | O22: =D22*G22 -> 30.8 | P22: =E22*G22 -> 28.6 | Q22: =G22*F22 -> 41.2
B23: PCT | C23: =F23 -> 12 | F23: 12 | G23: 2 | H23: =C23*G23 -> 24 | L23: =IF(C23<11,"NA",IF(C23<15,"ECA",IF(C23<18,"A",IF(C23<20,"A+")))) -> ECA | O23: =D23*G23 -> 0 | P23: =E23*G23 -> 0 | Q23: =G23*F23 -> 24
B24: SVTEEHB | C24: =(D24+F24+E24)/3 -> 10.366667 | D24: 9.1 | E24: 8.75 | F24: 13.25 | G24: 2 | H24: =C24*G24 -> 20.733333 | L24: =IF(C24<11,"NA",IF(C24<15,"ECA",IF(C24<18,"A",IF(C24<20,"A+")))) -> NA | O24: =D24*G24 -> 18.2 | P24: =E24*G24 -> 17.5 | Q24: =G24*F24 -> 26.5
B25: Total du GROUPE III :
B26: Moyenne du Groupe : | C26: =(SUM(H21:H24)/SUM(G21:G24)) -> 8.9433333 | G26: Rang de l’élève :
B28: EAC | C28: =(D28+F28+E28)/3 -> 14.166667 | D28: 15.5 | E28: 14 | F28: 13 | G28: 1 | H28: =C28*G28 -> 14.166667 | L28: =IF(C28<11,"NA",IF(C28<15,"ECA",IF(C28<18,"A",IF(C28<20,"A+")))) -> ECA | O28: =D28*G28 -> 15.5 | P28: =E28*G28 -> 14 | Q28: =G28*F28 -> 13
B29: EPS | C29: =(D29+F29+E29)/3 -> 14.2 | D29: 13.3 | E29: 14.5 | F29: 14.8 | G29: 2 | H29: =C29*G29 -> 28.4 | L29: =IF(C29<11,"NA",IF(C29<15,"ECA",IF(C29<18,"A",IF(C29<20,"A+")))) -> ECA | O29: =D29*G29 -> 26.6 | P29: =E29*G29 -> 29 | Q29: =G29*F29 -> 29.6
B30: ESF | C30: =(D30+F30+E30)/3 -> 12.9 | D30: 13 | E30: 11.7 | F30: 14 | G30: 1 | H30: =C30*G30 -> 12.9 | L30: =IF(C30<11,"NA",IF(C30<15,"ECA",IF(C30<18,"A",IF(C30<20,"A+")))) -> ECA | O30: =D30*G30 -> 13 | P30: =E30*G30 -> 11.7 | Q30: =G30*F30 -> 14
B31: Travail Manuel | C31: =(D31+F31+E31)/3 -> 15.833333 | D31: 16.5 | E31: 16 | F31: 15 | G31: 1 | H31: =C31*G31 -> 15.833333 | L31: =IF(C31<11,"NA",IF(C31<15,"ECA",IF(C31<18,"A",IF(C31<20,"A+")))) -> A | O31: =D31*G31 -> 16.5 | P31: =E31*G31 -> 16 | Q31: =G31*F31 -> 15
B32: Total du GROUPE IV : | O32: =SUM(O6:O31) -> 247.4875 | P32: =SUM(P6:P31) -> 245.1825 | Q32: =SUM(Q5:Q31) -> 329.3625
B33: Moyenne du Groupe : | C33: =(SUM(H28:H31)/SUM(G28:G31)) -> 14.26 | G33: Rang de l’élève : | O33: 26 | P33: 26 | Q33: 32
O34: =O32/O33 -> 9.51875 | P34: =P32/P33 -> 9.4300962 | Q34: =Q32/Q33 -> 10.292578
B35: Total Général (GI + GII + GIII+GIV) = | C35: Moy Gle de la Classe : | F35: Moy du 1er : | I35: Moy du Dernier :
C36: TRIM 1 | D36: TRIM 2 | E36: TRIM3
B37: Moyennes de l’Elève : | C37: =O34 -> 9.51875 | D37: =P34 -> 9.4300962 | E37: =Q34 -> 10.292578 | F37: Annuel : | G37: =(H5+H6+H7+H8+H9+H10+H14+H15+H16+H17+H21+H22+H23+H24+H28+H29+H30+H31)/32 -> 10.104505 | H37: /20 | I37: Rang de l’élève : | L37: /20
B39: v La moyenne Annuelle n’est pas égale à la moyenne arithmétique des trimestres
B40: DECISIONS ET OBSERVATIONS / Décisions And Observations
B41: DISCIPLINE / Disciplin | C41: Appréciation du travail de l’élève | G41: TRAVAIL / Academic Work
B42: Nb d’Heures : | C42: =IF(G37<11,"NA",IF(G37<15,"ECA",IF(G37<18,"A",IF(G37<20,"A+")))) -> NA | D42: =IF(#REF!<11,"NA",IF(#REF!<15,"ECA",IF(#REF!<18,"A",IF(#REF!<20,"A+")))) -> #REF! | F42: =IF(#REF!<11,"NA",IF(#REF!<15,"ECA",IF(#REF!<18,"A",IF(#REF!<20,"A+")))) -> #REF!
B43: Nb de jrnées : | C43: =IF(#REF!<11,"NA",IF(#REF!<15,"ECA",IF(#REF!<18,"A",IF(#REF!<20,"A+")))) -> #REF! | D43: =IF(#REF!<11,"NA",IF(#REF!<15,"ECA",IF(#REF!<18,"A",IF(#REF!<20,"A+")))) -> #REF! | F43: =IF(#REF!<11,"NA",IF(#REF!<15,"ECA",IF(#REF!<18,"A",IF(#REF!<20,"A+")))) -> #REF! | G43: Tableau d’honneur / Honour roll | K43: Observations et Visa du Principal
B44: Exclusions / Suspensions | C44: =IF(#REF!<11,"NA",IF(#REF!<15,"ECA",IF(#REF!<18,"A",IF(#REF!<20,"A+")))) -> #REF! | D44: =IF(#REF!<11,"NA",IF(#REF!<15,"ECA",IF(#REF!<18,"A",IF(#REF!<20,"A+")))) -> #REF! | F44: =IF(#REF!<11,"NA",IF(#REF!<15,"ECA",IF(#REF!<18,"A",IF(#REF!<20,"A+")))) -> #REF! | G44: Encouragements / Encouragements | K44: Observations and Signature of Principal
B45: Blâme / Blame | C45: Observations et Remarques du Professeur Principal | G45: Félicitations / Congratulations
B46: Avertissements / Warnings | G46: Décisions du Conseil de Classe | K46: Yaoundé le
B47: Observations et Remarques du parent de l’élève | K47: Le Principal

Sheet DJIKIA
B4: MATIERES | C4: Annuel | D4: TRIM 1 | E4: TRIM 2 | F4: TRIM 3 | G4: Coef | H4: Moy × Coef | I4: Moy Gle Classe | K4: Rang | L4: Appréciations
B5: Allemand | C5: =F5 -> 6.5 | F5: 6.5 | G5: 2 | H5: =C5*G5 -> 13 | L5: =IF(C5<11,"NA",IF(C5<15,"ECA",IF(C5<18,"A",IF(C5<20,"A+")))) -> NA | O5: =D5*G5 -> 0 | P5: =E5*G5 -> 0 | Q5: =G5*F5 -> 13
B6: Anglais | C6: =(D6+F6+E6)/3 -> 5.1166667 | D6: 3.9 | E6: 5.45 | F6: 6 | G6: 3 | H6: =C6*G6 -> 15.35 | L6: =IF(C6<11,"NA",IF(C6<15,"ECA",IF(C6<18,"A",IF(C6<20,"A+")))) -> NA | O6: =D6*G6 -> 11.7 | P6: =E6*G6 -> 16.35 | Q6: =G6*F6 -> 18
B7: Cor Orthographique/ Dictée | C7: =(D7+F7+E7)/3 -> 3.4833333 | D7: 5.7 | E7: 2.75 | F7: 2 | G7: 1 | H7: =C7*G7 -> 3.4833333 | L7: =IF(C7<11,"NA",IF(C7<15,"ECA",IF(C7<18,"A",IF(C7<20,"A+")))) -> NA | O7: =D7*G7 -> 5.7 | P7: =E7*G7 -> 2.75 | Q7: =G7*F7 -> 2
B8: Espagnol | C8: =F8 -> 13.25 | F8: 13.25 | G8: 2 | H8: =C8*G8 -> 26.5 | L8: =IF(C8<11,"NA",IF(C8<15,"ECA",IF(C8<18,"A",IF(C8<20,"A+")))) -> ECA | O8: =D8*G8 -> 0 | P8: =E8*G8 -> 0 | Q8: =G8*F8 -> 26.5
B9: Etude de Texte | C9: =(D9+F9+E9)/3 -> 5.1716667 | D9: 2.75 | E9: 8.765 | F9: 4 | G9: 2 | H9: =C9*G9 -> 10.343333 | L9: =IF(C9<11,"NA",IF(C9<15,"ECA",IF(C9<18,"A",IF(C9<20,"A+")))) -> NA | O9: =D9*G9 -> 5.5 | P9: =E9*G9 -> 17.53 | Q9: =G9*F9 -> 8
B10: Expression Ecrite | C10: =(D10+F10+E10)/3 -> 7.7883333 | D10: 4 | E10: 13.365 | F10: 6 | G10: 1 | H10: =C10*G10 -> 7.7883333 | L10: =IF(C10<11,"NA",IF(C10<15,"ECA",IF(C10<18,"A",IF(C10<20,"A+")))) -> NA | O10: =D10*G10 -> 4 | P10: =E10*G10 -> 13.365 | Q10: =G10*F10 -> 6
B11: Total du GROUPE I :
B12: Moyenne du Groupe : | C12: =(SUM(H5:H10)/SUM(G5:G10)) -> 6.9513636 | G12: Rang de l’élève :
B14: ECM | C14: =(D14+F14+E14)/3 -> 7.25 | D14: 6.4 | E14: 6.35 | F14: 9 | G14: 2 | H14: =C14*G14 -> 14.5 | L14: =IF(C14<11,"NA",IF(C14<15,"ECA",IF(C14<18,"A",IF(C14<20,"A+")))) -> NA | O14: =D14*G14 -> 12.8 | P14: =E14*G14 -> 12.7 | Q14: =G14*F14 -> 18
B15: Géographie | C15: =(D15+F15+E15)/3 -> 7.4416667 | D15: 4 | E15: 10.075 | F15: 8.25 | G15: 1.5 | H15: =C15*G15 -> 11.1625 | L15: =IF(C15<11,"NA",IF(C15<15,"ECA",IF(C15<18,"A",IF(C15<20,"A+")))) -> NA | O15: =D15*G15 -> 6 | P15: =E15*G15 -> 15.1125 | Q15: =G15*F15 -> 12.375
B16: Histoire | C16: =(D16+F16+E16)/3 -> 7.125 | D16: 6.275 | E16: 7.35 | F16: 7.75 | G16: 1.5 | H16: =C16*G16 -> 10.6875 | L16: =IF(C16<11,"NA",IF(C16<15,"ECA",IF(C16<18,"A",IF(C16<20,"A+")))) -> NA | O16: =D16*G16 -> 9.4125 | P16: =E16*G16 -> 11.025 | Q16: =G16*F16 -> 11.625
B17: LCN | C17: =(D17+F17+E17)/3 -> 10.4 | D17: 6.7 | E17: 10.5 | F17: 14 | G17: 1 | H17: =C17*G17 -> 10.4 | L17: =IF(C17<11,"NA",IF(C17<15,"ECA",IF(C17<18,"A",IF(C17<20,"A+")))) -> NA | O17: =D17*G17 -> 6.7 | P17: =E17*G17 -> 10.5 | Q17: =G17*F17 -> 14
B18: Total du GROUPE II :
B19: Moyenne du Groupe : | C19: =(SUM(H14:H17)/SUM(G14:G17)) -> 7.7916667 | G19: Rang de l’élève :
B21: Informatique | C21: =(D21+F21+E21)/3 -> 3.3583333 | D21: 3.125 | E21: 2.95 | F21: 4 | G21: 2 | H21: =C21*G21 -> 6.7166667 | L21: =IF(C21<11,"NA",IF(C21<15,"ECA",IF(C21<18,"A",IF(C21<20,"A+")))) -> NA | O21: =D21*G21 -> 6.25 | P21: =E21*G21 -> 5.9 | Q21: =G21*F21 -> 8
B22: Mathématiques | C22: =(D22+F22+E22)/3 -> 8.0783333 | D22: 6.35 | E22: 6.385 | F22: 11.5 | G22: 4 | H22: =C22*G22 -> 32.313333 | L22: =IF(C22<11,"NA",IF(C22<15,"ECA",IF(C22<18,"A",IF(C22<20,"A+")))) -> NA | O22: =D22*G22 -> 25.4 | P22: =E22*G22 -> 25.54 | Q22: =G22*F22 -> 46
B23: PCT | C23: =F23 -> 9 | F23: 9 | G23: 2 | H23: =C23*G23 -> 18 | L23: =IF(C23<11,"NA",IF(C23<15,"ECA",IF(C23<18,"A",IF(C23<20,"A+")))) -> NA | O23: =D23*G23 -> 0 | P23: =E23*G23 -> 0 | Q23: =G23*F23 -> 18
B24: SVTEEHB | C24: =(D24+F24+E24)/3 -> 6.56 | D24: 5.45 | E24: 3.73 | F24: 10.5 | G24: 2 | H24: =C24*G24 -> 13.12 | L24: =IF(C24<11,"NA",IF(C24<15,"ECA",IF(C24<18,"A",IF(C24<20,"A+")))) -> NA | O24: =D24*G24 -> 10.9 | P24: =E24*G24 -> 7.46 | Q24: =G24*F24 -> 21
B25: Total du GROUPE III :
B26: Moyenne du Groupe : | C26: =(SUM(H21:H24)/SUM(G21:G24)) -> 7.015 | G26: Rang de l’élève :
B28: EAC | C28: =(D28+F28+E28)/2 -> 14.5 | D28: 15.5 | E28: 13.5 | F28: 0 | G28: 1 | H28: =C28*G28 -> 14.5 | L28: =IF(C28<11,"NA",IF(C28<15,"ECA",IF(C28<18,"A",IF(C28<20,"A+")))) -> ECA | O28: =D28*G28 -> 15.5 | P28: =E28*G28 -> 13.5 | Q28: =G28*F28 -> 0
B29: EPS | C29: =(D29+F29+E29)/3 -> 12.75 | D29: 13.45 | E29: 14.8 | F29: 10 | G29: 2 | H29: =C29*G29 -> 25.5 | L29: =IF(C29<11,"NA",IF(C29<15,"ECA",IF(C29<18,"A",IF(C29<20,"A+")))) -> ECA | O29: =D29*G29 -> 26.9 | P29: =E29*G29 -> 29.6 | Q29: =G29*F29 -> 20
B30: ESF | C30: =(D30+F30+E30)/2 -> 10.25 | D30: 12.5 | E30: 8 | F30: 0 | G30: 1 | H30: =C30*G30 -> 10.25 | L30: =IF(C30<11,"NA",IF(C30<15,"ECA",IF(C30<18,"A",IF(C30<20,"A+")))) -> NA | O30: =D30*G30 -> 12.5 | P30: =E30*G30 -> 8 | Q30: =G30*F30 -> 0
B31: Travail Manuel | C31: =(D31+F31+E31)/3 -> 16.166667 | D31: 16.5 | E31: 16 | F31: 16 | G31: 1 | H31: =C31*G31 -> 16.166667 | L31: =IF(C31<11,"NA",IF(C31<15,"ECA",IF(C31<18,"A",IF(C31<20,"A+")))) -> A | O31: =D31*G31 -> 16.5 | P31: =E31*G31 -> 16 | Q31: =G31*F31 -> 16
B32: Total du GROUPE IV : | O32: =SUM(O6:O31) -> 175.7625 | P32: =SUM(P6:P31) -> 205.3325 | Q32: =SUM(Q5:Q31) -> 258.5
B33: Moyenne du Groupe : | C33: =(SUM(H28:H31)/SUM(G28:G31)) -> 13.283333 | G33: Rang de l’élève : | O33: 26 | P33: 26 | Q33: 30
O34: =O32/O33 -> 6.7600962 | P34: =P32/P33 -> 7.8974038 | Q34: =Q32/Q33 -> 8.6166667
B35: Total Général (GI + GII + GIII+GIV) = | C35: Moy Gle de la Classe : | F35: Moy du 1er : | I35: Moy du Dernier :
C36: TRIM 1 | D36: TRIM 2 | E36: TRIM3
B37: Moyennes de l’Elève : | C37: =O34 -> 6.7600962 | D37: =P34 -> 7.8974038 | E37: =Q34 -> 8.6166667 | F37: Annuel : | G37: =(H5+H6+H7+H8+H9+H10+H14+H15+H16+H17+H21+H22+H23+H24+H28+H29+H30+H31)/32 -> 8.1181771 | H37: /20 | I37: Rang de l’élève : | L37: /20
B39: v La moyenne Annuelle n’est pas égale à la moyenne arithmétique des trimestres
B40: DECISIONS ET OBSERVATIONS / Décisions And Observations
B41: DISCIPLINE / Disciplin | C41: Appréciation du travail de l’élève | G41: TRAVAIL / Academic Work
B42: Nb d’Heures : | C42: =IF(G37<11,"NA",IF(G37<15,"ECA",IF(G37<18,"A",IF(G37<20,"A+")))) -> NA | D42: =IF(#REF!<11,"NA",IF(#REF!<15,"ECA",IF(#REF!<18,"A",IF(#REF!<20,"A+")))) -> #REF! | F42: =IF(#REF!<11,"NA",IF(#REF!<15,"ECA",IF(#REF!<18,"A",IF(#REF!<20,"A+")))) -> #REF!
B43: Nb de jrnées : | C43: =IF(#REF!<11,"NA",IF(#REF!<15,"ECA",IF(#REF!<18,"A",IF(#REF!<20,"A+")))) -> #REF! | D43: =IF(#REF!<11,"NA",IF(#REF!<15,"ECA",IF(#REF!<18,"A",IF(#REF!<20,"A+")))) -> #REF! | F43: =IF(#REF!<11,"NA",IF(#REF!<15,"ECA",IF(#REF!<18,"A",IF(#REF!<20,"A+")))) -> #REF! | G43: Tableau d’honneur / Honour roll | K43: Observations et Visa du Principal
B44: Exclusions / Suspensions | C44: =IF(#REF!<11,"NA",IF(#REF!<15,"ECA",IF(#REF!<18,"A",IF(#REF!<20,"A+")))) -> #REF! | D44: =IF(#REF!<11,"NA",IF(#REF!<15,"ECA",IF(#REF!<18,"A",IF(#REF!<20,"A+")))) -> #REF! | F44: =IF(#REF!<11,"NA",IF(#REF!<15,"ECA",IF(#REF!<18,"A",IF(#REF!<20,"A+")))) -> #REF! | G44: Encouragements / Encouragements | K44: Observations and Signature of Principal
B45: Blâme / Blame | C45: Observations et Remarques du Professeur Principal | G45: Félicitations / Congratulations
B46: Avertissements / Warnings | G46: Décisions du Conseil de Classe | K46: Yaoundé le
B47: Observations et Remarques du parent de l’élève | K47: Le Principal

Sheet ELOGO
B4: MATIERES | C4: Annuel | D4: TRIM 1 | E4: TRIM 2 | F4: TRIM 3 | G4: Coef | H4: Moy × Coef | I4: Moy Gle Classe | K4: Rang | L4: Appréciations
B5: Allemand | C5: =F5 -> 13 | F5: 13 | G5: 2 | H5: =C5*G5 -> 26 | L5: =IF(C5<11,"NA",IF(C5<15,"ECA",IF(C5<18,"A",IF(C5<20,"A+")))) -> ECA | O5: =D5*G5 -> 0 | P5: =E5*G5 -> 0 | Q5: =G5*F5 -> 26
B6: Anglais | C6: =(D6+F6+E6)/3 -> 13.266667 | D6: 12.8 | E6: 11.55 | F6: 15.45 | G6: 3 | H6: =C6*G6 -> 39.8 | L6: =IF(C6<11,"NA",IF(C6<15,"ECA",IF(C6<18,"A",IF(C6<20,"A+")))) -> ECA | O6: =D6*G6 -> 38.4 | P6: =E6*G6 -> 34.65 | Q6: =G6*F6 -> 46.35
B7: Cor Orthographique/ Dictée | C7: =(D7+F7+E7)/3 -> 7.525 | D7: 8.85 | E7: 5.85 | F7: 7.875 | G7: 1 | H7: =C7*G7 -> 7.525 | L7: =IF(C7<11,"NA",IF(C7<15,"ECA",IF(C7<18,"A",IF(C7<20,"A+")))) -> NA | O7: =D7*G7 -> 8.85 | P7: =E7*G7 -> 5.85 | Q7: =G7*F7 -> 7.875
B8: Espagnol | C8: =F8 -> 17 | F8: 17 | G8: 2 | H8: =C8*G8 -> 34 | L8: =IF(C8<11,"NA",IF(C8<15,"ECA",IF(C8<18,"A",IF(C8<20,"A+")))) -> A | O8: =D8*G8 -> 0 | P8: =E8*G8 -> 0 | Q8: =G8*F8 -> 34
B9: Etude de Texte | C9: =(D9+F9+E9)/3 -> 9.9216667 | D9: 10.5 | E9: 10.415 | F9: 8.85 | G9: 2 | H9: =C9*G9 -> 19.843333 | L9: =IF(C9<11,"NA",IF(C9<15,"ECA",IF(C9<18,"A",IF(C9<20,"A+")))) -> NA | O9: =D9*G9 -> 21 | P9: =E9*G9 -> 20.83 | Q9: =G9*F9 -> 17.7
B10: Expression Ecrite | C10: =(D10+F10+E10)/3 -> 11.183333 | D10: 12.05 | E10: 10.9 | F10: 10.6 | G10: 1 | H10: =C10*G10 -> 11.183333 | L10: =IF(C10<11,"NA",IF(C10<15,"ECA",IF(C10<18,"A",IF(C10<20,"A+")))) -> ECA | O10: =D10*G10 -> 12.05 | P10: =E10*G10 -> 10.9 | Q10: =G10*F10 -> 10.6
B11: Total du GROUPE I :
B12: Moyenne du Groupe : | C12: =(SUM(H5:H10)/SUM(G5:G10)) -> 12.577424 | G12: Rang de l’élève :
B14: ECM | C14: =(D14+F14+E14)/3 -> 15.783333 | D14: 16.15 | E14: 16.7 | F14: 14.5 | G14: 2 | H14: =C14*G14 -> 31.566667 | L14: =IF(C14<11,"NA",IF(C14<15,"ECA",IF(C14<18,"A",IF(C14<20,"A+")))) -> A | O14: =D14*G14 -> 32.3 | P14: =E14*G14 -> 33.4 | Q14: =G14*F14 -> 29
B15: Géographie | C15: =(D15+F15+E15)/3 -> 13.475 | D15: 12.125 | E15: 14.725 | F15: 13.575 | G15: 1.5 | H15: =C15*G15 -> 20.2125 | L15: =IF(C15<11,"NA",IF(C15<15,"ECA",IF(C15<18,"A",IF(C15<20,"A+")))) -> ECA | O15: =D15*G15 -> 18.1875 | P15: =E15*G15 -> 22.0875 | Q15: =G15*F15 -> 20.3625
B16: Histoire | C16: =(D16+F16+E16)/3 -> 13.341667 | D16: 12.675 | E16: 14.475 | F16: 12.875 | G16: 1.5 | H16: =C16*G16 -> 20.0125 | L16: =IF(C16<11,"NA",IF(C16<15,"ECA",IF(C16<18,"A",IF(C16<20,"A+")))) -> ECA | O16: =D16*G16 -> 19.0125 | P16: =E16*G16 -> 21.7125 | Q16: =G16*F16 -> 19.3125
B17: LCN | C17: =(D17+F17+E17)/3 -> 13.458333 | D17: 11.75 | E17: 14.25 | F17: 14.375 | G17: 1 | H17: =C17*G17 -> 13.458333 | L17: =IF(C17<11,"NA",IF(C17<15,"ECA",IF(C17<18,"A",IF(C17<20,"A+")))) -> ECA | O17: =D17*G17 -> 11.75 | P17: =E17*G17 -> 14.25 | Q17: =G17*F17 -> 14.375
B18: Total du GROUPE II :
B19: Moyenne du Groupe : | C19: =(SUM(H14:H17)/SUM(G14:G17)) -> 14.208333 | G19: Rang de l’élève :
B21: Informatique | C21: =(D21+F21+E21)/3 -> 13.675 | D21: 15.025 | E21: 12.4 | F21: 13.6 | G21: 2 | H21: =C21*G21 -> 27.35 | L21: =IF(C21<11,"NA",IF(C21<15,"ECA",IF(C21<18,"A",IF(C21<20,"A+")))) -> ECA | O21: =D21*G21 -> 30.05 | P21: =E21*G21 -> 24.8 | Q21: =G21*F21 -> 27.2
B22: Mathématiques | C22: =(D22+F22+E22)/3 -> 11.943333 | D22: 9.85 | E22: 12.38 | F22: 13.6 | G22: 4 | H22: =C22*G22 -> 47.773333 | L22: =IF(C22<11,"NA",IF(C22<15,"ECA",IF(C22<18,"A",IF(C22<20,"A+")))) -> ECA | O22: =D22*G22 -> 39.4 | P22: =E22*G22 -> 49.52 | Q22: =G22*F22 -> 54.4
B23: PCT | C23: =F23 -> 18 | F23: 18 | G23: 2 | H23: =C23*G23 -> 36 | L23: =IF(C23<11,"NA",IF(C23<15,"ECA",IF(C23<18,"A",IF(C23<20,"A+")))) -> A+ | O23: =D23*G23 -> 0 | P23: =E23*G23 -> 0 | Q23: =G23*F23 -> 36
B24: SVTEEHB | C24: =(D24+F24+E24)/3 -> 12.85 | D24: 12.35 | E24: 11.2 | F24: 15 | G24: 2 | H24: =C24*G24 -> 25.7 | L24: =IF(C24<11,"NA",IF(C24<15,"ECA",IF(C24<18,"A",IF(C24<20,"A+")))) -> ECA | O24: =D24*G24 -> 24.7 | P24: =E24*G24 -> 22.4 | Q24: =G24*F24 -> 30
B25: Total du GROUPE III :
B26: Moyenne du Groupe : | C26: =(SUM(H21:H24)/SUM(G21:G24)) -> 13.682333 | G26: Rang de l’élève :
B28: EAC | C28: =(D28+F28+E28)/3 -> 17.5 | D28: 18.5 | E28: 17 | F28: 17 | G28: 1 | H28: =C28*G28 -> 17.5 | L28: =IF(C28<11,"NA",IF(C28<15,"ECA",IF(C28<18,"A",IF(C28<20,"A+")))) -> A | O28: =D28*G28 -> 18.5 | P28: =E28*G28 -> 17 | Q28: =G28*F28 -> 17
B29: EPS | C29: =(D29+F29+E29)/3 -> 14.7 | D29: 13.9 | E29: 15.4 | F29: 14.8 | G29: 2 | H29: =C29*G29 -> 29.4 | L29: =IF(C29<11,"NA",IF(C29<15,"ECA",IF(C29<18,"A",IF(C29<20,"A+")))) -> ECA | O29: =D29*G29 -> 27.8 | P29: =E29*G29 -> 30.8 | Q29: =G29*F29 -> 29.6
B30: ESF | C30: =(D30+F30+E30)/3 -> 13.533333 | D30: 13 | E30: 13.6 | F30: 14 | G30: 1 | H30: =C30*G30 -> 13.533333 | L30: =IF(C30<11,"NA",IF(C30<15,"ECA",IF(C30<18,"A",IF(C30<20,"A+")))) -> ECA | O30: =D30*G30 -> 13 | P30: =E30*G30 -> 13.6 | Q30: =G30*F30 -> 14
B31: Travail Manuel | C31: =(D31+F31+E31)/3 -> 15.166667 | D31: 13 | E31: 16 | F31: 16.5 | G31: 1 | H31: =C31*G31 -> 15.166667 | L31: =IF(C31<11,"NA",IF(C31<15,"ECA",IF(C31<18,"A",IF(C31<20,"A+")))) -> A | O31: =D31*G31 -> 13 | P31: =E31*G31 -> 16 | Q31: =G31*F31 -> 16.5
B32: Total du GROUPE IV : | O32: =SUM(O6:O31) -> 328 | P32: =SUM(P6:P31) -> 337.8 | Q32: =SUM(Q5:Q31) -> 450.275
B33: Moyenne du Groupe : | C33: =(SUM(H28:H31)/SUM(G28:G31)) -> 15.12 | G33: Rang de l’élève : | O33: 26 | P33: 26 | Q33: 32
O34: =O32/O33 -> 12.615385 | P34: =P32/P33 -> 12.992308 | Q34: =Q32/Q33 -> 14.071094
B35: Total Général (GI + GII + GIII+GIV) = | C35: Moy Gle de la Classe : | F35: Moy du 1er : | I35: Moy du Dernier :
C36: TRIM 1 | D36: TRIM 2 | E36: TRIM3
B37: Moyennes de l’Elève : | C37: =O34 -> 12.615385 | D37: =P34 -> 12.992308 | E37: =Q34 -> 14.071094 | F37: Annuel : | G37: =(H5+H6+H7+H8+H9+H10+H14+H15+H16+H17+H21+H22+H23+H24+H28+H29+H30+H31)/32 -> 13.625781 | H37: /20 | I37: Rang de l’élève : | L37: /20
B39: v La moyenne Annuelle n’est pas égale à la moyenne arithmétique des trimestres
B40: DECISIONS ET OBSERVATIONS / Décisions And Observations
B41: DISCIPLINE / Disciplin | C41: Appréciation du travail de l’élève | G41: TRAVAIL / Academic Work
B42: Nb d’Heures : | C42: =IF(G37<11,"NA",IF(G37<15,"ECA",IF(G37<18,"A",IF(G37<20,"A+")))) -> ECA | D42: =IF(#REF!<11,"NA",IF(#REF!<15,"ECA",IF(#REF!<18,"A",IF(#REF!<20,"A+")))) -> #REF! | F42: =IF(#REF!<11,"NA",IF(#REF!<15,"ECA",IF(#REF!<18,"A",IF(#REF!<20,"A+")))) -> #REF!
B43: Nb de jrnées : | C43: =IF(#REF!<11,"NA",IF(#REF!<15,"ECA",IF(#REF!<18,"A",IF(#REF!<20,"A+")))) -> #REF! | D43: =IF(#REF!<11,"NA",IF(#REF!<15,"ECA",IF(#REF!<18,"A",IF(#REF!<20,"A+")))) -> #REF! | F43: =IF(#REF!<11,"NA",IF(#REF!<15,"ECA",IF(#REF!<18,"A",IF(#REF!<20,"A+")))) -> #REF! | G43: Tableau d’honneur / Honour roll | K43: Observations et Visa du Principal
B44: Exclusions / Suspensions | C44: =IF(#REF!<11,"NA",IF(#REF!<15,"ECA",IF(#REF!<18,"A",IF(#REF!<20,"A+")))) -> #REF! | D44: =IF(#REF!<11,"NA",IF(#REF!<15,"ECA",IF(#REF!<18,"A",IF(#REF!<20,"A+")))) -> #REF! | F44: =IF(#REF!<11,"NA",IF(#REF!<15,"ECA",IF(#REF!<18,"A",IF(#REF!<20,"A+")))) -> #REF! | G44: Encouragements / Encouragements | K44: Observations and Signature of Principal
B45: Blâme / Blame | C45: Observations et Remarques du Professeur Principal | G45: Félicitations / Congratulations
B46: Avertissements / Warnings | G46: Décisions du Conseil de Classe | K46: Yaoundé le
B47: Observations et Remarques du parent de l’élève | K47: Le Principal

Sheet KINGUE
B4: MATIERES | C4: Annuel | D4: TRIM 1 | E4: TRIM 2 | F4: TRIM 3 | G4: Coef | H4: Moy × Coef | I4: Moy Gle Classe | K4: Rang | L4: Appréciations
B5: Allemand | C5: =F5 -> 12.5 | F5: 12.5 | G5: 2 | H5: =C5*G5 -> 25 | L5: =IF(C5<11,"NA",IF(C5<15,"ECA",IF(C5<18,"A",IF(C5<20,"A+")))) -> ECA | O5: =D5*G5 -> 0 | P5: =E5*G5 -> 0 | Q5: =G5*F5 -> 25
B6: Anglais | C6: =(D6+F6+E6)/3 -> 12.008333 | D6: 10.75 | E6: 11.5 | F6: 13.775 | G6: 3 | H6: =C6*G6 -> 36.025 | L6: =IF(C6<11,"NA",IF(C6<15,"ECA",IF(C6<18,"A",IF(C6<20,"A+")))) -> ECA | O6: =D6*G6 -> 32.25 | P6: =E6*G6 -> 34.5 | Q6: =G6*F6 -> 41.325
B7: Cor Orthographique/ Dictée | C7: =(D7+F7+E7)/3 -> 13.908333 | D7: 14.5 | E7: 12.6 | F7: 14.625 | G7: 1 | H7: =C7*G7 -> 13.908333 | L7: =IF(C7<11,"NA",IF(C7<15,"ECA",IF(C7<18,"A",IF(C7<20,"A+")))) -> ECA | O7: =D7*G7 -> 14.5 | P7: =E7*G7 -> 12.6 | Q7: =G7*F7 -> 14.625
B8: Espagnol | C8: =F8 -> 19.25 | F8: 19.25 | G8: 2 | H8: =C8*G8 -> 38.5 | L8: =IF(C8<11,"NA",IF(C8<15,"ECA",IF(C8<18,"A",IF(C8<20,"A+")))) -> A+ | O8: =D8*G8 -> 0 | P8: =E8*G8 -> 0 | Q8: =G8*F8 -> 38.5
B9: Etude de Texte | C9: =(D9+F9+E9)/3 -> 14.271667 | D9: 13.25 | E9: 14.415 | F9: 15.15 | G9: 2 | H9: =C9*G9 -> 28.543333 | L9: =IF(C9<11,"NA",IF(C9<15,"ECA",IF(C9<18,"A",IF(C9<20,"A+")))) -> ECA | O9: =D9*G9 -> 26.5 | P9: =E9*G9 -> 28.83 | Q9: =G9*F9 -> 30.3
B10: Expression Ecrite | C10: =(D10+F10+E10)/3 -> 13.5 | D10: 13.7 | E10: 11.2 | F10: 15.6 | G10: 1 | H10: =C10*G10 -> 13.5 | L10: =IF(C10<11,"NA",IF(C10<15,"ECA",IF(C10<18,"A",IF(C10<20,"A+")))) -> ECA | O10: =D10*G10 -> 13.7 | P10: =E10*G10 -> 11.2 | Q10: =G10*F10 -> 15.6
B11: Total du GROUPE I :
B12: Moyenne du Groupe : | C12: =(SUM(H5:H10)/SUM(G5:G10)) -> 14.134242 | G12: Rang de l’élève :
B14: ECM | C14: =(D14+F14+E14)/3 -> 16.916667 | D14: 16.55 | E14: 17.7 | F14: 16.5 | G14: 2 | H14: =C14*G14 -> 33.833333 | L14: =IF(C14<11,"NA",IF(C14<15,"ECA",IF(C14<18,"A",IF(C14<20,"A+")))) -> A | O14: =D14*G14 -> 33.1 | P14: =E14*G14 -> 35.4 | Q14: =G14*F14 -> 33
B15: Géographie | C15: =(D15+F15+E15)/3 -> 15.525 | D15: 13.25 | E15: 16.55 | F15: 16.775 | G15: 1.5 | H15: =C15*G15 -> 23.2875 | L15: =IF(C15<11,"NA",IF(C15<15,"ECA",IF(C15<18,"A",IF(C15<20,"A+")))) -> A | O15: =D15*G15 -> 19.875 | P15: =E15*G15 -> 24.825 | Q15: =G15*F15 -> 25.1625
B16: Histoire | C16: =(D16+F16+E16)/3 -> 12.691667 | D16: 11.825 | E16: 12.125 | F16: 14.125 | G16: 1.5 | H16: =C16*G16 -> 19.0375 | L16: =IF(C16<11,"NA",IF(C16<15,"ECA",IF(C16<18,"A",IF(C16<20,"A+")))) -> ECA | O16: =D16*G16 -> 17.7375 | P16: =E16*G16 -> 18.1875 | Q16: =G16*F16 -> 21.1875
B17: LCN | C17: =(D17+F17+E17)/3 -> 14.316667 | D17: 16.2 | E17: 12.75 | F17: 14 | G17: 1 | H17: =C17*G17 -> 14.316667 | L17: =IF(C17<11,"NA",IF(C17<15,"ECA",IF(C17<18,"A",IF(C17<20,"A+")))) -> ECA | O17: =D17*G17 -> 16.2 | P17: =E17*G17 -> 12.75 | Q17: =G17*F17 -> 14
B18: Total du GROUPE II :
B19: Moyenne du Groupe : | C19: =(SUM(H14:H17)/SUM(G14:G17)) -> 15.079167 | G19: Rang de l’élève :
B21: Informatique | C21: =(D21+F21+E21)/3 -> 14.308333 | D21: 14.175 | E21: 14.5 | F21: 14.25 | G21: 2 | H21: =C21*G21 -> 28.616667 | L21: =IF(C21<11,"NA",IF(C21<15,"ECA",IF(C21<18,"A",IF(C21<20,"A+")))) -> ECA | O21: =D21*G21 -> 28.35 | P21: =E21*G21 -> 29 | Q21: =G21*F21 -> 28.5
B22: Mathématiques | C22: =(D22+F22+E22)/3 -> 14.745 | D22: 14.4 | E22: 15.135 | F22: 14.7 | G22: 4 | H22: =C22*G22 -> 58.98 | L22: =IF(C22<11,"NA",IF(C22<15,"ECA",IF(C22<18,"A",IF(C22<20,"A+")))) -> ECA | O22: =D22*G22 -> 57.6 | P22: =E22*G22 -> 60.54 | Q22: =G22*F22 -> 58.8
B23: PCT | C23: =F23 -> 16 | F23: 16 | G23: 2 | H23: =C23*G23 -> 32 | L23: =IF(C23<11,"NA",IF(C23<15,"ECA",IF(C23<18,"A",IF(C23<20,"A+")))) -> A | O23: =D23*G23 -> 0 | P23: =E23*G23 -> 0 | Q23: =G23*F23 -> 32
B24: SVTEEHB | C24: =(D24+F24+E24)/3 -> 16.993333 | D24: 16.78 | E24: 15.7 | F24: 18.5 | G24: 2 | H24: =C24*G24 -> 33.986667 | L24: =IF(C24<11,"NA",IF(C24<15,"ECA",IF(C24<18,"A",IF(C24<20,"A+")))) -> A | O24: =D24*G24 -> 33.56 | P24: =E24*G24 -> 31.4 | Q24: =G24*F24 -> 37
B25: Total du GROUPE III :
B26: Moyenne du Groupe : | C26: =(SUM(H21:H24)/SUM(G21:G24)) -> 15.358333 | G26: Rang de l’élève :
B28: EAC | C28: =(D28+F28+E28)/3 -> 15.833333 | D28: 16 | E28: 15.5 | F28: 16 | G28: 1 | H28: =C28*G28 -> 15.833333 | L28: =IF(C28<11,"NA",IF(C28<15,"ECA",IF(C28<18,"A",IF(C28<20,"A+")))) -> A | O28: =D28*G28 -> 16 | P28: =E28*G28 -> 15.5 | Q28: =G28*F28 -> 16
B29: EPS | C29: =(D29+F29+E29)/3 -> 16.833333 | D29: 17 | E29: 17 | F29: 16.5 | G29: 2 | H29: =C29*G29 -> 33.666667 | L29: =IF(C29<11,"NA",IF(C29<15,"ECA",IF(C29<18,"A",IF(C29<20,"A+")))) -> A | O29: =D29*G29 -> 34 | P29: =E29*G29 -> 34 | Q29: =G29*F29 -> 33
B30: ESF | C30: =(D30+F30+E30)/3 -> 15.266667 | D30: 16 | E30: 15.8 | F30: 14 | G30: 1 | H30: =C30*G30 -> 15.266667 | L30: =IF(C30<11,"NA",IF(C30<15,"ECA",IF(C30<18,"A",IF(C30<20,"A+")))) -> A | O30: =D30*G30 -> 16 | P30: =E30*G30 -> 15.8 | Q30: =G30*F30 -> 14
B31: Travail Manuel | C31: =(D31+F31+E31)/3 -> 17.166667 | D31: 18.5 | E31: 17 | F31: 16 | G31: 1 | H31: =C31*G31 -> 17.166667 | L31: =IF(C31<11,"NA",IF(C31<15,"ECA",IF(C31<18,"A",IF(C31<20,"A+")))) -> A | O31: =D31*G31 -> 18.5 | P31: =E31*G31 -> 17 | Q31: =G31*F31 -> 16
B32: Total du GROUPE IV : | O32: =SUM(O6:O31) -> 377.8725 | P32: =SUM(P6:P31) -> 381.5325 | Q32: =SUM(Q5:Q31) -> 494
B33: Moyenne du Groupe : | C33: =(SUM(H28:H31)/SUM(G28:G31)) -> 16.386667 | G33: Rang de l’élève : | O33: 26 | P33: 26 | Q33: 32
O34: =O32/O33 -> 14.533558 | P34: =P32/P33 -> 14.674327 | Q34: =Q32/Q33 -> 15.4375
B35: Total Général (GI + GII + GIII+GIV) = | C35: Moy Gle de la Classe : | F35: Moy du 1er : | I35: Moy du Dernier :
C36: TRIM 1 | D36: TRIM 2 | E36: TRIM3
B37: Moyennes de l’Elève : | C37: =O34 -> 14.533558 | D37: =P34 -> 14.674327 | E37: =Q34 -> 15.4375 | F37: Annuel : | G37: =(H5+H6+H7+H8+H9+H10+H14+H15+H16+H17+H21+H22+H23+H24+H28+H29+H30+H31)/32 -> 15.045885 | H37: /20 | I37: Rang de l’élève : | L37: /20
B39: v La moyenne Annuelle n’est pas égale à la moyenne arithmétique des trimestres
B40: DECISIONS ET OBSERVATIONS / Décisions And Observations
B41: DISCIPLINE / Disciplin | C41: Appréciation du travail de l’élève | G41: TRAVAIL / Academic Work
B42: Nb d’Heures : | C42: =IF(G37<11,"NA",IF(G37<15,"ECA",IF(G37<18,"A",IF(G37<20,"A+")))) -> A | D42: =IF(#REF!<11,"NA",IF(#REF!<15,"ECA",IF(#REF!<18,"A",IF(#REF!<20,"A+")))) -> #REF! | F42: =IF(#REF!<11,"NA",IF(#REF!<15,"ECA",IF(#REF!<18,"A",IF(#REF!<20,"A+")))) -> #REF!
B43: Nb de jrnées : | C43: =IF(#REF!<11,"NA",IF(#REF!<15,"ECA",IF(#REF!<18,"A",IF(#REF!<20,"A+")))) -> #REF! | D43: =IF(#REF!<11,"NA",IF(#REF!<15,"ECA",IF(#REF!<18,"A",IF(#REF!<20,"A+")))) -> #REF! | F43: =IF(#REF!<11,"NA",IF(#REF!<15,"ECA",IF(#REF!<18,"A",IF(#REF!<20,"A+")))) -> #REF! | G43: Tableau d’honneur / Honour roll | K43: Observations et Visa du Principal
B44: Exclusions / Suspensions | C44: =IF(#REF!<11,"NA",IF(#REF!<15,"ECA",IF(#REF!<18,"A",IF(#REF!<20,"A+")))) -> #REF! | D44: =IF(#REF!<11,"NA",IF(#REF!<15,"ECA",IF(#REF!<18,"A",IF(#REF!<20,"A+")))) -> #REF! | F44: =IF(#REF!<11,"NA",IF(#REF!<15,"ECA",IF(#REF!<18,"A",IF(#REF!<20,"A+")))) -> #REF! | G44: Encouragements / Encouragements | K44: Observations and Signature of Principal
B45: Blâme / Blame | C45: Observations et Remarques du Professeur Principal | G45: Félicitations / Congratulations
B46: Avertissements / Warnings | G46: Décisions du Conseil de Classe | K46: Yaoundé le
B47: Observations et Remarques du parent de l’élève | K47: Le Principal

Sheet KOUAM
B4: MATIERES | C4: Annuel | D4: TRIM 1 | E4: TRIM 2 | F4: TRIM 3 | G4: Coef | H4: Moy × Coef | I4: Moy Gle Classe | K4: Rang | L4: Appréciations
B5: Allemand | C5: =F5 -> 14.5 | F5: 14.5 | G5: 2 | H5: =C5*G5 -> 29 | L5: =IF(C5<11,"NA",IF(C5<15,"ECA",IF(C5<18,"A",IF(C5<20,"A+")))) -> ECA | O5: =D5*G5 -> 0 | P5: =E5*G5 -> 0 | Q5: =G5*F5 -> 29
B6: Anglais | C6: =(D6+F6+E6)/3 -> 8 | D6: 7.3 | E6: 9 | F6: 7.7 | G6: 3 | H6: =C6*G6 -> 24 | L6: =IF(C6<11,"NA",IF(C6<15,"ECA",IF(C6<18,"A",IF(C6<20,"A+")))) -> NA | O6: =D6*G6 -> 21.9 | P6: =E6*G6 -> 27 | Q6: =G6*F6 -> 23.1
B7: Cor Orthographique/ Dictée | C7: =(D7+F7+E7)/3 -> 7.325 | D7: 8.6 | E7: 7 | F7: 6.375 | G7: 1 | H7: =C7*G7 -> 7.325 | L7: =IF(C7<11,"NA",IF(C7<15,"ECA",IF(C7<18,"A",IF(C7<20,"A+")))) -> NA | O7: =D7*G7 -> 8.6 | P7: =E7*G7 -> 7 | Q7: =G7*F7 -> 6.375
B8: Espagnol | C8: =F8 -> 15 | F8: 15 | G8: 2 | H8: =C8*G8 -> 30 | L8: =IF(C8<11,"NA",IF(C8<15,"ECA",IF(C8<18,"A",IF(C8<20,"A+")))) -> A | O8: =D8*G8 -> 0 | P8: =E8*G8 -> 0 | Q8: =G8*F8 -> 30
B9: Etude de Texte | C9: =(D9+F9+E9)/3 -> 8.71 | D9: 6.5 | E9: 11.03 | F9: 8.6 | G9: 2 | H9: =C9*G9 -> 17.42 | L9: =IF(C9<11,"NA",IF(C9<15,"ECA",IF(C9<18,"A",IF(C9<20,"A+")))) -> NA | O9: =D9*G9 -> 13 | P9: =E9*G9 -> 22.06 | Q9: =G9*F9 -> 17.2
B10: Expression Ecrite | C10: =(D10+F10+E10)/3 -> 9.79 | D10: 8 | E10: 11.07 | F10: 10.3 | G10: 1 | H10: =C10*G10 -> 9.79 | L10: =IF(C10<11,"NA",IF(C10<15,"ECA",IF(C10<18,"A",IF(C10<20,"A+")))) -> NA | O10: =D10*G10 -> 8 | P10: =E10*G10 -> 11.07 | Q10: =G10*F10 -> 10.3
B11: Total du GROUPE I :
B12: Moyenne du Groupe : | C12: =(SUM(H5:H10)/SUM(G5:G10)) -> 10.685 | G12: Rang de l’élève :
B14: ECM | C14: =(D14+F14+E14)/3 -> 13.283333 | D14: 11.65 | E14: 13.7 | F14: 14.5 | G14: 2 | H14: =C14*G14 -> 26.566667 | L14: =IF(C14<11,"NA",IF(C14<15,"ECA",IF(C14<18,"A",IF(C14<20,"A+")))) -> ECA | O14: =D14*G14 -> 23.3 | P14: =E14*G14 -> 27.4 | Q14: =G14*F14 -> 29
B15: Géographie | C15: =(D15+F15+E15)/3 -> 13.391667 | D15: 12.325 | E15: 13.175 | F15: 14.675 | G15: 1.5 | H15: =C15*G15 -> 20.0875 | L15: =IF(C15<11,"NA",IF(C15<15,"ECA",IF(C15<18,"A",IF(C15<20,"A+")))) -> ECA | O15: =D15*G15 -> 18.4875 | P15: =E15*G15 -> 19.7625 | Q15: =G15*F15 -> 22.0125
B16: Histoire | C16: =(D16+F16+E16)/3 -> 11.691667 | D16: 11.575 | E16: 11 | F16: 12.5 | G16: 1.5 | H16: =C16*G16 -> 17.5375 | L16: =IF(C16<11,"NA",IF(C16<15,"ECA",IF(C16<18,"A",IF(C16<20,"A+")))) -> ECA | O16: =D16*G16 -> 17.3625 | P16: =E16*G16 -> 16.5 | Q16: =G16*F16 -> 18.75
B17: LCN | C17: =(D17+F17+E17)/3 -> 10.383333 | D17: 12.15 | E17: 8.5 | F17: 10.5 | G17: 1 | H17: =C17*G17 -> 10.383333 | L17: =IF(C17<11,"NA",IF(C17<15,"ECA",IF(C17<18,"A",IF(C17<20,"A+")))) -> NA | O17: =D17*G17 -> 12.15 | P17: =E17*G17 -> 8.5 | Q17: =G17*F17 -> 10.5
B18: Total du GROUPE II :
B19: Moyenne du Groupe : | C19: =(SUM(H14:H17)/SUM(G14:G17)) -> 12.429167 | G19: Rang de l’élève :
B21: Informatique | C21: =(D21+F21+E21)/3 -> 9.9583333 | D21: 8.575 | E21: 9.8 | F21: 11.5 | G21: 2 | H21: =C21*G21 -> 19.916667 | L21: =IF(C21<11,"NA",IF(C21<15,"ECA",IF(C21<18,"A",IF(C21<20,"A+")))) -> NA | O21: =D21*G21 -> 17.15 | P21: =E21*G21 -> 19.6 | Q21: =G21*F21 -> 23
B22: Mathématiques | C22: =(D22+F22+E22)/3 -> 12.095 | D22: 10.95 | E22: 12.635 | F22: 12.7 | G22: 4 | H22: =C22*G22 -> 48.38 | L22: =IF(C22<11,"NA",IF(C22<15,"ECA",IF(C22<18,"A",IF(C22<20,"A+")))) -> ECA | O22: =D22*G22 -> 43.8 | P22: =E22*G22 -> 50.54 | Q22: =G22*F22 -> 50.8
B23: PCT | C23: =F23 -> 19 | F23: 19 | G23: 2 | H23: =C23*G23 -> 38 | L23: =IF(C23<11,"NA",IF(C23<15,"ECA",IF(C23<18,"A",IF(C23<20,"A+")))) -> A+ | O23: =D23*G23 -> 0 | P23: =E23*G23 -> 0 | Q23: =G23*F23 -> 38
B24: SVTEEHB | C24: =(D24+F24+E24)/3 -> 11.51 | D24: 9.55 | E24: 8.48 | F24: 16.5 | G24: 2 | H24: =C24*G24 -> 23.02 | L24: =IF(C24<11,"NA",IF(C24<15,"ECA",IF(C24<18,"A",IF(C24<20,"A+")))) -> ECA | O24: =D24*G24 -> 19.1 | P24: =E24*G24 -> 16.96 | Q24: =G24*F24 -> 33
B25: Total du GROUPE III :
B26: Moyenne du Groupe : | C26: =(SUM(H21:H24)/SUM(G21:G24)) -> 12.931667 | G26: Rang de l’élève :
B28: EAC | C28: =(D28+F28+E28)/3 -> 14 | D28: 13.5 | E28: 14.5 | F28: 14 | G28: 1 | H28: =C28*G28 -> 14 | L28: =IF(C28<11,"NA",IF(C28<15,"ECA",IF(C28<18,"A",IF(C28<20,"A+")))) -> ECA | O28: =D28*G28 -> 13.5 | P28: =E28*G28 -> 14.5 | Q28: =G28*F28 -> 14
B29: EPS | C29: =(D29+F29+E29)/3 -> 14.583333 | D29: 13.7 | E29: 15.05 | F29: 15 | G29: 2 | H29: =C29*G29 -> 29.166667 | L29: =IF(C29<11,"NA",IF(C29<15,"ECA",IF(C29<18,"A",IF(C29<20,"A+")))) -> ECA | O29: =D29*G29 -> 27.4 | P29: =E29*G29 -> 30.1 | Q29: =G29*F29 -> 30
B30: ESF | C30: =(D30+F30+E30)/3 -> 12.8 | D30: 12 | E30: 12.4 | F30: 14 | G30: 1 | H30: =C30*G30 -> 12.8 | L30: =IF(C30<11,"NA",IF(C30<15,"ECA",IF(C30<18,"A",IF(C30<20,"A+")))) -> ECA | O30: =D30*G30 -> 12 | P30: =E30*G30 -> 12.4 | Q30: =G30*F30 -> 14
B31: Travail Manuel | C31: =(D31+F31+E31)/3 -> 14.5 | D31: 12 | E31: 16 | F31: 15.5 | G31: 1 | H31: =C31*G31 -> 14.5 | L31: =IF(C31<11,"NA",IF(C31<15,"ECA",IF(C31<18,"A",IF(C31<20,"A+")))) -> ECA | O31: =D31*G31 -> 12 | P31: =E31*G31 -> 16 | Q31: =G31*F31 -> 15.5
B32: Total du GROUPE IV : | O32: =SUM(O6:O31) -> 267.75 | P32: =SUM(P6:P31) -> 299.3925 | Q32: =SUM(Q5:Q31) -> 414.5375
B33: Moyenne du Groupe : | C33: =(SUM(H28:H31)/SUM(G28:G31)) -> 14.093333 | G33: Rang de l’élève : | O33: 26 | P33: 26 | Q33: 32
O34: =O32/O33 -> 10.298077 | P34: =P32/P33 -> 11.515096 | Q34: =Q32/Q33 -> 12.954297
B35: Total Général (GI + GII + GIII+GIV) = | C35: Moy Gle de la Classe : | F35: Moy du 1er : | I35: Moy du Dernier :
C36: TRIM 1 | D36: TRIM 2 | E36: TRIM3
B37: Moyennes de l’Elève : | C37: =O34 -> 10.298077 | D37: =P34 -> 11.515096 | E37: =Q34 -> 12.954297 | F37: Annuel : | G37: =(H5+H6+H7+H8+H9+H10+H14+H15+H16+H17+H21+H22+H23+H24+H28+H29+H30+H31)/32 -> 12.246667 | H37: /20 | I37: Rang de l’élève : | L37: /20
B39: v La moyenne Annuelle n’est pas égale à la moyenne arithmétique des trimestres
B40: DECISIONS ET OBSERVATIONS / Décisions And Observations
B41: DISCIPLINE / Disciplin | C41: Appréciation du travail de l’élève | G41: TRAVAIL / Academic Work
B42: Nb d’Heures : | C42: =IF(G37<11,"NA",IF(G37<15,"ECA",IF(G37<18,"A",IF(G37<20,"A+")))) -> ECA | D42: =IF(#REF!<11,"NA",IF(#REF!<15,"ECA",IF(#REF!<18,"A",IF(#REF!<20,"A+")))) -> #REF! | F42: =IF(#REF!<11,"NA",IF(#REF!<15,"ECA",IF(#REF!<18,"A",IF(#REF!<20,"A+")))) -> #REF!
B43: Nb de jrnées : | C43: =IF(#REF!<11,"NA",IF(#REF!<15,"ECA",IF(#REF!<18,"A",IF(#REF!<20,"A+")))) -> #REF! | D43: =IF(#REF!<11,"NA",IF(#REF!<15,"ECA",IF(#REF!<18,"A",IF(#REF!<20,"A+")))) -> #REF! | F43: =IF(#REF!<11,"NA",IF(#REF!<15,"ECA",IF(#REF!<18,"A",IF(#REF!<20,"A+")))) -> #REF! | G43: Tableau d’honneur / Honour roll | K43: Observations et Visa du Principal
B44: Exclusions / Suspensions | C44: =IF(#REF!<11,"NA",IF(#REF!<15,"ECA",IF(#REF!<18,"A",IF(#REF!<20,"A+")))) -> #REF! | D44: =IF(#REF!<11,"NA",IF(#REF!<15,"ECA",IF(#REF!<18,"A",IF(#REF!<20,"A+")))) -> #REF! | F44: =IF(#REF!<11,"NA",IF(#REF!<15,"ECA",IF(#REF!<18,"A",IF(#REF!<20,"A+")))) -> #REF! | G44: Encouragements / Encouragements | K44: Observations and Signature of Principal
B45: Blâme / Blame | C45: Observations et Remarques du Professeur Principal | G45: Félicitations / Congratulations
B46: Avertissements / Warnings | G46: Décisions du Conseil de Classe | K46: Yaoundé le
B47: Observations et Remarques du parent de l’élève | K47: Le Principal

Sheet MAGATSING
B4: MATIERES | C4: Annuel | D4: TRIM 1 | E4: TRIM 2 | F4: TRIM 3 | G4: Coef | H4: Moy × Coef | I4: Moy Gle Classe | K4: Rang | L4: Appréciations
B5: Allemand | C5: =F5 -> 10.5 | F5: 10.5 | G5: 2 | H5: =C5*G5 -> 21 | L5: =IF(C5<11,"NA",IF(C5<15,"ECA",IF(C5<18,"A",IF(C5<20,"A+")))) -> NA | O5: =D5*G5 -> 0 | P5: =E5*G5 -> 0 | Q5: =G5*F5 -> 21
B6: Anglais | C6: =(D6+F6+E6)/3 -> 7.9583333 | D6: 6.575 | E6: 7.675 | F6: 9.625 | G6: 3 | H6: =C6*G6 -> 23.875 | L6: =IF(C6<11,"NA",IF(C6<15,"ECA",IF(C6<18,"A",IF(C6<20,"A+")))) -> NA | O6: =D6*G6 -> 19.725 | P6: =E6*G6 -> 23.025 | Q6: =G6*F6 -> 28.875
B7: Cor Orthographique/ Dictée | C7: =(D7+F7+E7)/3 -> 7.1083333 | D7: 6 | E7: 5.7 | F7: 9.625 | G7: 1 | H7: =C7*G7 -> 7.1083333 | L7: =IF(C7<11,"NA",IF(C7<15,"ECA",IF(C7<18,"A",IF(C7<20,"A+")))) -> NA | O7: =D7*G7 -> 6 | P7: =E7*G7 -> 5.7 | Q7: =G7*F7 -> 9.625
B8: Espagnol | C8: =F8 -> 15.75 | F8: 15.75 | G8: 2 | H8: =C8*G8 -> 31.5 | L8: =IF(C8<11,"NA",IF(C8<15,"ECA",IF(C8<18,"A",IF(C8<20,"A+")))) -> A | O8: =D8*G8 -> 0 | P8: =E8*G8 -> 0 | Q8: =G8*F8 -> 31.5
B9: Etude de Texte | C9: =(D9+F9+E9)/3 -> 10.35 | D9: 9.65 | E9: 12.4 | F9: 9 | G9: 2 | H9: =C9*G9 -> 20.7 | L9: =IF(C9<11,"NA",IF(C9<15,"ECA",IF(C9<18,"A",IF(C9<20,"A+")))) -> NA | O9: =D9*G9 -> 19.3 | P9: =E9*G9 -> 24.8 | Q9: =G9*F9 -> 18
B10: Expression Ecrite | C10: =(D10+F10+E10)/3 -> 9.655 | D10: 8.5 | E10: 10.965 | F10: 9.5 | G10: 1 | H10: =C10*G10 -> 9.655 | L10: =IF(C10<11,"NA",IF(C10<15,"ECA",IF(C10<18,"A",IF(C10<20,"A+")))) -> NA | O10: =D10*G10 -> 8.5 | P10: =E10*G10 -> 10.965 | Q10: =G10*F10 -> 9.5
B11: Total du GROUPE I :
B12: Moyenne du Groupe : | C12: =(SUM(H5:H10)/SUM(G5:G10)) -> 10.348939 | G12: Rang de l’élève :
B14: ECM | C14: =(D14+F14+E14)/3 -> 13.6 | D14: 14.7 | E14: 14.6 | F14: 11.5 | G14: 2 | H14: =C14*G14 -> 27.2 | L14: =IF(C14<11,"NA",IF(C14<15,"ECA",IF(C14<18,"A",IF(C14<20,"A+")))) -> ECA | O14: =D14*G14 -> 29.4 | P14: =E14*G14 -> 29.2 | Q14: =G14*F14 -> 23
B15: Géographie | C15: =(D15+F15+E15)/3 -> 12.558333 | D15: 11.45 | E15: 13.85 | F15: 12.375 | G15: 1.5 | H15: =C15*G15 -> 18.8375 | L15: =IF(C15<11,"NA",IF(C15<15,"ECA",IF(C15<18,"A",IF(C15<20,"A+")))) -> ECA | O15: =D15*G15 -> 17.175 | P15: =E15*G15 -> 20.775 | Q15: =G15*F15 -> 18.5625
B16: Histoire | C16: =(D16+F16+E16)/3 -> 12.491667 | D16: 12.525 | E16: 12.825 | F16: 12.125 | G16: 1.5 | H16: =C16*G16 -> 18.7375 | L16: =IF(C16<11,"NA",IF(C16<15,"ECA",IF(C16<18,"A",IF(C16<20,"A+")))) -> ECA | O16: =D16*G16 -> 18.7875 | P16: =E16*G16 -> 19.2375 | Q16: =G16*F16 -> 18.1875
B17: LCN | C17: =(D17+F17+E17)/3 -> 10.983333 | D17: 11.45 | E17: 10 | F17: 11.5 | G17: 1 | H17: =C17*G17 -> 10.983333 | L17: =IF(C17<11,"NA",IF(C17<15,"ECA",IF(C17<18,"A",IF(C17<20,"A+")))) -> NA | O17: =D17*G17 -> 11.45 | P17: =E17*G17 -> 10 | Q17: =G17*F17 -> 11.5
B18: Total du GROUPE II :
B19: Moyenne du Groupe : | C19: =(SUM(H14:H17)/SUM(G14:G17)) -> 12.626389 | G19: Rang de l’élève :
B21: Informatique | C21: =(D21+F21+E21)/3 -> 13.3 | D21: 14 | E21: 12.65 | F21: 13.25 | G21: 2 | H21: =C21*G21 -> 26.6 | L21: =IF(C21<11,"NA",IF(C21<15,"ECA",IF(C21<18,"A",IF(C21<20,"A+")))) -> ECA | O21: =D21*G21 -> 28 | P21: =E21*G21 -> 25.3 | Q21: =G21*F21 -> 26.5
B22: Mathématiques | C22: =(D22+F22+E22)/3 -> 12.178333 | D22: 12.25 | E22: 11.885 | F22: 12.4 | G22: 4 | H22: =C22*G22 -> 48.713333 | L22: =IF(C22<11,"NA",IF(C22<15,"ECA",IF(C22<18,"A",IF(C22<20,"A+")))) -> ECA | O22: =D22*G22 -> 49 | P22: =E22*G22 -> 47.54 | Q22: =G22*F22 -> 49.6
B23: PCT | C23: =F23 -> 15 | F23: 15 | G23: 2 | H23: =C23*G23 -> 30 | L23: =IF(C23<11,"NA",IF(C23<15,"ECA",IF(C23<18,"A",IF(C23<20,"A+")))) -> A | O23: =D23*G23 -> 0 | P23: =E23*G23 -> 0 | Q23: =G23*F23 -> 30
B24: SVTEEHB | C24: =(D24+F24+E24)/3 -> 13.633333 | D24: 13.55 | E24: 12.1 | F24: 15.25 | G24: 2 | H24: =C24*G24 -> 27.266667 | L24: =IF(C24<11,"NA",IF(C24<15,"ECA",IF(C24<18,"A",IF(C24<20,"A+")))) -> ECA | O24: =D24*G24 -> 27.1 | P24: =E24*G24 -> 24.2 | Q24: =G24*F24 -> 30.5
B25: Total du GROUPE III :
B26: Moyenne du Groupe : | C26: =(SUM(H21:H24)/SUM(G21:G24)) -> 13.258 | G26: Rang de l’élève :
B28: EAC | C28: =(D28+F28+E28)/3 -> 15.666667 | D28: 13 | E28: 16 | F28: 18 | G28: 1 | H28: =C28*G28 -> 15.666667 | L28: =IF(C28<11,"NA",IF(C28<15,"ECA",IF(C28<18,"A",IF(C28<20,"A+")))) -> A | O28: =D28*G28 -> 13 | P28: =E28*G28 -> 16 | Q28: =G28*F28 -> 18
B29: EPS | C29: =(D29+F29+E29)/3 -> 14.283333 | D29: 13.8 | E29: 14.85 | F29: 14.2 | G29: 2 | H29: =C29*G29 -> 28.566667 | L29: =IF(C29<11,"NA",IF(C29<15,"ECA",IF(C29<18,"A",IF(C29<20,"A+")))) -> ECA | O29: =D29*G29 -> 27.6 | P29: =E29*G29 -> 29.7 | Q29: =G29*F29 -> 28.4
B30: ESF | C30: =(D30+F30+E30)/3 -> 12.633333 | D30: 13 | E30: 10.9 | F30: 14 | G30: 1 | H30: =C30*G30 -> 12.633333 | L30: =IF(C30<11,"NA",IF(C30<15,"ECA",IF(C30<18,"A",IF(C30<20,"A+")))) -> ECA | O30: =D30*G30 -> 13 | P30: =E30*G30 -> 10.9 | Q30: =G30*F30 -> 14
B31: Travail Manuel | C31: =(D31+F31+E31)/3 -> 15.333333 | D31: 15 | E31: 16 | F31: 15 | G31: 1 | H31: =C31*G31 -> 15.333333 | L31: =IF(C31<11,"NA",IF(C31<15,"ECA",IF(C31<18,"A",IF(C31<20,"A+")))) -> A | O31: =D31*G31 -> 15 | P31: =E31*G31 -> 16 | Q31: =G31*F31 -> 15
B32: Total du GROUPE IV : | O32: =SUM(O6:O31) -> 303.0375 | P32: =SUM(P6:P31) -> 313.3425 | Q32: =SUM(Q5:Q31) -> 401.75
B33: Moyenne du Groupe : | C33: =(SUM(H28:H31)/SUM(G28:G31)) -> 14.44 | G33: Rang de l’élève : | O33: 26 | P33: 26 | Q33: 32
O34: =O32/O33 -> 11.655288 | P34: =P32/P33 -> 12.051635 | Q34: =Q32/Q33 -> 12.554688
B35: Total Général (GI + GII + GIII+GIV) = | C35: Moy Gle de la Classe : | F35: Moy du 1er : | I35: Moy du Dernier :
C36: TRIM 1 | D36: TRIM 2 | E36: TRIM3
B37: Moyennes de l’Elève : | C37: =O34 -> 11.655288 | D37: =P34 -> 12.051635 | E37: =Q34 -> 12.554688 | F37: Annuel : | G37: =(H5+H6+H7+H8+H9+H10+H14+H15+H16+H17+H21+H22+H23+H24+H28+H29+H30+H31)/32 -> 12.324271 | H37: /20 | I37: Rang de l’élève : | L37: /20
B39: v La moyenne Annuelle n’est pas égale à la moyenne arithmétique des trimestres
B40: DECISIONS ET OBSERVATIONS / Décisions And Observations
B41: DISCIPLINE / Disciplin | C41: Appréciation du travail de l’élève | G41: TRAVAIL / Academic Work
B42: Nb d’Heures : | C42: =IF(G37<11,"NA",IF(G37<15,"ECA",IF(G37<18,"A",IF(G37<20,"A+")))) -> ECA | D42: =IF(#REF!<11,"NA",IF(#REF!<15,"ECA",IF(#REF!<18,"A",IF(#REF!<20,"A+")))) -> #REF! | F42: =IF(#REF!<11,"NA",IF(#REF!<15,"ECA",IF(#REF!<18,"A",IF(#REF!<20,"A+")))) -> #REF!
B43: Nb de jrnées : | C43: =IF(#REF!<11,"NA",IF(#REF!<15,"ECA",IF(#REF!<18,"A",IF(#REF!<20,"A+")))) -> #REF! | D43: =IF(#REF!<11,"NA",IF(#REF!<15,"ECA",IF(#REF!<18,"A",IF(#REF!<20,"A+")))) -> #REF! | F43: =IF(#REF!<11,"NA",IF(#REF!<15,"ECA",IF(#REF!<18,"A",IF(#REF!<20,"A+")))) -> #REF! | G43: Tableau d’honneur / Honour roll | K43: Observations et Visa du Principal
B44: Exclusions / Suspensions | C44: =IF(#REF!<11,"NA",IF(#REF!<15,"ECA",IF(#REF!<18,"A",IF(#REF!<20,"A+")))) -> #REF! | D44: =IF(#REF!<11,"NA",IF(#REF!<15,"ECA",IF(#REF!<18,"A",IF(#REF!<20,"A+")))) -> #REF! | F44: =IF(#REF!<11,"NA",IF(#REF!<15,"ECA",IF(#REF!<18,"A",IF(#REF!<20,"A+")))) -> #REF! | G44: Encouragements / Encouragements | K44: Observations and Signature of Principal
B45: Blâme / Blame | C45: Observations et Remarques du Professeur Principal | G45: Félicitations / Congratulations
B46: Avertissements / Warnings | G46: Décisions du Conseil de Classe | K46: Yaoundé le
B47: Observations et Remarques du parent de l’élève | K47: Le Principal

Sheet MENYE
B4: MATIERES | C4: Annuel | D4: TRIM 1 | E4: TRIM 2 | F4: TRIM 3 | G4: Coef | H4: Moy × Coef | I4: Moy Gle Classe | K4: Rang | L4: Appréciations
B5: Allemand | C5: =F5 -> 9 | F5: 9 | G5: 2 | H5: =C5*G5 -> 18 | L5: =IF(C5<11,"NA",IF(C5<15,"ECA",IF(C5<18,"A",IF(C5<20,"A+")))) -> NA | O5: =D5*G5 -> 0 | P5: =E5*G5 -> 0 | Q5: =G5*F5 -> 18
B6: Anglais | C6: =(D6+F6+E6)/3 -> 6.425 | D6: 6.05 | E6: 5.6 | F6: 7.625 | G6: 3 | H6: =C6*G6 -> 19.275 | L6: =IF(C6<11,"NA",IF(C6<15,"ECA",IF(C6<18,"A",IF(C6<20,"A+")))) -> NA | O6: =D6*G6 -> 18.15 | P6: =E6*G6 -> 16.8 | Q6: =G6*F6 -> 22.875
B7: Cor Orthographique/ Dictée | C7: =(D7+F7+E7)/3 -> 6.9416667 | D7: 7.9 | E7: 9.3 | F7: 3.625 | G7: 1 | H7: =C7*G7 -> 6.9416667 | L7: =IF(C7<11,"NA",IF(C7<15,"ECA",IF(C7<18,"A",IF(C7<20,"A+")))) -> NA | O7: =D7*G7 -> 7.9 | P7: =E7*G7 -> 9.3 | Q7: =G7*F7 -> 3.625
B8: Espagnol | C8: =F8 -> 13.5 | F8: 13.5 | G8: 2 | H8: =C8*G8 -> 27 | L8: =IF(C8<11,"NA",IF(C8<15,"ECA",IF(C8<18,"A",IF(C8<20,"A+")))) -> ECA | O8: =D8*G8 -> 0 | P8: =E8*G8 -> 0 | Q8: =G8*F8 -> 27
B9: Etude de Texte | C9: =(D9+F9+E9)/3 -> 8.0366667 | D9: 7.35 | E9: 9.76 | F9: 7 | G9: 2 | H9: =C9*G9 -> 16.073333 | L9: =IF(C9<11,"NA",IF(C9<15,"ECA",IF(C9<18,"A",IF(C9<20,"A+")))) -> NA | O9: =D9*G9 -> 14.7 | P9: =E9*G9 -> 19.52 | Q9: =G9*F9 -> 14
B10: Expression Ecrite | C10: =(D10+F10+E10)/3 -> 12.083333 | D10: 12.7 | E10: 14.8 | F10: 8.75 | G10: 1 | H10: =C10*G10 -> 12.083333 | L10: =IF(C10<11,"NA",IF(C10<15,"ECA",IF(C10<18,"A",IF(C10<20,"A+")))) -> ECA | O10: =D10*G10 -> 12.7 | P10: =E10*G10 -> 14.8 | Q10: =G10*F10 -> 8.75
B11: Total du GROUPE I :
B12: Moyenne du Groupe : | C12: =(SUM(H5:H10)/SUM(G5:G10)) -> 9.0339394 | G12: Rang de l’élève :
B14: ECM | C14: =(D14+F14+E14)/3 -> 12.283333 | D14: 11.35 | E14: 14 | F14: 11.5 | G14: 2 | H14: =C14*G14 -> 24.566667 | L14: =IF(C14<11,"NA",IF(C14<15,"ECA",IF(C14<18,"A",IF(C14<20,"A+")))) -> ECA | O14: =D14*G14 -> 22.7 | P14: =E14*G14 -> 28 | Q14: =G14*F14 -> 23
B15: Géographie | C15: =(D15+F15+E15)/3 -> 12.35 | D15: 10.8 | E15: 13.75 | F15: 12.5 | G15: 1.5 | H15: =C15*G15 -> 18.525 | L15: =IF(C15<11,"NA",IF(C15<15,"ECA",IF(C15<18,"A",IF(C15<20,"A+")))) -> ECA | O15: =D15*G15 -> 16.2 | P15: =E15*G15 -> 20.625 | Q15: =G15*F15 -> 18.75
B16: Histoire | C16: =(D16+F16+E16)/3 -> 11.041667 | D16: 9.175 | E16: 11.2 | F16: 12.75 | G16: 1.5 | H16: =C16*G16 -> 16.5625 | L16: =IF(C16<11,"NA",IF(C16<15,"ECA",IF(C16<18,"A",IF(C16<20,"A+")))) -> ECA | O16: =D16*G16 -> 13.7625 | P16: =E16*G16 -> 16.8 | Q16: =G16*F16 -> 19.125
B17: LCN | C17: =(D17+F17+E17)/3 -> 11.166667 | D17: 11 | E17: 10 | F17: 12.5 | G17: 1 | H17: =C17*G17 -> 11.166667 | L17: =IF(C17<11,"NA",IF(C17<15,"ECA",IF(C17<18,"A",IF(C17<20,"A+")))) -> ECA | O17: =D17*G17 -> 11 | P17: =E17*G17 -> 10 | Q17: =G17*F17 -> 12.5
B18: Total du GROUPE II :
B19: Moyenne du Groupe : | C19: =(SUM(H14:H17)/SUM(G14:G17)) -> 11.803472 | G19: Rang de l’élève :
B21: Informatique | C21: =(D21+F21+E21)/3 -> 8.9833333 | D21: 12.15 | E21: 8.3 | F21: 6.5 | G21: 2 | H21: =C21*G21 -> 17.966667 | L21: =IF(C21<11,"NA",IF(C21<15,"ECA",IF(C21<18,"A",IF(C21<20,"A+")))) -> NA | O21: =D21*G21 -> 24.3 | P21: =E21*G21 -> 16.6 | Q21: =G21*F21 -> 13
B22: Mathématiques | C22: =(D22+F22+E22)/3 -> 11.556667 | D22: 10.8 | E22: 12.67 | F22: 11.2 | G22: 4 | H22: =C22*G22 -> 46.226667 | L22: =IF(C22<11,"NA",IF(C22<15,"ECA",IF(C22<18,"A",IF(C22<20,"A+")))) -> ECA | O22: =D22*G22 -> 43.2 | P22: =E22*G22 -> 50.68 | Q22: =G22*F22 -> 44.8
B23: PCT | C23: =F23 -> 18 | F23: 18 | G23: 2 | H23: =C23*G23 -> 36 | L23: =IF(C23<11,"NA",IF(C23<15,"ECA",IF(C23<18,"A",IF(C23<20,"A+")))) -> A+ | O23: =D23*G23 -> 0 | P23: =E23*G23 -> 0 | Q23: =G23*F23 -> 36
B24: SVTEEHB | C24: =(D24+F24+E24)/3 -> 10.783333 | D24: 10.7 | E24: 8.9 | F24: 12.75 | G24: 2 | H24: =C24*G24 -> 21.566667 | L24: =IF(C24<11,"NA",IF(C24<15,"ECA",IF(C24<18,"A",IF(C24<20,"A+")))) -> NA | O24: =D24*G24 -> 21.4 | P24: =E24*G24 -> 17.8 | Q24: =G24*F24 -> 25.5
B25: Total du GROUPE III :
B26: Moyenne du Groupe : | C26: =(SUM(H21:H24)/SUM(G21:G24)) -> 12.176 | G26: Rang de l’élève :
B28: EAC | C28: =(D28+F28+E28)/3 -> 18.333333 | D28: 19 | E28: 19 | F28: 17 | G28: 1 | H28: =C28*G28 -> 18.333333 | L28: =IF(C28<11,"NA",IF(C28<15,"ECA",IF(C28<18,"A",IF(C28<20,"A+")))) -> A+ | O28: =D28*G28 -> 19 | P28: =E28*G28 -> 19 | Q28: =G28*F28 -> 17
B29: EPS | C29: =(D29+F29+E29)/3 -> 15.85 | D29: 15.35 | E29: 17 | F29: 15.2 | G29: 2 | H29: =C29*G29 -> 31.7 | L29: =IF(C29<11,"NA",IF(C29<15,"ECA",IF(C29<18,"A",IF(C29<20,"A+")))) -> A | O29: =D29*G29 -> 30.7 | P29: =E29*G29 -> 34 | Q29: =G29*F29 -> 30.4
B30: ESF | C30: =(D30+F30+E30)/3 -> 11.5 | D30: 13.5 | E30: 7 | F30: 14 | G30: 1 | H30: =C30*G30 -> 11.5 | L30: =IF(C30<11,"NA",IF(C30<15,"ECA",IF(C30<18,"A",IF(C30<20,"A+")))) -> ECA | O30: =D30*G30 -> 13.5 | P30: =E30*G30 -> 7 | Q30: =G30*F30 -> 14
B31: Travail Manuel | C31: =(D31+F31+E31)/3 -> 15.75 | D31: 15 | E31: 16 | F31: 16.25 | G31: 1 | H31: =C31*G31 -> 15.75 | L31: =IF(C31<11,"NA",IF(C31<15,"ECA",IF(C31<18,"A",IF(C31<20,"A+")))) -> A | O31: =D31*G31 -> 15 | P31: =E31*G31 -> 16 | Q31: =G31*F31 -> 16.25
B32: Total du GROUPE IV : | O32: =SUM(O6:O31) -> 284.2125 | P32: =SUM(P6:P31) -> 296.925 | Q32: =SUM(Q5:Q31) -> 364.575
B33: Moyenne du Groupe : | C33: =(SUM(H28:H31)/SUM(G28:G31)) -> 15.456667 | G33: Rang de l’élève : | O33: 26 | P33: 26 | Q33: 32
O34: =O32/O33 -> 10.93125 | P34: =P32/P33 -> 11.420192 | Q34: =Q32/Q33 -> 11.392969
B35: Total Général (GI + GII + GIII+GIV) = | C35: Moy Gle de la Classe : | F35: Moy du 1er : | I35: Moy du Dernier :
C36: TRIM 1 | D36: TRIM 2 | E36: TRIM3
B37: Moyennes de l’Elève : | C37: =O34 -> 10.93125 | D37: =P34 -> 11.420192 | E37: =Q34 -> 11.392969 | F37: Annuel : | G37: =(H5+H6+H7+H8+H9+H10+H14+H15+H16+H17+H21+H22+H23+H24+H28+H29+H30+H31)/32 -> 11.538672 | H37: /20 | I37: Rang de l’élève : | L37: /20
B39: v La moyenne Annuelle n’est pas égale à la moyenne arithmétique des trimestres
B40: DECISIONS ET OBSERVATIONS / Décisions And Observations
B41: DISCIPLINE / Disciplin | C41: Appréciation du travail de l’élève | G41: TRAVAIL / Academic Work
B42: Nb d’Heures : | C42: =IF(G37<11,"NA",IF(G37<15,"ECA",IF(G37<18,"A",IF(G37<20,"A+")))) -> ECA | D42: =IF(#REF!<11,"NA",IF(#REF!<15,"ECA",IF(#REF!<18,"A",IF(#REF!<20,"A+")))) -> #REF! | F42: =IF(#REF!<11,"NA",IF(#REF!<15,"ECA",IF(#REF!<18,"A",IF(#REF!<20,"A+")))) -> #REF!
B43: Nb de jrnées : | C43: =IF(#REF!<11,"NA",IF(#REF!<15,"ECA",IF(#REF!<18,"A",IF(#REF!<20,"A+")))) -> #REF! | D43: =IF(#REF!<11,"NA",IF(#REF!<15,"ECA",IF(#REF!<18,"A",IF(#REF!<20,"A+")))) -> #REF! | F43: =IF(#REF!<11,"NA",IF(#REF!<15,"ECA",IF(#REF!<18,"A",IF(#REF!<20,"A+")))) -> #REF! | G43: Tableau d’honneur / Honour roll | K43: Observations et Visa du Principal
B44: Exclusions / Suspensions | C44: =IF(#REF!<11,"NA",IF(#REF!<15,"ECA",IF(#REF!<18,"A",IF(#REF!<20,"A+")))) -> #REF! | D44: =IF(#REF!<11,"NA",IF(#REF!<15,"ECA",IF(#REF!<18,"A",IF(#REF!<20,"A+")))) -> #REF! | F44: =IF(#REF!<11,"NA",IF(#REF!<15,"ECA",IF(#REF!<18,"A",IF(#REF!<20,"A+")))) -> #REF! | G44: Encouragements / Encouragements | K44: Observations and Signature of Principal
B45: Blâme / Blame | C45: Observations et Remarques du Professeur Principal | G45: Félicitations / Congratulations
B46: Avertissements / Warnings | G46: Décisions du Conseil de Classe | K46: Yaoundé le
B47: Observations et Remarques du parent de l’élève | K47: Le Principal

Sheet NGO KONDE
B4: MATIERES | C4: Annuel | D4: TRIM 1 | E4: TRIM 2 | F4: TRIM 3 | G4: Coef | H4: Moy × Coef | I4: Moy Gle Classe | K4: Rang | L4: Appréciations
B5: Allemand | C5: =F5 -> 6 | F5: 6 | G5: 2 | H5: =C5*G5 -> 12 | L5: =IF(C5<11,"NA",IF(C5<15,"ECA",IF(C5<18,"A",IF(C5<20,"A+")))) -> NA | O5: =D5*G5 -> 0 | P5: =E5*G5 -> 0 | Q5: =G5*F5 -> 12
B6: Anglais | C6: =(D6+F6+E6)/3 -> 9.475 | D6: 7.7 | E6: 9.8 | F6: 10.925 | G6: 3 | H6: =C6*G6 -> 28.425 | L6: =IF(C6<11,"NA",IF(C6<15,"ECA",IF(C6<18,"A",IF(C6<20,"A+")))) -> NA | O6: =D6*G6 -> 23.1 | P6: =E6*G6 -> 29.4 | Q6: =G6*F6 -> 32.775
B7: Cor Orthographique/ Dictée | C7: =(D7+F7+E7)/3 -> 7.925 | D7: 7.9 | E7: 7.25 | F7: 8.625 | G7: 1 | H7: =C7*G7 -> 7.925 | L7: =IF(C7<11,"NA",IF(C7<15,"ECA",IF(C7<18,"A",IF(C7<20,"A+")))) -> NA | O7: =D7*G7 -> 7.9 | P7: =E7*G7 -> 7.25 | Q7: =G7*F7 -> 8.625
B8: Espagnol | C8: =F8 -> 7 | F8: 7 | G8: 2 | H8: =C8*G8 -> 14 | L8: =IF(C8<11,"NA",IF(C8<15,"ECA",IF(C8<18,"A",IF(C8<20,"A+")))) -> NA | O8: =D8*G8 -> 0 | P8: =E8*G8 -> 0 | Q8: =G8*F8 -> 14
B9: Etude de Texte | C9: =(D9+F9+E9)/3 -> 7.2166667 | D9: 6.55 | E9: 7.4 | F9: 7.7 | G9: 2 | H9: =C9*G9 -> 14.433333 | L9: =IF(C9<11,"NA",IF(C9<15,"ECA",IF(C9<18,"A",IF(C9<20,"A+")))) -> NA | O9: =D9*G9 -> 13.1 | P9: =E9*G9 -> 14.8 | Q9: =G9*F9 -> 15.4
B10: Expression Ecrite | C10: =(D10+F10+E10)/3 -> 9.56 | D10: 9.7 | E10: 9.53 | F10: 9.45 | G10: 1 | H10: =C10*G10 -> 9.56 | L10: =IF(C10<11,"NA",IF(C10<15,"ECA",IF(C10<18,"A",IF(C10<20,"A+")))) -> NA | O10: =D10*G10 -> 9.7 | P10: =E10*G10 -> 9.53 | Q10: =G10*F10 -> 9.45
B11: Total du GROUPE I :
B12: Moyenne du Groupe : | C12: =(SUM(H5:H10)/SUM(G5:G10)) -> 7.8493939 | G12: Rang de l’élève :
B14: ECM | C14: =(D14+F14+E14)/3 -> 14.966667 | D14: 14.2 | E14: 15.7 | F14: 15 | G14: 2 | H14: =C14*G14 -> 29.933333 | L14: =IF(C14<11,"NA",IF(C14<15,"ECA",IF(C14<18,"A",IF(C14<20,"A+")))) -> ECA | O14: =D14*G14 -> 28.4 | P14: =E14*G14 -> 31.4 | Q14: =G14*F14 -> 30
B15: Géographie | C15: =(D15+F15+E15)/3 -> 14.1 | D15: 12.875 | E15: 16.225 | F15: 13.2 | G15: 1.5 | H15: =C15*G15 -> 21.15 | L15: =IF(C15<11,"NA",IF(C15<15,"ECA",IF(C15<18,"A",IF(C15<20,"A+")))) -> ECA | O15: =D15*G15 -> 19.3125 | P15: =E15*G15 -> 24.3375 | Q15: =G15*F15 -> 19.8
B16: Histoire | C16: =(D16+F16+E16)/3 -> 11.583333 | D16: 10.325 | E16: 12.3 | F16: 12.125 | G16: 1.5 | H16: =C16*G16 -> 17.375 | L16: =IF(C16<11,"NA",IF(C16<15,"ECA",IF(C16<18,"A",IF(C16<20,"A+")))) -> ECA | O16: =D16*G16 -> 15.4875 | P16: =E16*G16 -> 18.45 | Q16: =G16*F16 -> 18.1875
B17: LCN | C17: =(D17+F17+E17)/3 -> 8.625 | D17: 8 | E17: 8.5 | F17: 9.375 | G17: 1 | H17: =C17*G17 -> 8.625 | L17: =IF(C17<11,"NA",IF(C17<15,"ECA",IF(C17<18,"A",IF(C17<20,"A+")))) -> NA | O17: =D17*G17 -> 8 | P17: =E17*G17 -> 8.5 | Q17: =G17*F17 -> 9.375
B18: Total du GROUPE II :
B19: Moyenne du Groupe : | C19: =(SUM(H14:H17)/SUM(G14:G17)) -> 12.847222 | G19: Rang de l’élève :
B21: Informatique | C21: =(D21+F21+E21)/3 -> 10.183333 | D21: 10.2 | E21: 10.65 | F21: 9.7 | G21: 2 | H21: =C21*G21 -> 20.366667 | L21: =IF(C21<11,"NA",IF(C21<15,"ECA",IF(C21<18,"A",IF(C21<20,"A+")))) -> NA | O21: =D21*G21 -> 20.4 | P21: =E21*G21 -> 21.3 | Q21: =G21*F21 -> 19.4
B22: Mathématiques | C22: =(D22+F22+E22)/3 -> 10.2 | D22: 10.55 | E22: 9.35 | F22: 10.7 | G22: 4 | H22: =C22*G22 -> 40.8 | L22: =IF(C22<11,"NA",IF(C22<15,"ECA",IF(C22<18,"A",IF(C22<20,"A+")))) -> NA | O22: =D22*G22 -> 42.2 | P22: =E22*G22 -> 37.4 | Q22: =G22*F22 -> 42.8
B23: PCT | C23: =F23 -> 8 | F23: 8 | G23: 2 | H23: =C23*G23 -> 16 | L23: =IF(C23<11,"NA",IF(C23<15,"ECA",IF(C23<18,"A",IF(C23<20,"A+")))) -> NA | O23: =D23*G23 -> 0 | P23: =E23*G23 -> 0 | Q23: =G23*F23 -> 16
B24: SVTEEHB | C24: =(D24+F24+E24)/3 -> 10.593333 | D24: 7.4 | E24: 10.63 | F24: 13.75 | G24: 2 | H24: =C24*G24 -> 21.186667 | L24: =IF(C24<11,"NA",IF(C24<15,"ECA",IF(C24<18,"A",IF(C24<20,"A+")))) -> NA | O24: =D24*G24 -> 14.8 | P24: =E24*G24 -> 21.26 | Q24: =G24*F24 -> 27.5
B25: Total du GROUPE III :
B26: Moyenne du Groupe : | C26: =(SUM(H21:H24)/SUM(G21:G24)) -> 9.8353333 | G26: Rang de l’élève :
B28: EAC | C28: =(D28+F28+E28)/3 -> 14.5 | D28: 15.5 | E28: 14 | F28: 14 | G28: 1 | H28: =C28*G28 -> 14.5 | L28: =IF(C28<11,"NA",IF(C28<15,"ECA",IF(C28<18,"A",IF(C28<20,"A+")))) -> ECA | O28: =D28*G28 -> 15.5 | P28: =E28*G28 -> 14 | Q28: =G28*F28 -> 14
B29: EPS | C29: =(D29+F29+E29)/3 -> 12.783333 | D29: 12.7 | E29: 15.15 | F29: 10.5 | G29: 2 | H29: =C29*G29 -> 25.566667 | L29: =IF(C29<11,"NA",IF(C29<15,"ECA",IF(C29<18,"A",IF(C29<20,"A+")))) -> ECA | O29: =D29*G29 -> 25.4 | P29: =E29*G29 -> 30.3 | Q29: =G29*F29 -> 21
B30: ESF | C30: =(D30+F30+E30)/3 -> 12.733333 | D30: 12.5 | E30: 11.7 | F30: 14 | G30: 1 | H30: =C30*G30 -> 12.733333 | L30: =IF(C30<11,"NA",IF(C30<15,"ECA",IF(C30<18,"A",IF(C30<20,"A+")))) -> ECA | O30: =D30*G30 -> 12.5 | P30: =E30*G30 -> 11.7 | Q30: =G30*F30 -> 14
B31: Travail Manuel | C31: =(D31+F31+E31)/3 -> 15.666667 | D31: 16 | E31: 16 | F31: 15 | G31: 1 | H31: =C31*G31 -> 15.666667 | L31: =IF(C31<11,"NA",IF(C31<15,"ECA",IF(C31<18,"A",IF(C31<20,"A+")))) -> A | O31: =D31*G31 -> 16 | P31: =E31*G31 -> 16 | Q31: =G31*F31 -> 15
B32: Total du GROUPE IV : | O32: =SUM(O6:O31) -> 271.8 | P32: =SUM(P6:P31) -> 295.6275 | Q32: =SUM(Q5:Q31) -> 339.3125
B33: Moyenne du Groupe : | C33: =(SUM(H28:H31)/SUM(G28:G31)) -> 13.693333 | G33: Rang de l’élève : | O33: 26 | P33: 26 | Q33: 32
O34: =O32/O33 -> 10.453846 | P34: =P32/P33 -> 11.370288 | Q34: =Q32/Q33 -> 10.603516
B35: Total Général (GI + GII + GIII+GIV) = | C35: Moy Gle de la Classe : | F35: Moy du 1er : | I35: Moy du Dernier :
C36: TRIM 1 | D36: TRIM 2 | E36: TRIM3
B37: Moyennes de l’Elève : | C37: =O34 -> 10.453846 | D37: =P34 -> 11.370288 | E37: =Q34 -> 10.603516 | F37: Annuel : | G37: =(H5+H6+H7+H8+H9+H10+H14+H15+H16+H17+H21+H22+H23+H24+H28+H29+H30+H31)/32 -> 10.320208 | H37: /20 | I37: Rang de l’élève : | L37: /20
B39: v La moyenne Annuelle n’est pas égale à la moyenne arithmétique des trimestres
B40: DECISIONS ET OBSERVATIONS / Décisions And Observations
B41: DISCIPLINE / Disciplin | C41: Appréciation du travail de l’élève | G41: TRAVAIL / Academic Work
B42: Nb d’Heures : | C42: =IF(G37<11,"NA",IF(G37<15,"ECA",IF(G37<18,"A",IF(G37<20,"A+")))) -> NA | D42: =IF(#REF!<11,"NA",IF(#REF!<15,"ECA",IF(#REF!<18,"A",IF(#REF!<20,"A+")))) -> #REF! | F42: =IF(#REF!<11,"NA",IF(#REF!<15,"ECA",IF(#REF!<18,"A",IF(#REF!<20,"A+")))) -> #REF!
B43: Nb de jrnées : | C43: =IF(#REF!<11,"NA",IF(#REF!<15,"ECA",IF(#REF!<18,"A",IF(#REF!<20,"A+")))) -> #REF! | D43: =IF(#REF!<11,"NA",IF(#REF!<15,"ECA",IF(#REF!<18,"A",IF(#REF!<20,"A+")))) -> #REF! | F43: =IF(#REF!<11,"NA",IF(#REF!<15,"ECA",IF(#REF!<18,"A",IF(#REF!<20,"A+")))) -> #REF! | G43: Tableau d’honneur / Honour roll | K43: Observations et Visa du Principal
B44: Exclusions / Suspensions | C44: =IF(#REF!<11,"NA",IF(#REF!<15,"ECA",IF(#REF!<18,"A",IF(#REF!<20,"A+")))) -> #REF! | D44: =IF(#REF!<11,"NA",IF(#REF!<15,"ECA",IF(#REF!<18,"A",IF(#REF!<20,"A+")))) -> #REF! | F44: =IF(#REF!<11,"NA",IF(#REF!<15,"ECA",IF(#REF!<18,"A",IF(#REF!<20,"A+")))) -> #REF! | G44: Encouragements / Encouragements | K44: Observations and Signature of Principal
B45: Blâme / Blame | C45: Observations et Remarques du Professeur Principal | G45: Félicitations / Congratulations
B46: Avertissements / Warnings | G46: Décisions du Conseil de Classe | K46: Yaoundé le
B47: Observations et Remarques du parent de l’élève | K47: Le Principal

Sheet METOUWE
B4: MATIERES | C4: Annuel | D4: TRIM 1 | E4: TRIM 2 | F4: TRIM 3 | G4: Coef | H4: Moy × Coef | I4: Moy Gle Classe | K4: Rang | L4: Appréciations
B5: Allemand | C5: =F5 -> 11.5 | F5: 11.5 | G5: 2 | H5: =C5*G5 -> 23 | L5: =IF(C5<11,"NA",IF(C5<15,"ECA",IF(C5<18,"A",IF(C5<20,"A+")))) -> ECA | O5: =D5*G5 -> 0 | P5: =E5*G5 -> 0 | Q5: =G5*F5 -> 23
