Workbook

Sheet ABENA
B4: MATIERES | C4: ANNUEL | D4: TRIM 1 | E4: TRIM 2 | F4: TRIM 3 | G4: Coef | H4: Moy × Coef | I4: Moy Gle Classe | K4: Rang | L4: Appréciations
B5: Anglais | C5: =(D5+F5+E5)/3 -> 8.7166667 | D5: 10 | E5: 7.4 | F5: 8.75 | G5: 3 | H5: =C5*G5 -> 26.15 | L5: =IF(C5<11,"NA",IF(C5<15,"ECA",IF(C5<18,"A",IF(C5<20,"A+")))) -> NA | O5: =D5*G5 -> 30 | P5: =E5*G5 -> 22.2 | Q5: =G5*F5 -> 26.25
B6: Cor Orthographique/ Dictée | C6: =(D6+F6+E6)/3 -> 8.26 | D6: 5.5 | E6: 5.03 | F6: 14.25 | G6: 1 | H6: =C6*G6 -> 8.26 | L6: =IF(C6<11,"NA",IF(C6<15,"ECA",IF(C6<18,"A",IF(C6<20,"A+")))) -> NA | O6: =D6*G6 -> 5.5 | P6: =E6*G6 -> 5.03 | Q6: =G6*F6 -> 14.25
B7: Etude de Texte | C7: =(D7+F7+E7)/3 -> 11.933333 | D7: 13.4 | E7: 10.65 | F7: 11.75 | G7: 2 | H7: =C7*G7 -> 23.866667 | L7: =IF(C7<11,"NA",IF(C7<15,"ECA",IF(C7<18,"A",IF(C7<20,"A+")))) -> ECA | O7: =D7*G7 -> 26.8 | P7: =E7*G7 -> 21.3 | Q7: =G7*F7 -> 23.5
B8: Expression Ecrite | C8: =(D8+F8+E8)/3 -> 9.04 | D8: 9.9 | E8: 8.22 | F8: 9 | G8: 1 | H8: =C8*G8 -> 9.04 | L8: =IF(C8<11,"NA",IF(C8<15,"ECA",IF(C8<18,"A",IF(C8<20,"A+")))) -> NA | O8: =D8*G8 -> 9.9 | P8: =E8*G8 -> 8.22 | Q8: =G8*F8 -> 9
B9: Langue Vivante II | C9: =(D9+F9+E9)/3 -> 10.883333 | D9: 12.1 | E9: 11.8 | F9: 8.75 | G9: 2 | H9: =C9*G9 -> 21.766667 | L9: =IF(C9<11,"NA",IF(C9<15,"ECA",IF(C9<18,"A",IF(C9<20,"A+")))) -> NA | O9: =D9*G9 -> 24.2 | P9: =E9*G9 -> 23.6 | Q9: =G9*F9 -> 17.5
B10: Total du GROUPE I :
B11: Moyenne du Groupe : | C11: =(SUM(H5:H9)/SUM(G5:G9)) -> 9.8981481 | G11: Rang de l’élève :
B13: ECM | C13: =(D13+F13+E13)/3 -> 11.041667 | D13: 11.25 | E13: 11.125 | F13: 10.75 | G13: 2 | H13: =C13*G13 -> 22.083333 | L13: =IF(C13<11,"NA",IF(C13<15,"ECA",IF(C13<18,"A",IF(C13<20,"A+")))) -> ECA | O13: =D13*G13 -> 22.5 | P13: =E13*G13 -> 22.25 | Q13: =G13*F13 -> 21.5
B14: Géographie | C14: =(D14+F14+E14)/3 -> 10.758333 | D14: 9.75 | E14: 10.6 | F14: 11.925 | G14: 1.5 | H14: =C14*G14 -> 16.1375 | L14: =IF(C14<11,"NA",IF(C14<15,"ECA",IF(C14<18,"A",IF(C14<20,"A+")))) -> NA | O14: =D14*G14 -> 14.625 | P14: =E14*G14 -> 15.9 | Q14: =G14*F14 -> 17.8875
B15: Histoire | C15: =(D15+F15+E15)/3 -> 9.2666667 | D15: 8.6 | E15: 9.45 | F15: 9.75 | G15: 1.5 | H15: =C15*G15 -> 13.9 | L15: =IF(C15<11,"NA",IF(C15<15,"ECA",IF(C15<18,"A",IF(C15<20,"A+")))) -> NA | O15: =D15*G15 -> 12.9 | P15: =E15*G15 -> 14.175 | Q15: =G15*F15 -> 14.625
B16: LCN | C16: =(D16+F16+E16)/3 -> 10.583333 | D16: 9.75 | E16: 10 | F16: 12 | G16: 1 | H16: =C16*G16 -> 10.583333 | L16: =IF(C16<11,"NA",IF(C16<15,"ECA",IF(C16<18,"A",IF(C16<20,"A+")))) -> NA | O16: =D16*G16 -> 9.75 | P16: =E16*G16 -> 10 | Q16: =G16*F16 -> 12
B17: Total du GROUPE II :
B18: Moyenne du Groupe : | C18: =(SUM(H13:H16)/SUM(G13:G16)) -> 10.450694 | G18: Rang de l’élève :
B20: Informatique | C20: =(D20+F20+E20)/3 -> 12.383333 | D20: 11.4 | E20: 12.75 | F20: 13 | G20: 2 | H20: =C20*G20 -> 24.766667 | L20: =IF(C20<11,"NA",IF(C20<15,"ECA",IF(C20<18,"A",IF(C20<20,"A+")))) -> ECA | O20: =D20*G20 -> 22.8 | P20: =E20*G20 -> 25.5 | Q20: =G20*F20 -> 26
B21: Mathématiques | C21: =(D21+F21+E21)/3 -> 5.5383333 | D21: 6.37 | E21: 4.795 | F21: 5.45 | G21: 4 | H21: =C21*G21 -> 22.153333 | L21: =IF(C21<11,"NA",IF(C21<15,"ECA",IF(C21<18,"A",IF(C21<20,"A+")))) -> NA | O21: =D21*G21 -> 25.48 | P21: =E21*G21 -> 19.18 | Q21: =G21*F21 -> 21.8
B22: PCT | C22: =(D22+F22+E22)/3 -> 8.8416667 | D22: 7.4 | E22: 10.725 | F22: 8.4 | G22: 2 | H22: =C22*G22 -> 17.683333 | L22: =IF(C22<11,"NA",IF(C22<15,"ECA",IF(C22<18,"A",IF(C22<20,"A+")))) -> NA | O22: =D22*G22 -> 14.8 | P22: =E22*G22 -> 21.45 | Q22: =G22*F22 -> 16.8
B23: SVTEEHB | C23: =(D23+F23+E23)/3 -> 10.65 | D23: 11.1 | E23: 10.5 | F23: 10.35 | G23: 2 | H23: =C23*G23 -> 21.3 | L23: =IF(C23<11,"NA",IF(C23<15,"ECA",IF(C23<18,"A",IF(C23<20,"A+")))) -> NA | O23: =D23*G23 -> 22.2 | P23: =E23*G23 -> 21 | Q23: =G23*F23 -> 20.7
B24: Total du GROUPE III :
B25: Moyenne du Groupe : | C25: =(SUM(H20:H23)/SUM(G20:G23)) -> 8.5903333 | G25: Rang de l’élève :
B27: EAC | C27: =(D27+F27+E27)/2 -> 14.5 | D27: 17 | E27: 0 | F27: 12 | G27: 1 | H27: =C27*G27 -> 14.5 | L27: =IF(C27<11,"NA",IF(C27<15,"ECA",IF(C27<18,"A",IF(C27<20,"A+")))) -> ECA | O27: =D27*G27 -> 17 | P27: =E27*G27 -> 0 | Q27: =G27*F27 -> 12
B28: EPS | C28: =(D28+F28+E28)/3 -> 12.833333 | D28: 13.5 | E28: 12.25 | F28: 12.75 | G28: 2 | H28: =C28*G28 -> 25.666667 | L28: =IF(C28<11,"NA",IF(C28<15,"ECA",IF(C28<18,"A",IF(C28<20,"A+")))) -> ECA | O28: =D28*G28 -> 27 | P28: =E28*G28 -> 24.5 | Q28: =G28*F28 -> 25.5
B29: ESF | C29: =(D29+F29+E29)/2 -> 14 | D29: 13 | E29: 15 | F29: 0 | G29: 1 | H29: =C29*G29 -> 14 | L29: =IF(C29<11,"NA",IF(C29<15,"ECA",IF(C29<18,"A",IF(C29<20,"A+")))) -> ECA | O29: =D29*G29 -> 13 | P29: =E29*G29 -> 15 | Q29: =G29*F29 -> 0
B30: Travail Manuel | C30: =(D30+F30+E30)/2 -> 13.75 | D30: 12 | E30: 0 | F30: 15.5 | G30: 1 | H30: =C30*G30 -> 13.75 | L30: =IF(C30<11,"NA",IF(C30<15,"ECA",IF(C30<18,"A",IF(C30<20,"A+")))) -> ECA | O30: =D30*G30 -> 12 | P30: =E30*G30 -> 0 | Q30: =G30*F30 -> 15.5
B31: Total du GROUPE IV : | O31: =SUM(O5:O30) -> 310.455 | P31: =SUM(P5:P30) -> 269.305 | Q31: =SUM(Q5:Q30) -> 294.8125
B32: Moyenne du Groupe : | C32: =(SUM(H27:H30)/SUM(G27:G30)) -> 13.583333 | G32: Rang de l’élève : | O32: 30 | P32: 28 | Q32: 29
O33: =O31/O32 -> 10.3485 | P33: =P31/P32 -> 9.6180357 | Q33: =Q31/Q32 -> 10.165948
B34: Total Général (GI + GII + GIII+GIV) = | C34: Moy Gle de la Classe : | F34: Moy du 1er : | I34: Moy du Dernier :
C35: TRIM 1 | D35: TRIM 2 | E35: TRIM 3
B36: Moyennes de l’Elève : | C36: =O33 -> 10.3485 | D36: =P33 -> 9.6180357 | E36: =Q33 -> 10.165948 | F36: MOY ANNUELLE | G36: =(H5+H6+H7+H8+H9+H13+H14+H15+H20+H16+H21+H22+H23+H27+H28+H29+H30)/30 -> 10.186917 | H36: /20 | I36: Rang de l’élève : | L36: /20
B38: v La moyenne Annuelle n’est pas égale à la moyenne arithmétique des trimestres
B39: DECISIONS ET OBSERVATIONS / Décisions And Observations
B40: DISCIPLINE / Disciplin | C40: Appréciation du travail de l’élève | G40: TRAVAIL / Academic Work
B41: Nb d’Heures : | C41: =IF(G36<11,"NA",IF(G36<15,"ECA",IF(G36<18,"A",IF(G36<20,"A+")))) -> NA | D41: =IF(#REF!<11,"NA",IF(#REF!<15,"ECA",IF(#REF!<18,"A",IF(#REF!<20,"A+")))) -> #REF! | F41: =IF(#REF!<11,"NA",IF(#REF!<15,"ECA",IF(#REF!<18,"A",IF(#REF!<20,"A+")))) -> #REF!
B42: Nb de jrnées : | C42: =IF(#REF!<11,"NA",IF(#REF!<15,"ECA",IF(#REF!<18,"A",IF(#REF!<20,"A+")))) -> #REF! | D42: =IF(#REF!<11,"NA",IF(#REF!<15,"ECA",IF(#REF!<18,"A",IF(#REF!<20,"A+")))) -> #REF! | F42: =IF(#REF!<11,"NA",IF(#REF!<15,"ECA",IF(#REF!<18,"A",IF(#REF!<20,"A+")))) -> #REF! | G42: Tableau d’honneur / Honour roll | K42: Observations et Visa du Principal
B43: Exclusions / Suspensions | C43: =IF(#REF!<11,"NA",IF(#REF!<15,"ECA",IF(#REF!<18,"A",IF(#REF!<20,"A+")))) -> #REF! | D43: =IF(#REF!<11,"NA",IF(#REF!<15,"ECA",IF(#REF!<18,"A",IF(#REF!<20,"A+")))) -> #REF! | F43: =IF(#REF!<11,"NA",IF(#REF!<15,"ECA",IF(#REF!<18,"A",IF(#REF!<20,"A+")))) -> #REF! | G43: Encouragements / Encouragements | K43: Observations and Signature of Principal
B44: Blâme / Blame | C44: Observations et Remarques du Professeur Principal | G44: Félicitations / Congratulations
B45: Avertissements / Warnings | G45: Décisions du Conseil de Classe | K45: Yaoundé le
B46: Observations et Remarques du parent de l’élève | K46: Le Principal

Sheet AGNANANE
B4: MATIERES | C4: ANNUEL | D4: TRIM 1 | E4: TRIM 2 | F4: TRIM 3 | G4: Coef | H4: Moy × Coef | I4: Moy Gle Classe | K4: Rang | L4: Appréciations
B5: Anglais | C5: =(D5+F5+E5)/3 -> 7.15 | D5: 7.5 | E5: 6.7 | F5: 7.25 | G5: 3 | H5: =C5*G5 -> 21.45 | L5: =IF(C5<11,"NA",IF(C5<15,"ECA",IF(C5<18,"A",IF(C5<20,"A+")))) -> NA | O5: =D5*G5 -> 22.5 | P5: =E5*G5 -> 20.1 | Q5: =G5*F5 -> 21.75
B6: Cor Orthographique/ Dictée | C6: =(D6+F6+E6)/3 -> 8.455 | D6: 6.1 | E6: 5.015 | F6: 14.25 | G6: 1 | H6: =C6*G6 -> 8.455 | L6: =IF(C6<11,"NA",IF(C6<15,"ECA",IF(C6<18,"A",IF(C6<20,"A+")))) -> NA | O6: =D6*G6 -> 6.1 | P6: =E6*G6 -> 5.015 | Q6: =G6*F6 -> 14.25
B7: Etude de Texte | C7: =(D7+F7+E7)/3 -> 9.6216667 | D7: 9.15 | E7: 9.965 | F7: 9.75 | G7: 2 | H7: =C7*G7 -> 19.243333 | L7: =IF(C7<11,"NA",IF(C7<15,"ECA",IF(C7<18,"A",IF(C7<20,"A+")))) -> NA | O7: =D7*G7 -> 18.3 | P7: =E7*G7 -> 19.93 | Q7: =G7*F7 -> 19.5
B8: Expression Ecrite | C8: =(D8+F8+E8)/3 -> 9.2333333 | D8: 9.915 | E8: 8.785 | F8: 9 | G8: 1 | H8: =C8*G8 -> 9.2333333 | L8: =IF(C8<11,"NA",IF(C8<15,"ECA",IF(C8<18,"A",IF(C8<20,"A+")))) -> NA | O8: =D8*G8 -> 9.915 | P8: =E8*G8 -> 8.785 | Q8: =G8*F8 -> 9
B9: Langue Vivante II | C9: =(D9+F9+E9)/3 -> 10.458333 | D9: 13.9 | E9: 10.6 | F9: 6.875 | G9: 2 | H9: =C9*G9 -> 20.916667 | L9: =IF(C9<11,"NA",IF(C9<15,"ECA",IF(C9<18,"A",IF(C9<20,"A+")))) -> NA | O9: =D9*G9 -> 27.8 | P9: =E9*G9 -> 21.2 | Q9: =G9*F9 -> 13.75
B10: Total du GROUPE I :
B11: Moyenne du Groupe : | C11: =(SUM(H5:H9)/SUM(G5:G9)) -> 8.8109259 | G11: Rang de l’élève :
B13: ECM | C13: =(D13+F13+E13)/3 -> 11.633333 | D13: 13.075 | E13: 10.825 | F13: 11 | G13: 2 | H13: =C13*G13 -> 23.266667 | L13: =IF(C13<11,"NA",IF(C13<15,"ECA",IF(C13<18,"A",IF(C13<20,"A+")))) -> ECA | O13: =D13*G13 -> 26.15 | P13: =E13*G13 -> 21.65 | Q13: =G13*F13 -> 22
B14: Géographie | C14: =(D14+F14+E14)/3 -> 12.083333 | D14: 8.875 | E14: 14 | F14: 13.375 | G14: 1.5 | H14: =C14*G14 -> 18.125 | L14: =IF(C14<11,"NA",IF(C14<15,"ECA",IF(C14<18,"A",IF(C14<20,"A+")))) -> ECA | O14: =D14*G14 -> 13.3125 | P14: =E14*G14 -> 21 | Q14: =G14*F14 -> 20.0625
B15: Histoire | C15: =(D15+F15+E15)/3 -> 8.7833333 | D15: 8.8 | E15: 8.05 | F15: 9.5 | G15: 1.5 | H15: =C15*G15 -> 13.175 | L15: =IF(C15<11,"NA",IF(C15<15,"ECA",IF(C15<18,"A",IF(C15<20,"A+")))) -> NA | O15: =D15*G15 -> 13.2 | P15: =E15*G15 -> 12.075 | Q15: =G15*F15 -> 14.25
B16: LCN | C16: =(D16+F16+E16)/3 -> 12.166667 | D16: 12 | E16: 13.5 | F16: 11 | G16: 1 | H16: =C16*G16 -> 12.166667 | L16: =IF(C16<11,"NA",IF(C16<15,"ECA",IF(C16<18,"A",IF(C16<20,"A+")))) -> ECA | O16: =D16*G16 -> 12 | P16: =E16*G16 -> 13.5 | Q16: =G16*F16 -> 11
B17: Total du GROUPE II :
B18: Moyenne du Groupe : | C18: =(SUM(H13:H16)/SUM(G13:G16)) -> 11.122222 | G18: Rang de l’élève :
B20: Informatique | C20: =(D20+F20+E20)/3 -> 8.4916667 | D20: 5.6 | E20: 9 | F20: 10.875 | G20: 2 | H20: =C20*G20 -> 16.983333 | L20: =IF(C20<11,"NA",IF(C20<15,"ECA",IF(C20<18,"A",IF(C20<20,"A+")))) -> NA | O20: =D20*G20 -> 11.2 | P20: =E20*G20 -> 18 | Q20: =G20*F20 -> 21.75
B21: Mathématiques | C21: =(D21+F21+E21)/3 -> 5.5033333 | D21: 5.375 | E21: 6.51 | F21: 4.625 | G21: 4 | H21: =C21*G21 -> 22.013333 | L21: =IF(C21<11,"NA",IF(C21<15,"ECA",IF(C21<18,"A",IF(C21<20,"A+")))) -> NA | O21: =D21*G21 -> 21.5 | P21: =E21*G21 -> 26.04 | Q21: =G21*F21 -> 18.5
B22: PCT | C22: =(D22+F22+E22)/3 -> 8.7416667 | D22: 8.1 | E22: 10.225 | F22: 7.9 | G22: 2 | H22: =C22*G22 -> 17.483333 | L22: =IF(C22<11,"NA",IF(C22<15,"ECA",IF(C22<18,"A",IF(C22<20,"A+")))) -> NA | O22: =D22*G22 -> 16.2 | P22: =E22*G22 -> 20.45 | Q22: =G22*F22 -> 15.8
B23: SVTEEHB | C23: =(D23+F23+E23)/3 -> 9.65 | D23: 10.325 | E23: 9.25 | F23: 9.375 | G23: 2 | H23: =C23*G23 -> 19.3 | L23: =IF(C23<11,"NA",IF(C23<15,"ECA",IF(C23<18,"A",IF(C23<20,"A+")))) -> NA | O23: =D23*G23 -> 20.65 | P23: =E23*G23 -> 18.5 | Q23: =G23*F23 -> 18.75
B24: Total du GROUPE III :
B25: Moyenne du Groupe : | C25: =(SUM(H20:H23)/SUM(G20:G23)) -> 7.578 | G25: Rang de l’élève :
B27: EAC | C27: =(D27+F27+E27)/2 -> 15.75 | D27: 13.5 | E27: 0 | F27: 18 | G27: 1 | H27: =C27*G27 -> 15.75 | L27: =IF(C27<11,"NA",IF(C27<15,"ECA",IF(C27<18,"A",IF(C27<20,"A+")))) -> A | O27: =D27*G27 -> 13.5 | P27: =E27*G27 -> 0 | Q27: =G27*F27 -> 18
B28: EPS | C28: =(D28+F28+E28)/3 -> 12.25 | D28: 14.25 | E28: 11 | F28: 11.5 | G28: 2 | H28: =C28*G28 -> 24.5 | L28: =IF(C28<11,"NA",IF(C28<15,"ECA",IF(C28<18,"A",IF(C28<20,"A+")))) -> ECA | O28: =D28*G28 -> 28.5 | P28: =E28*G28 -> 22 | Q28: =G28*F28 -> 23
B29: ESF | C29: =(D29+F29+E29)/2 -> 16.5 | D29: 15 | E29: 18 | F29: 0 | G29: 1 | H29: =C29*G29 -> 16.5 | L29: =IF(C29<11,"NA",IF(C29<15,"ECA",IF(C29<18,"A",IF(C29<20,"A+")))) -> A | O29: =D29*G29 -> 15 | P29: =E29*G29 -> 18 | Q29: =G29*F29 -> 0
B30: Travail Manuel | C30: =(D30+F30+E30)/2 -> 15 | D30: 14.5 | E30: 0 | F30: 15.5 | G30: 1 | H30: =C30*G30 -> 15 | L30: =IF(C30<11,"NA",IF(C30<15,"ECA",IF(C30<18,"A",IF(C30<20,"A+")))) -> A | O30: =D30*G30 -> 14.5 | P30: =E30*G30 -> 0 | Q30: =G30*F30 -> 15.5
B31: Total du GROUPE IV : | O31: =SUM(O5:O30) -> 290.3275 | P31: =SUM(P5:P30) -> 266.245 | Q31: =SUM(Q5:Q30) -> 276.8625
B32: Moyenne du Groupe : | C32: =(SUM(H27:H30)/SUM(G27:G30)) -> 14.35 | G32: Rang de l’élève : | O32: 30 | P32: 28 | Q32: 29
O33: =O31/O32 -> 9.6775833 | P33: =P31/P32 -> 9.50875 | Q33: =Q31/Q32 -> 9.5469828
B34: Total Général (GI + GII + GIII+GIV) = | C34: Moy Gle de la Classe : | F34: Moy du 1er : | I34: Moy du Dernier :
C35: TRIM 1 | D35: TRIM 2 | E35: TRIM 3
B36: Moyennes de l’Elève : | C36: =O33 -> 9.6775833 | D36: =P33 -> 9.50875 | E36: =Q33 -> 9.5469828 | F36: MOY ANNUELLE | G36: =(H5+H6+H7+H8+H9+H13+H14+H15+H20+H16+H21+H22+H23+H27+H28+H29+H30)/30 -> 9.7853889 | H36: /20 | I36: Rang de l’élève : | L36: /20
B38: v La moyenne Annuelle n’est pas égale à la moyenne arithmétique des trimestres
B39: DECISIONS ET OBSERVATIONS / Décisions And Observations
B40: DISCIPLINE / Disciplin | C40: Appréciation du travail de l’élève | G40: TRAVAIL / Academic Work
B41: Nb d’Heures : | C41: =IF(G36<11,"NA",IF(G36<15,"ECA",IF(G36<18,"A",IF(G36<20,"A+")))) -> NA | D41: =IF(#REF!<11,"NA",IF(#REF!<15,"ECA",IF(#REF!<18,"A",IF(#REF!<20,"A+")))) -> #REF! | F41: =IF(#REF!<11,"NA",IF(#REF!<15,"ECA",IF(#REF!<18,"A",IF(#REF!<20,"A+")))) -> #REF!
B42: Nb de jrnées : | C42: =IF(#REF!<11,"NA",IF(#REF!<15,"ECA",IF(#REF!<18,"A",IF(#REF!<20,"A+")))) -> #REF! | D42: =IF(#REF!<11,"NA",IF(#REF!<15,"ECA",IF(#REF!<18,"A",IF(#REF!<20,"A+")))) -> #REF! | F42: =IF(#REF!<11,"NA",IF(#REF!<15,"ECA",IF(#REF!<18,"A",IF(#REF!<20,"A+")))) -> #REF! | G42: Tableau d’honneur / Honour roll | K42: Observations et Visa du Principal
B43: Exclusions / Suspensions | C43: =IF(#REF!<11,"NA",IF(#REF!<15,"ECA",IF(#REF!<18,"A",IF(#REF!<20,"A+")))) -> #REF! | D43: =IF(#REF!<11,"NA",IF(#REF!<15,"ECA",IF(#REF!<18,"A",IF(#REF!<20,"A+")))) -> #REF! | F43: =IF(#REF!<11,"NA",IF(#REF!<15,"ECA",IF(#REF!<18,"A",IF(#REF!<20,"A+")))) -> #REF! | G43: Encouragements / Encouragements | K43: Observations and Signature of Principal
B44: Blâme / Blame | C44: Observations et Remarques du Professeur Principal | G44: Félicitations / Congratulations
B45: Avertissements / Warnings | G45: Décisions du Conseil de Classe | K45: Yaoundé le
B46: Observations et Remarques du parent de l’élève | K46: Le Principal

Sheet ALIMA
B4: MATIERES | C4: ANNUEL | D4: TRIM 1 | E4: TRIM 2 | F4: TRIM 3 | G4: Coef | H4: Moy × Coef | I4: Moy Gle Classe | K4: Rang | L4: Appréciations
B5: Anglais | C5: =(D5+F5+E5)/3 -> 7.9583333 | D5: 7 | E5: 8.5 | F5: 8.375 | G5: 3 | H5: =C5*G5 -> 23.875 | L5: =IF(C5<11,"NA",IF(C5<15,"ECA",IF(C5<18,"A",IF(C5<20,"A+")))) -> NA | O5: =D5*G5 -> 21 | P5: =E5*G5 -> 25.5 | Q5: =G5*F5 -> 25.125
B6: Cor Orthographique/ Dictée | C6: =(D6+F6+E6)/3 -> 4.0916667 | D6: 1.3 | E6: 3.6 | F6: 7.375 | G6: 1 | H6: =C6*G6 -> 4.0916667 | L6: =IF(C6<11,"NA",IF(C6<15,"ECA",IF(C6<18,"A",IF(C6<20,"A+")))) -> NA | O6: =D6*G6 -> 1.3 | P6: =E6*G6 -> 3.6 | Q6: =G6*F6 -> 7.375
B7: Etude de Texte | C7: =(D7+F7+E7)/3 -> 10.645 | D7: 8.3 | E7: 10.135 | F7: 13.5 | G7: 2 | H7: =C7*G7 -> 21.29 | L7: =IF(C7<11,"NA",IF(C7<15,"ECA",IF(C7<18,"A",IF(C7<20,"A+")))) -> NA | O7: =D7*G7 -> 16.6 | P7: =E7*G7 -> 20.27 | Q7: =G7*F7 -> 27
B8: Expression Ecrite | C8: =(D8+F8+E8)/3 -> 8.26 | D8: 6.9 | E8: 7.88 | F8: 10 | G8: 1 | H8: =C8*G8 -> 8.26 | L8: =IF(C8<11,"NA",IF(C8<15,"ECA",IF(C8<18,"A",IF(C8<20,"A+")))) -> NA | O8: =D8*G8 -> 6.9 | P8: =E8*G8 -> 7.88 | Q8: =G8*F8 -> 10
B9: Langue Vivante II | C9: =(D9+F9+E9)/3 -> 10.65 | D9: 11.8 | E9: 11.9 | F9: 8.25 | G9: 2 | H9: =C9*G9 -> 21.3 | L9: =IF(C9<11,"NA",IF(C9<15,"ECA",IF(C9<18,"A",IF(C9<20,"A+")))) -> NA | O9: =D9*G9 -> 23.6 | P9: =E9*G9 -> 23.8 | Q9: =G9*F9 -> 16.5
B10: Total du GROUPE I :
B11: Moyenne du Groupe : | C11: =(SUM(H5:H9)/SUM(G5:G9)) -> 8.7574074 | G11: Rang de l’élève :
B13: ECM | C13: =(D13+F13+E13)/3 -> 10.875 | D13: 9.45 | E13: 12.175 | F13: 11 | G13: 2 | H13: =C13*G13 -> 21.75 | L13: =IF(C13<11,"NA",IF(C13<15,"ECA",IF(C13<18,"A",IF(C13<20,"A+")))) -> NA | O13: =D13*G13 -> 18.9 | P13: =E13*G13 -> 24.35 | Q13: =G13*F13 -> 22
B14: Géographie | C14: =(D14+F14+E14)/3 -> 13.208333 | D14: 11 | E14: 12.875 | F14: 15.75 | G14: 1.5 | H14: =C14*G14 -> 19.8125 | L14: =IF(C14<11,"NA",IF(C14<15,"ECA",IF(C14<18,"A",IF(C14<20,"A+")))) -> ECA | O14: =D14*G14 -> 16.5 | P14: =E14*G14 -> 19.3125 | Q14: =G14*F14 -> 23.625
B15: Histoire | C15: =(D15+F15+E15)/3 -> 10.15 | D15: 8.5 | E15: 10.7 | F15: 11.25 | G15: 1.5 | H15: =C15*G15 -> 15.225 | L15: =IF(C15<11,"NA",IF(C15<15,"ECA",IF(C15<18,"A",IF(C15<20,"A+")))) -> NA | O15: =D15*G15 -> 12.75 | P15: =E15*G15 -> 16.05 | Q15: =G15*F15 -> 16.875
B16: LCN | C16: =(D16+F16+E16)/3 -> 12.333333 | D16: 14.5 | E16: 10 | F16: 12.5 | G16: 1 | H16: =C16*G16 -> 12.333333 | L16: =IF(C16<11,"NA",IF(C16<15,"ECA",IF(C16<18,"A",IF(C16<20,"A+")))) -> ECA | O16: =D16*G16 -> 14.5 | P16: =E16*G16 -> 10 | Q16: =G16*F16 -> 12.5
B17: Total du GROUPE II :
B18: Moyenne du Groupe : | C18: =(SUM(H13:H16)/SUM(G13:G16)) -> 11.520139 | G18: Rang de l’élève :
B20: Informatique | C20: =(D20+F20+E20)/3 -> 11.083333 | D20: 12.25 | E20: 9.75 | F20: 11.25 | G20: 2 | H20: =C20*G20 -> 22.166667 | L20: =IF(C20<11,"NA",IF(C20<15,"ECA",IF(C20<18,"A",IF(C20<20,"A+")))) -> ECA | O20: =D20*G20 -> 24.5 | P20: =E20*G20 -> 19.5 | Q20: =G20*F20 -> 22.5
B21: Mathématiques | C21: =(D21+F21+E21)/3 -> 3.4433333 | D21: 2.13 | E21: 3.95 | F21: 4.25 | G21: 4 | H21: =C21*G21 -> 13.773333 | L21: =IF(C21<11,"NA",IF(C21<15,"ECA",IF(C21<18,"A",IF(C21<20,"A+")))) -> NA | O21: =D21*G21 -> 8.52 | P21: =E21*G21 -> 15.8 | Q21: =G21*F21 -> 17
B22: PCT | C22: =(D22+F22+E22)/3 -> 5.7666667 | D22: 3.95 | E22: 4.875 | F22: 8.475 | G22: 2 | H22: =C22*G22 -> 11.533333 | L22: =IF(C22<11,"NA",IF(C22<15,"ECA",IF(C22<18,"A",IF(C22<20,"A+")))) -> NA | O22: =D22*G22 -> 7.9 | P22: =E22*G22 -> 9.75 | Q22: =G22*F22 -> 16.95
B23: SVTEEHB | C23: =(D23+F23+E23)/3 -> 9.175 | D23: 8.7 | E23: 8.6 | F23: 10.225 | G23: 2 | H23: =C23*G23 -> 18.35 | L23: =IF(C23<11,"NA",IF(C23<15,"ECA",IF(C23<18,"A",IF(C23<20,"A+")))) -> NA | O23: =D23*G23 -> 17.4 | P23: =E23*G23 -> 17.2 | Q23: =G23*F23 -> 20.45
B24: Total du GROUPE III :
B25: Moyenne du Groupe : | C25: =(SUM(H20:H23)/SUM(G20:G23)) -> 6.5823333 | G25: Rang de l’élève :
B27: EAC | C27: =(D27+F27+E27)/2 -> 13.5 | D27: 14 | E27: 0 | F27: 13 | G27: 1 | H27: =C27*G27 -> 13.5 | L27: =IF(C27<11,"NA",IF(C27<15,"ECA",IF(C27<18,"A",IF(C27<20,"A+")))) -> ECA | O27: =D27*G27 -> 14 | P27: =E27*G27 -> 0 | Q27: =G27*F27 -> 13
B28: EPS | C28: =(D28+F28+E28)/3 -> 13.25 | D28: 12 | E28: 14.5 | F28: 13.25 | G28: 2 | H28: =C28*G28 -> 26.5 | L28: =IF(C28<11,"NA",IF(C28<15,"ECA",IF(C28<18,"A",IF(C28<20,"A+")))) -> ECA | O28: =D28*G28 -> 24 | P28: =E28*G28 -> 29 | Q28: =G28*F28 -> 26.5
B29: ESF | C29: =(D29+F29+E29)/2 -> 13 | D29: 13 | E29: 13 | F29: 0 | G29: 1 | H29: =C29*G29 -> 13 | L29: =IF(C29<11,"NA",IF(C29<15,"ECA",IF(C29<18,"A",IF(C29<20,"A+")))) -> ECA | O29: =D29*G29 -> 13 | P29: =E29*G29 -> 13 | Q29: =G29*F29 -> 0
B30: Travail Manuel | C30: =(D30+F30+E30)/2 -> 15.75 | D30: 16 | E30: 0 | F30: 15.5 | G30: 1 | H30: =C30*G30 -> 15.75 | L30: =IF(C30<11,"NA",IF(C30<15,"ECA",IF(C30<18,"A",IF(C30<20,"A+")))) -> A | O30: =D30*G30 -> 16 | P30: =E30*G30 -> 0 | Q30: =G30*F30 -> 15.5
B31: Total du GROUPE IV : | O31: =SUM(O5:O30) -> 257.37 | P31: =SUM(P5:P30) -> 255.0125 | Q31: =SUM(Q5:Q30) -> 292.9
B32: Moyenne du Groupe : | C32: =(SUM(H27:H30)/SUM(G27:G30)) -> 13.75 | G32: Rang de l’élève : | O32: 30 | P32: 28 | Q32: 29
O33: =O31/O32 -> 8.579 | P33: =P31/P32 -> 9.1075893 | Q33: =Q31/Q32 -> 10.1
B34: Total Général (GI + GII + GIII+GIV) = | C34: Moy Gle de la Classe : | F34: Moy du 1er : | I34: Moy du Dernier :
C35: TRIM 1 | D35: TRIM 2 | E35: TRIM 3
B36: Moyennes de l’Elève : | C36: =O33 -> 8.579 | D36: =P33 -> 9.1075893 | E36: =Q33 -> 10.1 | F36: MOY ANNUELLE | G36: =(H5+H6+H7+H8+H9+H13+H14+H15+H20+H16+H21+H22+H23+H27+H28+H29+H30)/30 -> 9.4170278 | H36: /20 | I36: Rang de l’élève : | L36: /20
B38: v La moyenne Annuelle n’est pas égale à la moyenne arithmétique des trimestres
B39: DECISIONS ET OBSERVATIONS / Décisions And Observations
B40: DISCIPLINE / Disciplin | C40: Appréciation du travail de l’élève | G40: TRAVAIL / Academic Work
B41: Nb d’Heures : | C41: =IF(G36<11,"NA",IF(G36<15,"ECA",IF(G36<18,"A",IF(G36<20,"A+")))) -> NA | D41: =IF(#REF!<11,"NA",IF(#REF!<15,"ECA",IF(#REF!<18,"A",IF(#REF!<20,"A+")))) -> #REF! | F41: =IF(#REF!<11,"NA",IF(#REF!<15,"ECA",IF(#REF!<18,"A",IF(#REF!<20,"A+")))) -> #REF!
B42: Nb de jrnées : | C42: =IF(#REF!<11,"NA",IF(#REF!<15,"ECA",IF(#REF!<18,"A",IF(#REF!<20,"A+")))) -> #REF! | D42: =IF(#REF!<11,"NA",IF(#REF!<15,"ECA",IF(#REF!<18,"A",IF(#REF!<20,"A+")))) -> #REF! | F42: =IF(#REF!<11,"NA",IF(#REF!<15,"ECA",IF(#REF!<18,"A",IF(#REF!<20,"A+")))) -> #REF! | G42: Tableau d’honneur / Honour roll | K42: Observations et Visa du Principal
B43: Exclusions / Suspensions | C43: =IF(#REF!<11,"NA",IF(#REF!<15,"ECA",IF(#REF!<18,"A",IF(#REF!<20,"A+")))) -> #REF! | D43: =IF(#REF!<11,"NA",IF(#REF!<15,"ECA",IF(#REF!<18,"A",IF(#REF!<20,"A+")))) -> #REF! | F43: =IF(#REF!<11,"NA",IF(#REF!<15,"ECA",IF(#REF!<18,"A",IF(#REF!<20,"A+")))) -> #REF! | G43: Encouragements / Encouragements | K43: Observations and Signature of Principal
B44: Blâme / Blame | C44: Observations et Remarques du Professeur Principal | G44: Félicitations / Congratulations
B45: Avertissements / Warnings | G45: Décisions du Conseil de Classe | K45: Yaoundé le
B46: Observations et Remarques du parent de l’élève | K46: Le Principal

Sheet APOUOBOUE
B4: MATIERES | C4: ANNUEL | D4: TRIM 1 | E4: TRIM 2 | F4: TRIM 3 | G4: Coef | H4: Moy × Coef | I4: Moy Gle Classe | K4: Rang | L4: Appréciations
B5: Anglais | C5: =(D5+F5+E5)/3 -> 4.75 | D5: 5.5 | E5: 3 | F5: 5.75 | G5: 3 | H5: =C5*G5 -> 14.25 | L5: =IF(C5<11,"NA",IF(C5<15,"ECA",IF(C5<18,"A",IF(C5<20,"A+")))) -> NA | O5: =D5*G5 -> 16.5 | P5: =E5*G5 -> 9 | Q5: =G5*F5 -> 17.25
B6: Cor Orthographique/ Dictée | C6: =(D6+F6+E6)/3 -> 1.9083333 | D6: 1.6 | E6: 1 | F6: 3.125 | G6: 1 | H6: =C6*G6 -> 1.9083333 | L6: =IF(C6<11,"NA",IF(C6<15,"ECA",IF(C6<18,"A",IF(C6<20,"A+")))) -> NA | O6: =D6*G6 -> 1.6 | P6: =E6*G6 -> 1 | Q6: =G6*F6 -> 3.125
B7: Etude de Texte | C7: =(D7+F7+E7)/3 -> 4.75 | D7: 6.5 | E7: 1 | F7: 6.75 | G7: 2 | H7: =C7*G7 -> 9.5 | L7: =IF(C7<11,"NA",IF(C7<15,"ECA",IF(C7<18,"A",IF(C7<20,"A+")))) -> NA | O7: =D7*G7 -> 13 | P7: =E7*G7 -> 2 | Q7: =G7*F7 -> 13.5
B8: Expression Ecrite | C8: =(D8+F8+E8)/3 -> 6.315 | D8: 5.515 | E8: 7.93 | F8: 5.5 | G8: 1 | H8: =C8*G8 -> 6.315 | L8: =IF(C8<11,"NA",IF(C8<15,"ECA",IF(C8<18,"A",IF(C8<20,"A+")))) -> NA | O8: =D8*G8 -> 5.515 | P8: =E8*G8 -> 7.93 | Q8: =G8*F8 -> 5.5
B9: Langue Vivante II | C9: =(D9+F9+E9)/2 -> 7.5 | D9: 7.25 | E9: 0 | F9: 7.75 | G9: 2 | H9: =C9*G9 -> 15 | L9: =IF(C9<11,"NA",IF(C9<15,"ECA",IF(C9<18,"A",IF(C9<20,"A+")))) -> NA | O9: =D9*G9 -> 14.5 | P9: =E9*G9 -> 0 | Q9: =G9*F9 -> 15.5
B10: Total du GROUPE I :
B11: Moyenne du Groupe : | C11: =(SUM(H5:H9)/SUM(G5:G9)) -> 5.2192593 | G11: Rang de l’élève :
B13: ECM | C13: =(D13+F13+E13)/3 -> 9.2666667 | D13: 11.425 | E13: 10.5 | F13: 5.875 | G13: 2 | H13: =C13*G13 -> 18.533333 | L13: =IF(C13<11,"NA",IF(C13<15,"ECA",IF(C13<18,"A",IF(C13<20,"A+")))) -> NA | O13: =D13*G13 -> 22.85 | P13: =E13*G13 -> 21 | Q13: =G13*F13 -> 11.75
B14: Géographie | C14: =(D14+F14+E14)/3 -> 6.9166667 | D14: 3 | E14: 10 | F14: 7.75 | G14: 1.5 | H14: =C14*G14 -> 10.375 | L14: =IF(C14<11,"NA",IF(C14<15,"ECA",IF(C14<18,"A",IF(C14<20,"A+")))) -> NA | O14: =D14*G14 -> 4.5 | P14: =E14*G14 -> 15 | Q14: =G14*F14 -> 11.625
B15: Histoire | C15: =(D15+F15+E15)/3 -> 8.5 | D15: 8.5 | E15: 10.5 | F15: 6.5 | G15: 1.5 | H15: =C15*G15 -> 12.75 | L15: =IF(C15<11,"NA",IF(C15<15,"ECA",IF(C15<18,"A",IF(C15<20,"A+")))) -> NA | O15: =D15*G15 -> 12.75 | P15: =E15*G15 -> 15.75 | Q15: =G15*F15 -> 9.75
B16: LCN | C16: =(D16+F16+E16)/3 -> 8.9583333 | D16: 8.875 | E16: 8 | F16: 10 | G16: 1 | H16: =C16*G16 -> 8.9583333 | L16: =IF(C16<11,"NA",IF(C16<15,"ECA",IF(C16<18,"A",IF(C16<20,"A+")))) -> NA | O16: =D16*G16 -> 8.875 | P16: =E16*G16 -> 8 | Q16: =G16*F16 -> 10
B17: Total du GROUPE II :
B18: Moyenne du Groupe : | C18: =(SUM(H13:H16)/SUM(G13:G16)) -> 8.4361111 | G18: Rang de l’élève :
B20: Informatique | C20: =(D20+F20+E20)/3 -> 6.6166667 | D20: 5.175 | E20: 7.55 | F20: 7.125 | G20: 2 | H20: =C20*G20 -> 13.233333 | L20: =IF(C20<11,"NA",IF(C20<15,"ECA",IF(C20<18,"A",IF(C20<20,"A+")))) -> NA | O20: =D20*G20 -> 10.35 | P20: =E20*G20 -> 15.1 | Q20: =G20*F20 -> 14.25
B21: Mathématiques | C21: =(D21+F21+E21)/3 -> 4.8633333 | D21: 3.94 | E21: 6.75 | F21: 3.9 | G21: 4 | H21: =C21*G21 -> 19.453333 | L21: =IF(C21<11,"NA",IF(C21<15,"ECA",IF(C21<18,"A",IF(C21<20,"A+")))) -> NA | O21: =D21*G21 -> 15.76 | P21: =E21*G21 -> 27 | Q21: =G21*F21 -> 15.6
B22: PCT | C22: =(D22+F22+E22)/3 -> 5.2583333 | D22: 7.05 | E22: 4.7 | F22: 4.025 | G22: 2 | H22: =C22*G22 -> 10.516667 | L22: =IF(C22<11,"NA",IF(C22<15,"ECA",IF(C22<18,"A",IF(C22<20,"A+")))) -> NA | O22: =D22*G22 -> 14.1 | P22: =E22*G22 -> 9.4 | Q22: =G22*F22 -> 8.05
B23: SVTEEHB | C23: =(D23+F23+E23)/3 -> 7.7166667 | D23: 9.375 | E23: 5.6 | F23: 8.175 | G23: 2 | H23: =C23*G23 -> 15.433333 | L23: =IF(C23<11,"NA",IF(C23<15,"ECA",IF(C23<18,"A",IF(C23<20,"A+")))) -> NA | O23: =D23*G23 -> 18.75 | P23: =E23*G23 -> 11.2 | Q23: =G23*F23 -> 16.35
B24: Total du GROUPE III :
B25: Moyenne du Groupe : | C25: =(SUM(H20:H23)/SUM(G20:G23)) -> 5.8636667 | G25: Rang de l’élève :
B27: EAC | C27: =(D27+F27+E27)/2 -> 11.75 | D27: 11.5 | E27: 0 | F27: 12 | G27: 1 | H27: =C27*G27 -> 11.75 | L27: =IF(C27<11,"NA",IF(C27<15,"ECA",IF(C27<18,"A",IF(C27<20,"A+")))) -> ECA | O27: =D27*G27 -> 11.5 | P27: =E27*G27 -> 0 | Q27: =G27*F27 -> 12
B28: EPS | C28: =(D28+F28+E28)/3 -> 11.708333 | D28: 13.25 | E28: 14 | F28: 7.875 | G28: 2 | H28: =C28*G28 -> 23.416667 | L28: =IF(C28<11,"NA",IF(C28<15,"ECA",IF(C28<18,"A",IF(C28<20,"A+")))) -> ECA | O28: =D28*G28 -> 26.5 | P28: =E28*G28 -> 28 | Q28: =G28*F28 -> 15.75
B29: ESF | C29: =(D29+F29+E29) -> 11 | D29: 11 | E29: 0 | F29: 0 | G29: 1 | H29: =C29*G29 -> 11 | L29: =IF(C29<11,"NA",IF(C29<15,"ECA",IF(C29<18,"A",IF(C29<20,"A+")))) -> ECA | O29: =D29*G29 -> 11 | P29: =E29*G29 -> 0 | Q29: =G29*F29 -> 0
B30: Travail Manuel | C30: =(D30+F30+E30)/2 -> 14.75 | D30: 14 | E30: 0 | F30: 15.5 | G30: 1 | H30: =C30*G30 -> 14.75 | L30: =IF(C30<11,"NA",IF(C30<15,"ECA",IF(C30<18,"A",IF(C30<20,"A+")))) -> ECA | O30: =D30*G30 -> 14 | P30: =E30*G30 -> 0 | Q30: =G30*F30 -> 15.5
B31: Total du GROUPE IV : | O31: =SUM(O5:O30) -> 222.05 | P31: =SUM(P5:P30) -> 170.38 | Q31: =SUM(Q5:Q30) -> 195.5
B32: Moyenne du Groupe : | C32: =(SUM(H27:H30)/SUM(G27:G30)) -> 12.183333 | G32: Rang de l’élève : | O32: 30 | P32: 26 | Q32: 29
O33: =O31/O32 -> 7.4016667 | P33: =P31/P32 -> 6.5530769 | Q33: =Q31/Q32 -> 6.7413793
B34: Total Général (GI + GII + GIII+GIV) = | C34: Moy Gle de la Classe : | F34: Moy du 1er : | I34: Moy du Dernier :
C35: TRIM 1 | D35: TRIM 2 | E35: TRIM 3
B36: Moyennes de l’Elève : | C36: =O33 -> 7.4016667 | D36: =P33 -> 6.5530769 | E36: =Q33 -> 6.7413793 | F36: MOY ANNUELLE | G36: =(H5+H6+H7+H8+H9+H13+H14+H15+H20+H16+H21+H22+H23+H27+H28+H29+H30)/30 -> 7.2381111 | H36: /20 | I36: Rang de l’élève : | L36: /20
B38: v La moyenne Annuelle n’est pas égale à la moyenne arithmétique des trimestres
B39: DECISIONS ET OBSERVATIONS / Décisions And Observations
B40: DISCIPLINE / Disciplin | C40: Appréciation du travail de l’élève | G40: TRAVAIL / Academic Work
B41: Nb d’Heures : | C41: =IF(G36<11,"NA",IF(G36<15,"ECA",IF(G36<18,"A",IF(G36<20,"A+")))) -> NA | D41: =IF(#REF!<11,"NA",IF(#REF!<15,"ECA",IF(#REF!<18,"A",IF(#REF!<20,"A+")))) -> #REF! | F41: =IF(#REF!<11,"NA",IF(#REF!<15,"ECA",IF(#REF!<18,"A",IF(#REF!<20,"A+")))) -> #REF!
B42: Nb de jrnées : | C42: =IF(#REF!<11,"NA",IF(#REF!<15,"ECA",IF(#REF!<18,"A",IF(#REF!<20,"A+")))) -> #REF! | D42: =IF(#REF!<11,"NA",IF(#REF!<15,"ECA",IF(#REF!<18,"A",IF(#REF!<20,"A+")))) -> #REF! | F42: =IF(#REF!<11,"NA",IF(#REF!<15,"ECA",IF(#REF!<18,"A",IF(#REF!<20,"A+")))) -> #REF! | G42: Tableau d’honneur / Honour roll | K42: Observations et Visa du Principal
B43: Exclusions / Suspensions | C43: =IF(#REF!<11,"NA",IF(#REF!<15,"ECA",IF(#REF!<18,"A",IF(#REF!<20,"A+")))) -> #REF! | D43: =IF(#REF!<11,"NA",IF(#REF!<15,"ECA",IF(#REF!<18,"A",IF(#REF!<20,"A+")))) -> #REF! | F43: =IF(#REF!<11,"NA",IF(#REF!<15,"ECA",IF(#REF!<18,"A",IF(#REF!<20,"A+")))) -> #REF! | G43: Encouragements / Encouragements | K43: Observations and Signature of Principal
B44: Blâme / Blame | C44: Observations et Remarques du Professeur Principal | G44: Félicitations / Congratulations
B45: Avertissements / Warnings | G45: Décisions du Conseil de Classe | K45: Yaoundé le
B46: Observations et Remarques du parent de l’élève | K46: Le Principal

Sheet DJOUMKOUA
B4: MATIERES | C4: ANNUEL | D4: TRIM 1 | E4: TRIM 2 | F4: TRIM 3 | G4: Coef | H4: Moy × Coef | I4: Moy Gle Classe | K4: Rang | L4: Appréciations
B5: Anglais | C5: =(D5+F5+E5)/3 -> 4.0666667 | D5: 3.5 | E5: 4.7 | F5: 4 | G5: 3 | H5: =C5*G5 -> 12.2 | L5: =IF(C5<11,"NA",IF(C5<15,"ECA",IF(C5<18,"A",IF(C5<20,"A+")))) -> NA | O5: =D5*G5 -> 10.5 | P5: =E5*G5 -> 14.1 | Q5: =G5*F5 -> 12
B6: Cor Orthographique/ Dictée | C6: =(D6+F6+E6)/3 -> 3.0333333 | D6: 1.35 | E6: 1.25 | F6: 6.5 | G6: 1 | H6: =C6*G6 -> 3.0333333 | L6: =IF(C6<11,"NA",IF(C6<15,"ECA",IF(C6<18,"A",IF(C6<20,"A+")))) -> NA | O6: =D6*G6 -> 1.35 | P6: =E6*G6 -> 1.25 | Q6: =G6*F6 -> 6.5
B7: Etude de Texte | C7: =(D7+F7+E7)/3 -> 9.6 | D7: 8.6 | E7: 7.2 | F7: 13 | G7: 2 | H7: =C7*G7 -> 19.2 | L7: =IF(C7<11,"NA",IF(C7<15,"ECA",IF(C7<18,"A",IF(C7<20,"A+")))) -> NA | O7: =D7*G7 -> 17.2 | P7: =E7*G7 -> 14.4 | Q7: =G7*F7 -> 26
B8: Expression Ecrite | C8: =(D8+F8+E8)/3 -> 7.5283333 | D8: 6.835 | E8: 6.75 | F8: 9 | G8: 1 | H8: =C8*G8 -> 7.5283333 | L8: =IF(C8<11,"NA",IF(C8<15,"ECA",IF(C8<18,"A",IF(C8<20,"A+")))) -> NA | O8: =D8*G8 -> 6.835 | P8: =E8*G8 -> 6.75 | Q8: =G8*F8 -> 9
B9: Langue Vivante II | C9: =(D9+F9+E9)/3 -> 6.025 | D9: 6.05 | E9: 6.775 | F9: 5.25 | G9: 2 | H9: =C9*G9 -> 12.05 | L9: =IF(C9<11,"NA",IF(C9<15,"ECA",IF(C9<18,"A",IF(C9<20,"A+")))) -> NA | O9: =D9*G9 -> 12.1 | P9: =E9*G9 -> 13.55 | Q9: =G9*F9 -> 10.5
B10: Total du GROUPE I :
B11: Moyenne du Groupe : | C11: =(SUM(H5:H9)/SUM(G5:G9)) -> 6.0012963 | G11: Rang de l’élève :
B13: ECM | C13: =(D13+F13+E13)/3 -> 8.225 | D13: 8.875 | E13: 8.8 | F13: 7 | G13: 2 | H13: =C13*G13 -> 16.45 | L13: =IF(C13<11,"NA",IF(C13<15,"ECA",IF(C13<18,"A",IF(C13<20,"A+")))) -> NA | O13: =D13*G13 -> 17.75 | P13: =E13*G13 -> 17.6 | Q13: =G13*F13 -> 14
B14: Géographie | C14: =(D14+F14+E14)/3 -> 10.408333 | D14: 7.375 | E14: 11.85 | F14: 12 | G14: 1.5 | H14: =C14*G14 -> 15.6125 | L14: =IF(C14<11,"NA",IF(C14<15,"ECA",IF(C14<18,"A",IF(C14<20,"A+")))) -> NA | O14: =D14*G14 -> 11.0625 | P14: =E14*G14 -> 17.775 | Q14: =G14*F14 -> 18
B15: Histoire | C15: =(D15+F15+E15)/3 -> 8.3833333 | D15: 7.2 | E15: 9.45 | F15: 8.5 | G15: 1.5 | H15: =C15*G15 -> 12.575 | L15: =IF(C15<11,"NA",IF(C15<15,"ECA",IF(C15<18,"A",IF(C15<20,"A+")))) -> NA | O15: =D15*G15 -> 10.8 | P15: =E15*G15 -> 14.175 | Q15: =G15*F15 -> 12.75
B16: LCN | C16: =(D16+F16+E16)/3 -> 10.608333 | D16: 9.625 | E16: 12.2 | F16: 10 | G16: 1 | H16: =C16*G16 -> 10.608333 | L16: =IF(C16<11,"NA",IF(C16<15,"ECA",IF(C16<18,"A",IF(C16<20,"A+")))) -> NA | O16: =D16*G16 -> 9.625 | P16: =E16*G16 -> 12.2 | Q16: =G16*F16 -> 10
B17: Total du GROUPE II :
B18: Moyenne du Groupe : | C18: =(SUM(H13:H16)/SUM(G13:G16)) -> 9.2076389 | G18: Rang de l’élève :
B20: Informatique | C20: =(D20+F20+E20)/3 -> 7.725 | D20: 4.55 | E20: 9.375 | F20: 9.25 | G20: 2 | H20: =C20*G20 -> 15.45 | L20: =IF(C20<11,"NA",IF(C20<15,"ECA",IF(C20<18,"A",IF(C20<20,"A+")))) -> NA | O20: =D20*G20 -> 9.1 | P20: =E20*G20 -> 18.75 | Q20: =G20*F20 -> 18.5
B21: Mathématiques | C21: =(D21+F21+E21)/3 -> 4.0833333 | D21: 5.075 | E21: 5.175 | F21: 2 | G21: 4 | H21: =C21*G21 -> 16.333333 | L21: =IF(C21<11,"NA",IF(C21<15,"ECA",IF(C21<18,"A",IF(C21<20,"A+")))) -> NA | O21: =D21*G21 -> 20.3 | P21: =E21*G21 -> 20.7 | Q21: =G21*F21 -> 8
B22: PCT | C22: =(D22+F22+E22)/3 -> 5.7583333 | D22: 3.95 | E22: 9.075 | F22: 4.25 | G22: 2 | H22: =C22*G22 -> 11.516667 | L22: =IF(C22<11,"NA",IF(C22<15,"ECA",IF(C22<18,"A",IF(C22<20,"A+")))) -> NA | O22: =D22*G22 -> 7.9 | P22: =E22*G22 -> 18.15 | Q22: =G22*F22 -> 8.5
B23: SVTEEHB | C23: =(D23+F23+E23)/3 -> 7.0083333 | D23: 8.475 | E23: 6.3 | F23: 6.25 | G23: 2 | H23: =C23*G23 -> 14.016667 | L23: =IF(C23<11,"NA",IF(C23<15,"ECA",IF(C23<18,"A",IF(C23<20,"A+")))) -> NA | O23: =D23*G23 -> 16.95 | P23: =E23*G23 -> 12.6 | Q23: =G23*F23 -> 12.5
B24: Total du GROUPE III :
B25: Moyenne du Groupe : | C25: =(SUM(H20:H23)/SUM(G20:G23)) -> 5.7316667 | G25: Rang de l’élève :
B27: EAC | C27: =(D27+F27+E27) -> 13.5 | D27: 13.5 | E27: 0 | F27: 0 | G27: 1 | H27: =C27*G27 -> 13.5 | L27: =IF(C27<11,"NA",IF(C27<15,"ECA",IF(C27<18,"A",IF(C27<20,"A+")))) -> ECA | O27: =D27*G27 -> 13.5 | P27: =E27*G27 -> 0 | Q27: =G27*F27 -> 0
B28: EPS | C28: =(D28+F28+E28)/3 -> 10.083333 | D28: 12.5 | E28: 11.75 | F28: 6 | G28: 2 | H28: =C28*G28 -> 20.166667 | L28: =IF(C28<11,"NA",IF(C28<15,"ECA",IF(C28<18,"A",IF(C28<20,"A+")))) -> NA | O28: =D28*G28 -> 25 | P28: =E28*G28 -> 23.5 | Q28: =G28*F28 -> 12
B29: ESF | C29: =(D29+F29+E29)/2 -> 13.75 | D29: 13.5 | E29: 14 | F29: 0 | G29: 1 | H29: =C29*G29 -> 13.75 | L29: =IF(C29<11,"NA",IF(C29<15,"ECA",IF(C29<18,"A",IF(C29<20,"A+")))) -> ECA | O29: =D29*G29 -> 13.5 | P29: =E29*G29 -> 14 | Q29: =G29*F29 -> 0
B30: Travail Manuel | C30: =(D30+F30+E30)/2 -> 15.75 | D30: 14.5 | E30: 0 | F30: 17 | G30: 1 | H30: =C30*G30 -> 15.75 | L30: =IF(C30<11,"NA",IF(C30<15,"ECA",IF(C30<18,"A",IF(C30<20,"A+")))) -> A | O30: =D30*G30 -> 14.5 | P30: =E30*G30 -> 0 | Q30: =G30*F30 -> 17
B31: Total du GROUPE IV : | O31: =SUM(O5:O30) -> 217.9725 | P31: =SUM(P5:P30) -> 219.5 | Q31: =SUM(Q5:Q30) -> 195.25
B32: Moyenne du Groupe : | C32: =(SUM(H27:H30)/SUM(G27:G30)) -> 12.633333 | G32: Rang de l’élève : | O32: 30 | P32: 28 | Q32: 28
O33: =O31/O32 -> 7.26575 | P33: =P31/P32 -> 7.8392857 | Q33: =Q31/Q32 -> 6.9732143
B34: Total Général (GI + GII + GIII+GIV) = | C34: Moy Gle de la Classe : | F34: Moy du 1er : | I34: Moy du Dernier :
C35: TRIM 1 | D35: TRIM 2 | E35: TRIM 3
B36: Moyennes de l’Elève : | C36: =O33 -> 7.26575 | D36: =P33 -> 7.8392857 | E36: =Q33 -> 6.9732143 | F36: MOY ANNUELLE | G36: =(H5+H6+H7+H8+H9+H13+H14+H15+H20+H16+H21+H22+H23+H27+H28+H29+H30)/30 -> 7.6580278 | H36: /20 | I36: Rang de l’élève : | L36: /20
B38: v La moyenne Annuelle n’est pas égale à la moyenne arithmétique des trimestres
B39: DECISIONS ET OBSERVATIONS / Décisions And Observations
B40: DISCIPLINE / Disciplin | C40: Appréciation du travail de l’élève | G40: TRAVAIL / Academic Work
B41: Nb d’Heures : | C41: =IF(G36<11,"NA",IF(G36<15,"ECA",IF(G36<18,"A",IF(G36<20,"A+")))) -> NA | D41: =IF(#REF!<11,"NA",IF(#REF!<15,"ECA",IF(#REF!<18,"A",IF(#REF!<20,"A+")))) -> #REF! | F41: =IF(#REF!<11,"NA",IF(#REF!<15,"ECA",IF(#REF!<18,"A",IF(#REF!<20,"A+")))) -> #REF!
B42: Nb de jrnées : | C42: =IF(#REF!<11,"NA",IF(#REF!<15,"ECA",IF(#REF!<18,"A",IF(#REF!<20,"A+")))) -> #REF! | D42: =IF(#REF!<11,"NA",IF(#REF!<15,"ECA",IF(#REF!<18,"A",IF(#REF!<20,"A+")))) -> #REF! | F42: =IF(#REF!<11,"NA",IF(#REF!<15,"ECA",IF(#REF!<18,"A",IF(#REF!<20,"A+")))) -> #REF! | G42: Tableau d’honneur / Honour roll | K42: Observations et Visa du Principal
B43: Exclusions / Suspensions | C43: =IF(#REF!<11,"NA",IF(#REF!<15,"ECA",IF(#REF!<18,"A",IF(#REF!<20,"A+")))) -> #REF! | D43: =IF(#REF!<11,"NA",IF(#REF!<15,"ECA",IF(#REF!<18,"A",IF(#REF!<20,"A+")))) -> #REF! | F43: =IF(#REF!<11,"NA",IF(#REF!<15,"ECA",IF(#REF!<18,"A",IF(#REF!<20,"A+")))) -> #REF! | G43: Encouragements / Encouragements | K43: Observations and Signature of Principal
B44: Blâme / Blame | C44: Observations et Remarques du Professeur Principal | G44: Félicitations / Congratulations
B45: Avertissements / Warnings | G45: Décisions du Conseil de Classe | K45: Yaoundé le
B46: Observations et Remarques du parent de l’élève | K46: Le Principal

Sheet ELOLONGUE
B4: MATIERES | C4: ANNUEL | D4: TRIM 1 | E4: TRIM 2 | F4: TRIM 3 | G4: Coef | H4: Moy × Coef | I4: Moy Gle Classe | K4: Rang | L4: Appréciations
B5: Anglais | C5: =(D5+F5+E5)/3 -> 9.475 | D5: 9.7 | E5: 9.6 | F5: 9.125 | G5: 3 | H5: =C5*G5 -> 28.425 | L5: =IF(C5<11,"NA",IF(C5<15,"ECA",IF(C5<18,"A",IF(C5<20,"A+")))) -> NA | O5: =D5*G5 -> 29.1 | P5: =E5*G5 -> 28.8 | Q5: =G5*F5 -> 27.375
B6: Cor Orthographique/ Dictée | C6: =(D6+F6+E6)/3 -> 5.8883333 | D6: 3.9 | E6: 3.515 | F6: 10.25 | G6: 1 | H6: =C6*G6 -> 5.8883333 | L6: =IF(C6<11,"NA",IF(C6<15,"ECA",IF(C6<18,"A",IF(C6<20,"A+")))) -> NA | O6: =D6*G6 -> 3.9 | P6: =E6*G6 -> 3.515 | Q6: =G6*F6 -> 10.25
B7: Etude de Texte | C7: =(D7+F7+E7)/3 -> 11.571667 | D7: 11 | E7: 11.965 | F7: 11.75 | G7: 2 | H7: =C7*G7 -> 23.143333 | L7: =IF(C7<11,"NA",IF(C7<15,"ECA",IF(C7<18,"A",IF(C7<20,"A+")))) -> ECA | O7: =D7*G7 -> 22 | P7: =E7*G7 -> 23.93 | Q7: =G7*F7 -> 23.5
B8: Expression Ecrite | C8: =(D8+F8+E8)/3 -> 10.638333 | D8: 11.065 | E8: 11.1 | F8: 9.75 | G8: 1 | H8: =C8*G8 -> 10.638333 | L8: =IF(C8<11,"NA",IF(C8<15,"ECA",IF(C8<18,"A",IF(C8<20,"A+")))) -> NA | O8: =D8*G8 -> 11.065 | P8: =E8*G8 -> 11.1 | Q8: =G8*F8 -> 9.75
B9: Langue Vivante II | C9: =(D9+F9+E9)/3 -> 9.9216667 | D9: 6 | E9: 12.9 | F9: 10.865 | G9: 2 | H9: =C9*G9 -> 19.843333 | L9: =IF(C9<11,"NA",IF(C9<15,"ECA",IF(C9<18,"A",IF(C9<20,"A+")))) -> NA | O9: =D9*G9 -> 12 | P9: =E9*G9 -> 25.8 | Q9: =G9*F9 -> 21.73
B10: Total du GROUPE I :
B11: Moyenne du Groupe : | C11: =(SUM(H5:H9)/SUM(G5:G9)) -> 9.7709259 | G11: Rang de l’élève :
B13: ECM | C13: =(D13+F13+E13)/3 -> 11.091667 | D13: 13 | E13: 12.15 | F13: 8.125 | G13: 2 | H13: =C13*G13 -> 22.183333 | L13: =IF(C13<11,"NA",IF(C13<15,"ECA",IF(C13<18,"A",IF(C13<20,"A+")))) -> ECA | O13: =D13*G13 -> 26 | P13: =E13*G13 -> 24.3 | Q13: =G13*F13 -> 16.25
B14: Géographie | C14: =(D14+F14+E14)/3 -> 12.508333 | D14: 9.25 | E14: 14.25 | F14: 14.025 | G14: 1.5 | H14: =C14*G14 -> 18.7625 | L14: =IF(C14<11,"NA",IF(C14<15,"ECA",IF(C14<18,"A",IF(C14<20,"A+")))) -> ECA | O14: =D14*G14 -> 13.875 | P14: =E14*G14 -> 21.375 | Q14: =G14*F14 -> 21.0375
B15: Histoire | C15: =(D15+F15+E15)/3 -> 10.216667 | D15: 10.55 | E15: 10.85 | F15: 9.25 | G15: 1.5 | H15: =C15*G15 -> 15.325 | L15: =IF(C15<11,"NA",IF(C15<15,"ECA",IF(C15<18,"A",IF(C15<20,"A+")))) -> NA | O15: =D15*G15 -> 15.825 | P15: =E15*G15 -> 16.275 | Q15: =G15*F15 -> 13.875
B16: LCN | C16: =(D16+F16+E16)/3 -> 12.058333 | D16: 10.875 | E16: 12.3 | F16: 13 | G16: 1 | H16: =C16*G16 -> 12.058333 | L16: =IF(C16<11,"NA",IF(C16<15,"ECA",IF(C16<18,"A",IF(C16<20,"A+")))) -> ECA | O16: =D16*G16 -> 10.875 | P16: =E16*G16 -> 12.3 | Q16: =G16*F16 -> 13
B17: Total du GROUPE II :
B18: Moyenne du Groupe : | C18: =(SUM(H13:H16)/SUM(G13:G16)) -> 11.388194 | G18: Rang de l’élève :
B20: Informatique | C20: =(D20+F20+E20)/3 -> 10.2 | D20: 10.35 | E20: 10.25 | F20: 10 | G20: 2 | H20: =C20*G20 -> 20.4 | L20: =IF(C20<11,"NA",IF(C20<15,"ECA",IF(C20<18,"A",IF(C20<20,"A+")))) -> NA | O20: =D20*G20 -> 20.7 | P20: =E20*G20 -> 20.5 | Q20: =G20*F20 -> 20
B21: Mathématiques | C21: =(D21+F21+E21)/3 -> 4.8966667 | D21: 5.9 | E21: 4.49 | F21: 4.3 | G21: 4 | H21: =C21*G21 -> 19.586667 | L21: =IF(C21<11,"NA",IF(C21<15,"ECA",IF(C21<18,"A",IF(C21<20,"A+")))) -> NA | O21: =D21*G21 -> 23.6 | P21: =E21*G21 -> 17.96 | Q21: =G21*F21 -> 17.2
B22: PCT | C22: =(D22+F22+E22)/3 -> 8.9166667 | D22: 8.25 | E22: 9.9 | F22: 8.6 | G22: 2 | H22: =C22*G22 -> 17.833333 | L22: =IF(C22<11,"NA",IF(C22<15,"ECA",IF(C22<18,"A",IF(C22<20,"A+")))) -> NA | O22: =D22*G22 -> 16.5 | P22: =E22*G22 -> 19.8 | Q22: =G22*F22 -> 17.2
B23: SVTEEHB | C23: =(D23+F23+E23)/3 -> 12.616667 | D23: 13.35 | E23: 11.9 | F23: 12.6 | G23: 2 | H23: =C23*G23 -> 25.233333 | L23: =IF(C23<11,"NA",IF(C23<15,"ECA",IF(C23<18,"A",IF(C23<20,"A+")))) -> ECA | O23: =D23*G23 -> 26.7 | P23: =E23*G23 -> 23.8 | Q23: =G23*F23 -> 25.2
B24: Total du GROUPE III :
B25: Moyenne du Groupe : | C25: =(SUM(H20:H23)/SUM(G20:G23)) -> 8.3053333 | G25: Rang de l’élève :
B27: EAC | C27: =(D27+F27+E27)/2 -> 13.75 | D27: 13.5 | E27: 0 | F27: 14 | G27: 1 | H27: =C27*G27 -> 13.75 | L27: =IF(C27<11,"NA",IF(C27<15,"ECA",IF(C27<18,"A",IF(C27<20,"A+")))) -> ECA | O27: =D27*G27 -> 13.5 | P27: =E27*G27 -> 0 | Q27: =G27*F27 -> 14
B28: EPS | C28: =(D28+F28+E28)/3 -> 13.416667 | D28: 12.75 | E28: 15.125 | F28: 12.375 | G28: 2 | H28: =C28*G28 -> 26.833333 | L28: =IF(C28<11,"NA",IF(C28<15,"ECA",IF(C28<18,"A",IF(C28<20,"A+")))) -> ECA | O28: =D28*G28 -> 25.5 | P28: =E28*G28 -> 30.25 | Q28: =G28*F28 -> 24.75
B29: ESF | C29: =(D29+F29+E29)/2 -> 13.75 | D29: 14 | E29: 13.5 | F29: 0 | G29: 1 | H29: =C29*G29 -> 13.75 | L29: =IF(C29<11,"NA",IF(C29<15,"ECA",IF(C29<18,"A",IF(C29<20,"A+")))) -> ECA | O29: =D29*G29 -> 14 | P29: =E29*G29 -> 13.5 | Q29: =G29*F29 -> 0
B30: Travail Manuel | C30: =(D30+F30+E30)/2 -> 15 | D30: 14.5 | E30: 0 | F30: 15.5 | G30: 1 | H30: =C30*G30 -> 15 | L30: =IF(C30<11,"NA",IF(C30<15,"ECA",IF(C30<18,"A",IF(C30<20,"A+")))) -> A | O30: =D30*G30 -> 14.5 | P30: =E30*G30 -> 0 | Q30: =G30*F30 -> 15.5
B31: Total du GROUPE IV : | O31: =SUM(O5:O30) -> 299.64 | P31: =SUM(P5:P30) -> 293.205 | Q31: =SUM(Q5:Q30) -> 290.6175
B32: Moyenne du Groupe : | C32: =(SUM(H27:H30)/SUM(G27:G30)) -> 13.866667 | G32: Rang de l’élève : | O32: 30 | P32: 28 | Q32: 29
O33: =O31/O32 -> 9.988 | P33: =P31/P32 -> 10.471607 | Q33: =Q31/Q32 -> 10.021293
B34: Total Général (GI + GII + GIII+GIV) = | C34: Moy Gle de la Classe : | F34: Moy du 1er : | I34: Moy du Dernier :
C35: TRIM 1 | D35: TRIM 2 | E35: TRIM 3
B36: Moyennes de l’Elève : | C36: =O33 -> 9.988 | D36: =P33 -> 10.471607 | E36: =Q33 -> 10.021293 | F36: MOY ANNUELLE | G36: =(H5+H6+H7+H8+H9+H13+H14+H15+H20+H16+H21+H22+H23+H27+H28+H29+H30)/30 -> 10.288472 | H36: /20 | I36: Rang de l’élève : | L36: /20
B38: v La moyenne Annuelle n’est pas égale à la moyenne arithmétique des trimestres
B39: DECISIONS ET OBSERVATIONS / Décisions And Observations
B40: DISCIPLINE / Disciplin | C40: Appréciation du travail de l’élève | G40: TRAVAIL / Academic Work
B41: Nb d’Heures : | C41: =IF(G36<11,"NA",IF(G36<15,"ECA",IF(G36<18,"A",IF(G36<20,"A+")))) -> NA | D41: =IF(#REF!<11,"NA",IF(#REF!<15,"ECA",IF(#REF!<18,"A",IF(#REF!<20,"A+")))) -> #REF! | F41: =IF(#REF!<11,"NA",IF(#REF!<15,"ECA",IF(#REF!<18,"A",IF(#REF!<20,"A+")))) -> #REF!
B42: Nb de jrnées : | C42: =IF(#REF!<11,"NA",IF(#REF!<15,"ECA",IF(#REF!<18,"A",IF(#REF!<20,"A+")))) -> #REF! | D42: =IF(#REF!<11,"NA",IF(#REF!<15,"ECA",IF(#REF!<18,"A",IF(#REF!<20,"A+")))) -> #REF! | F42: =IF(#REF!<11,"NA",IF(#REF!<15,"ECA",IF(#REF!<18,"A",IF(#REF!<20,"A+")))) -> #REF! | G42: Tableau d’honneur / Honour roll | K42: Observations et Visa du Principal
B43: Exclusions / Suspensions | C43: =IF(#REF!<11,"NA",IF(#REF!<15,"ECA",IF(#REF!<18,"A",IF(#REF!<20,"A+")))) -> #REF! | D43: =IF(#REF!<11,"NA",IF(#REF!<15,"ECA",IF(#REF!<18,"A",IF(#REF!<20,"A+")))) -> #REF! | F43: =IF(#REF!<11,"NA",IF(#REF!<15,"ECA",IF(#REF!<18,"A",IF(#REF!<20,"A+")))) -> #REF! | G43: Encouragements / Encouragements | K43: Observations and Signature of Principal
B44: Blâme / Blame | C44: Observations et Remarques du Professeur Principal | G44: Félicitations / Congratulations
B45: Avertissements / Warnings | G45: Décisions du Conseil de Classe | K45: Yaoundé le
B46: Observations et Remarques du parent de l’élève | K46: Le Principal

Sheet EYENGA
B4: MATIERES | C4: ANNUEL | D4: TRIM 1 | E4: TRIM 2 | F4: TRIM 3 | G4: Coef | H4: Moy × Coef | I4: Moy Gle Classe | K4: Rang | L4: Appréciations
B5: Anglais | C5: =(D5+F5+E5)/3 -> 7.6083333 | D5: 8.4 | E5: 8.8 | F5: 5.625 | G5: 3 | H5: =C5*G5 -> 22.825 | L5: =IF(C5<11,"NA",IF(C5<15,"ECA",IF(C5<18,"A",IF(C5<20,"A+")))) -> NA | O5: =D5*G5 -> 25.2 | P5: =E5*G5 -> 26.4 | Q5: =G5*F5 -> 16.875
B6: Cor Orthographique/ Dictée | C6: =(D6+F6+E6)/3 -> 6.9266667 | D6: 4.05 | E6: 3.48 | F6: 13.25 | G6: 1 | H6: =C6*G6 -> 6.9266667 | L6: =IF(C6<11,"NA",IF(C6<15,"ECA",IF(C6<18,"A",IF(C6<20,"A+")))) -> NA | O6: =D6*G6 -> 4.05 | P6: =E6*G6 -> 3.48 | Q6: =G6*F6 -> 13.25
B7: Etude de Texte | C7: =(D7+F7+E7)/3 -> 10.3 | D7: 12.15 | E7: 11 | F7: 7.75 | G7: 2 | H7: =C7*G7 -> 20.6 | L7: =IF(C7<11,"NA",IF(C7<15,"ECA",IF(C7<18,"A",IF(C7<20,"A+")))) -> NA | O7: =D7*G7 -> 24.3 | P7: =E7*G7 -> 22 | Q7: =G7*F7 -> 15.5
B8: Expression Ecrite | C8: =(D8+F8+E8)/3 -> 9.4616667 | D8: 9.785 | E8: 8.1 | F8: 10.5 | G8: 1 | H8: =C8*G8 -> 9.4616667 | L8: =IF(C8<11,"NA",IF(C8<15,"ECA",IF(C8<18,"A",IF(C8<20,"A+")))) -> NA | O8: =D8*G8 -> 9.785 | P8: =E8*G8 -> 8.1 | Q8: =G8*F8 -> 10.5
B9: Langue Vivante II | C9: =(D9+F9+E9)/3 -> 9.9083333 | D9: 12.15 | E9: 10.7 | F9: 6.875 | G9: 2 | H9: =C9*G9 -> 19.816667 | L9: =IF(C9<11,"NA",IF(C9<15,"ECA",IF(C9<18,"A",IF(C9<20,"A+")))) -> NA | O9: =D9*G9 -> 24.3 | P9: =E9*G9 -> 21.4 | Q9: =G9*F9 -> 13.75
B10: Total du GROUPE I :
B11: Moyenne du Groupe : | C11: =(SUM(H5:H9)/SUM(G5:G9)) -> 8.8477778 | G11: Rang de l’élève :
B13: ECM | C13: =(D13+F13+E13)/3 -> 10.266667 | D13: 10.4 | E13: 11.15 | F13: 9.25 | G13: 2 | H13: =C13*G13 -> 20.533333 | L13: =IF(C13<11,"NA",IF(C13<15,"ECA",IF(C13<18,"A",IF(C13<20,"A+")))) -> NA | O13: =D13*G13 -> 20.8 | P13: =E13*G13 -> 22.3 | Q13: =G13*F13 -> 18.5
B14: Géographie | C14: =(D14+F14+E14)/3 -> 11.258333 | D14: 6.25 | E14: 13.75 | F14: 13.775 | G14: 1.5 | H14: =C14*G14 -> 16.8875 | L14: =IF(C14<11,"NA",IF(C14<15,"ECA",IF(C14<18,"A",IF(C14<20,"A+")))) -> ECA | O14: =D14*G14 -> 9.375 | P14: =E14*G14 -> 20.625 | Q14: =G14*F14 -> 20.6625
B15: Histoire | C15: =(D15+F15+E15)/3 -> 7.9666667 | D15: 8.35 | E15: 7.55 | F15: 8 | G15: 1.5 | H15: =C15*G15 -> 11.95 | L15: =IF(C15<11,"NA",IF(C15<15,"ECA",IF(C15<18,"A",IF(C15<20,"A+")))) -> NA | O15: =D15*G15 -> 12.525 | P15: =E15*G15 -> 11.325 | Q15: =G15*F15 -> 12
B16: LCN | C16: =(D16+F16+E16)/3 -> 10.1 | D16: 8.5 | E16: 11.8 | F16: 10 | G16: 1 | H16: =C16*G16 -> 10.1 | L16: =IF(C16<11,"NA",IF(C16<15,"ECA",IF(C16<18,"A",IF(C16<20,"A+")))) -> NA | O16: =D16*G16 -> 8.5 | P16: =E16*G16 -> 11.8 | Q16: =G16*F16 -> 10
B17: Total du GROUPE II :
B18: Moyenne du Groupe : | C18: =(SUM(H13:H16)/SUM(G13:G16)) -> 9.9118056 | G18: Rang de l’élève :
B20: Informatique | C20: =(D20+F20+E20)/3 -> 9.8416667 | D20: 9.15 | E20: 10.125 | F20: 10.25 | G20: 2 | H20: =C20*G20 -> 19.683333 | L20: =IF(C20<11,"NA",IF(C20<15,"ECA",IF(C20<18,"A",IF(C20<20,"A+")))) -> NA | O20: =D20*G20 -> 18.3 | P20: =E20*G20 -> 20.25 | Q20: =G20*F20 -> 20.5
B21: Mathématiques | C21: =(D21+F21+E21)/3 -> 5.2583333 | D21: 7.235 | E21: 4.09 | F21: 4.45 | G21: 4 | H21: =C21*G21 -> 21.033333 | L21: =IF(C21<11,"NA",IF(C21<15,"ECA",IF(C21<18,"A",IF(C21<20,"A+")))) -> NA | O21: =D21*G21 -> 28.94 | P21: =E21*G21 -> 16.36 | Q21: =G21*F21 -> 17.8
B22: PCT | C22: =(D22+F22+E22)/3 -> 6.2583333 | D22: 7.8 | E22: 4.975 | F22: 6 | G22: 2 | H22: =C22*G22 -> 12.516667 | L22: =IF(C22<11,"NA",IF(C22<15,"ECA",IF(C22<18,"A",IF(C22<20,"A+")))) -> NA | O22: =D22*G22 -> 15.6 | P22: =E22*G22 -> 9.95 | Q22: =G22*F22 -> 12
B23: SVTEEHB | C23: =(D23+F23+E23)/3 -> 9.675 | D23: 9.4 | E23: 11.5 | F23: 8.125 | G23: 2 | H23: =C23*G23 -> 19.35 | L23: =IF(C23<11,"NA",IF(C23<15,"ECA",IF(C23<18,"A",IF(C23<20,"A+")))) -> NA | O23: =D23*G23 -> 18.8 | P23: =E23*G23 -> 23 | Q23: =G23*F23 -> 16.25
B24: Total du GROUPE III :
B25: Moyenne du Groupe : | C25: =(SUM(H20:H23)/SUM(G20:G23)) -> 7.2583333 | G25: Rang de l’élève :
B27: EAC | C27: =(D27+F27+E27)/3 -> 9.6666667 | D27: 12 | E27: 0 | F27: 17 | G27: 1 | H27: =C27*G27 -> 9.6666667 | L27: =IF(C27<11,"NA",IF(C27<15,"ECA",IF(C27<18,"A",IF(C27<20,"A+")))) -> NA | O27: =D27*G27 -> 12 | P27: =E27*G27 -> 0 | Q27: =G27*F27 -> 17
B28: EPS | C28: =(D28+F28+E28)/3 -> 12.208333 | D28: 12.5 | E28: 14.125 | F28: 10 | G28: 2 | H28: =C28*G28 -> 24.416667 | L28: =IF(C28<11,"NA",IF(C28<15,"ECA",IF(C28<18,"A",IF(C28<20,"A+")))) -> ECA | O28: =D28*G28 -> 25 | P28: =E28*G28 -> 28.25 | Q28: =G28*F28 -> 20
B29: ESF | C29: =(D29+F29+E29)/2 -> 15 | D29: 13 | E29: 17 | F29: 0 | G29: 1 | H29: =C29*G29 -> 15 | L29: =IF(C29<11,"NA",IF(C29<15,"ECA",IF(C29<18,"A",IF(C29<20,"A+")))) -> A | O29: =D29*G29 -> 13 | P29: =E29*G29 -> 17 | Q29: =G29*F29 -> 0
B30: Travail Manuel | C30: =(D30+F30+E30)/3 -> 10.166667 | D30: 15 | E30: 0 | F30: 15.5 | G30: 1 | H30: =C30*G30 -> 10.166667 | L30: =IF(C30<11,"NA",IF(C30<15,"ECA",IF(C30<18,"A",IF(C30<20,"A+")))) -> NA | O30: =D30*G30 -> 15 | P30: =E30*G30 -> 0 | Q30: =G30*F30 -> 15.5
B31: Total du GROUPE IV : | O31: =SUM(O5:O30) -> 285.475 | P31: =SUM(P5:P30) -> 262.24 | Q31: =SUM(Q5:Q30) -> 250.0875
B32: Moyenne du Groupe : | C32: =(SUM(H27:H30)/SUM(G27:G30)) -> 11.85 | G32: Rang de l’élève : | O32: 30 | P32: 28 | Q32: 29
O33: =O31/O32 -> 9.5158333 | P33: =P31/P32 -> 9.3657143 | Q33: =Q31/Q32 -> 8.6237069
B34: Total Général (GI + GII + GIII+GIV) = | C34: Moy Gle de la Classe : | F34: Moy du 1er : | I34: Moy du Dernier :
C35: TRIM 1 | D35: TRIM 2 | E35: TRIM 3
B36: Moyennes de l’Elève : | C36: =O33 -> 9.5158333 | D36: =P33 -> 9.3657143 | E36: =Q33 -> 8.6237069 | F36: MOY ANNUELLE | G36: =(H5+H6+H7+H8+H9+H13+H14+H15+H20+H16+H21+H22+H23+H27+H28+H29+H30)/30 -> 9.0311389 | H36: /20 | I36: Rang de l’élève : | L36: /20
B38: v La moyenne Annuelle n’est pas égale à la moyenne arithmétique des trimestres
B39: DECISIONS ET OBSERVATIONS / Décisions And Observations
B40: DISCIPLINE / Disciplin | C40: Appréciation du travail de l’élève | G40: TRAVAIL / Academic Work
B41: Nb d’Heures : | C41: =IF(G36<11,"NA",IF(G36<15,"ECA",IF(G36<18,"A",IF(G36<20,"A+")))) -> NA | D41: =IF(#REF!<11,"NA",IF(#REF!<15,"ECA",IF(#REF!<18,"A",IF(#REF!<20,"A+")))) -> #REF! | F41: =IF(#REF!<11,"NA",IF(#REF!<15,"ECA",IF(#REF!<18,"A",IF(#REF!<20,"A+")))) -> #REF!
B42: Nb de jrnées : | C42: =IF(#REF!<11,"NA",IF(#REF!<15,"ECA",IF(#REF!<18,"A",IF(#REF!<20,"A+")))) -> #REF! | D42: =IF(#REF!<11,"NA",IF(#REF!<15,"ECA",IF(#REF!<18,"A",IF(#REF!<20,"A+")))) -> #REF! | F42: =IF(#REF!<11,"NA",IF(#REF!<15,"ECA",IF(#REF!<18,"A",IF(#REF!<20,"A+")))) -> #REF! | G42: Tableau d’honneur / Honour roll | K42: Observations et Visa du Principal
B43: Exclusions / Suspensions | C43: =IF(#REF!<11,"NA",IF(#REF!<15,"ECA",IF(#REF!<18,"A",IF(#REF!<20,"A+")))) -> #REF! | D43: =IF(#REF!<11,"NA",IF(#REF!<15,"ECA",IF(#REF!<18,"A",IF(#REF!<20,"A+")))) -> #REF! | F43: =IF(#REF!<11,"NA",IF(#REF!<15,"ECA",IF(#REF!<18,"A",IF(#REF!<20,"A+")))) -> #REF! | G43: Encouragements / Encouragements | K43: Observations and Signature of Principal
B44: Blâme / Blame | C44: Observations et Remarques du Professeur Principal | G44: Félicitations / Congratulations
B45: Avertissements / Warnings | G45: Décisions du Conseil de Classe | K45: Yaoundé le
B46: Observations et Remarques du parent de l’élève | K46: Le Principal

Sheet FOE
B4: MATIERES | C4: ANNUEL | D4: TRIM 1 | E4: TRIM 2 | F4: TRIM 3 | G4: Coef | H4: Moy × Coef | I4: Moy Gle Classe | K4: Rang | L4: Appréciations
B5: Anglais | C5: =(D5+F5+E5)/2 -> 5.7875 | D5: 5.7 | F5: 5.875 | G5: 3 | H5: =C5*G5 -> 17.3625 | L5: =IF(C5<11,"NA",IF(C5<15,"ECA",IF(C5<18,"A",IF(C5<20,"A+")))) -> NA | O5: =D5*G5 -> 17.1 | P5: =E5*G5 -> 0 | Q5: =G5*F5 -> 17.625
B6: Cor Orthographique/ Dictée | C6: =(D6+F6+E6)/2 -> 8.15 | D6: 3.55 | F6: 12.75 | G6: 1 | H6: =C6*G6 -> 8.15 | L6: =IF(C6<11,"NA",IF(C6<15,"ECA",IF(C6<18,"A",IF(C6<20,"A+")))) -> NA | O6: =D6*G6 -> 3.55 | P6: =E6*G6 -> 0 | Q6: =G6*F6 -> 12.75
B7: Etude de Texte | C7: =(D7+F7+E7)/2 -> 9.625 | D7: 10 | F7: 9.25 | G7: 2 | H7: =C7*G7 -> 19.25 | L7: =IF(C7<11,"NA",IF(C7<15,"ECA",IF(C7<18,"A",IF(C7<20,"A+")))) -> NA | O7: =D7*G7 -> 20 | P7: =E7*G7 -> 0 | Q7: =G7*F7 -> 18.5
B8: Expression Ecrite | C8: =(D8+F8+E8)/2 -> 8.9575 | D8: 9.415 | F8: 8.5 | G8: 1 | H8: =C8*G8 -> 8.9575 | L8: =IF(C8<11,"NA",IF(C8<15,"ECA",IF(C8<18,"A",IF(C8<20,"A+")))) -> NA | O8: =D8*G8 -> 9.415 | P8: =E8*G8 -> 0 | Q8: =G8*F8 -> 8.5
B9: Langue Vivante II | C9: =(D9+F9+E9)/2 -> 8.925 | D9: 11.85 | F9: 6 | G9: 2 | H9: =C9*G9 -> 17.85 | L9: =IF(C9<11,"NA",IF(C9<15,"ECA",IF(C9<18,"A",IF(C9<20,"A+")))) -> NA | O9: =D9*G9 -> 23.7 | P9: =E9*G9 -> 0 | Q9: =G9*F9 -> 12
B10: Total du GROUPE I :
B11: Moyenne du Groupe : | C11: =(SUM(H5:H9)/SUM(G5:G9)) -> 7.9522222 | G11: Rang de l’élève :
B13: ECM | C13: =(D13+F13+E13)/2 -> 8.425 | D13: 8.975 | F13: 7.875 | G13: 2 | H13: =C13*G13 -> 16.85 | L13: =IF(C13<11,"NA",IF(C13<15,"ECA",IF(C13<18,"A",IF(C13<20,"A+")))) -> NA | O13: =D13*G13 -> 17.95 | P13: =E13*G13 -> 0 | Q13: =G13*F13 -> 15.75
B14: Géographie | C14: =(D14+F14+E14)/2 -> 10.5625 | D14: 8 | F14: 13.125 | G14: 1.5 | H14: =C14*G14 -> 15.84375 | L14: =IF(C14<11,"NA",IF(C14<15,"ECA",IF(C14<18,"A",IF(C14<20,"A+")))) -> NA | O14: =D14*G14 -> 12 | P14: =E14*G14 -> 0 | Q14: =G14*F14 -> 19.6875
B15: Histoire | C15: =(D15+F15+E15)/2 -> 7.95 | D15: 6.9 | F15: 9 | G15: 1.5 | H15: =C15*G15 -> 11.925 | L15: =IF(C15<11,"NA",IF(C15<15,"ECA",IF(C15<18,"A",IF(C15<20,"A+")))) -> NA | O15: =D15*G15 -> 10.35 | P15: =E15*G15 -> 0 | Q15: =G15*F15 -> 13.5
B16: LCN | C16: =(D16+F16+E16)/2 -> 12.125 | D16: 12 | F16: 12.25 | G16: 1 | H16: =C16*G16 -> 12.125 | L16: =IF(C16<11,"NA",IF(C16<15,"ECA",IF(C16<18,"A",IF(C16<20,"A+")))) -> ECA | O16: =D16*G16 -> 12 | P16: =E16*G16 -> 0 | Q16: =G16*F16 -> 12.25
B17: Total du GROUPE II :
B18: Moyenne du Groupe : | C18: =(SUM(H13:H16)/SUM(G13:G16)) -> 9.4572917 | G18: Rang de l’élève :
B20: Informatique | C20: =(D20+F20+E20)/2 -> 8.375 | D20: 7.875 | F20: 8.875 | G20: 2 | H20: =C20*G20 -> 16.75 | L20: =IF(C20<11,"NA",IF(C20<15,"ECA",IF(C20<18,"A",IF(C20<20,"A+")))) -> NA | O20: =D20*G20 -> 15.75 | P20: =E20*G20 -> 0 | Q20: =G20*F20 -> 17.75
B21: Mathématiques | C21: =(D21+F21+E21)/2 -> 4.9125 | D21: 5.575 | F21: 4.25 | G21: 4 | H21: =C21*G21 -> 19.65 | L21: =IF(C21<11,"NA",IF(C21<15,"ECA",IF(C21<18,"A",IF(C21<20,"A+")))) -> NA | O21: =D21*G21 -> 22.3 | P21: =E21*G21 -> 0 | Q21: =G21*F21 -> 17
B22: PCT | C22: =(D22+F22+E22)/2 -> 5.9 | D22: 7.175 | F22: 4.625 | G22: 2 | H22: =C22*G22 -> 11.8 | L22: =IF(C22<11,"NA",IF(C22<15,"ECA",IF(C22<18,"A",IF(C22<20,"A+")))) -> NA | O22: =D22*G22 -> 14.35 | P22: =E22*G22 -> 0 | Q22: =G22*F22 -> 9.25
B23: SVTEEHB | C23: =(D23+F23+E23)/2 -> 7.9625 | D23: 9.8 | F23: 6.125 | G23: 2 | H23: =C23*G23 -> 15.925 | L23: =IF(C23<11,"NA",IF(C23<15,"ECA",IF(C23<18,"A",IF(C23<20,"A+")))) -> NA | O23: =D23*G23 -> 19.6 | P23: =E23*G23 -> 0 | Q23: =G23*F23 -> 12.25
B24: Total du GROUPE III :
B25: Moyenne du Groupe : | C25: =(SUM(H20:H23)/SUM(G20:G23)) -> 6.4125 | G25: Rang de l’élève :
B27: EAC | C27: =(D27+F27+E27)/2 -> 11.75 | D27: 11.5 | F27: 12 | G27: 1 | H27: =C27*G27 -> 11.75 | L27: =IF(C27<11,"NA",IF(C27<15,"ECA",IF(C27<18,"A",IF(C27<20,"A+")))) -> ECA | O27: =D27*G27 -> 11.5 | P27: =E27*G27 -> 0 | Q27: =G27*F27 -> 12
B28: EPS | C28: =(D28+F28+E28)/2 -> 10.9375 | D28: 14.25 | F28: 7.625 | G28: 2 | H28: =C28*G28 -> 21.875 | L28: =IF(C28<11,"NA",IF(C28<15,"ECA",IF(C28<18,"A",IF(C28<20,"A+")))) -> NA | O28: =D28*G28 -> 28.5 | P28: =E28*G28 -> 0 | Q28: =G28*F28 -> 15.25
B29: ESF | C29: =(D29+F29+E29) -> 12.5 | D29: 12.5 | F29: 0 | G29: 1 | H29: =C29*G29 -> 12.5 | L29: =IF(C29<11,"NA",IF(C29<15,"ECA",IF(C29<18,"A",IF(C29<20,"A+")))) -> ECA | O29: =D29*G29 -> 12.5 | P29: =E29*G29 -> 0 | Q29: =G29*F29 -> 0
B30: Travail Manuel | C30: =(D30+F30+E30)/2 -> 15 | D30: 14.5 | F30: 15.5 | G30: 1 | H30: =C30*G30 -> 15 | L30: =IF(C30<11,"NA",IF(C30<15,"ECA",IF(C30<18,"A",IF(C30<20,"A+")))) -> A | O30: =D30*G30 -> 14.5 | P30: =E30*G30 -> 0 | Q30: =G30*F30 -> 15.5
B31: Total du GROUPE IV : | O31: =SUM(O5:O30) -> 265.065 | P31: =SUM(P5:P30) -> 0 | Q31: =SUM(Q5:Q30) -> 229.5625
B32: Moyenne du Groupe : | C32: =(SUM(H27:H30)/SUM(G27:G30)) -> 12.225 | G32: Rang de l’élève : | O32: 30 | P32: 30 | Q32: 29
O33: =O31/O32 -> 8.8355 | P33: =P31/P32 -> 0 | Q33: =Q31/Q32 -> 7.9159483
B34: Total Général (GI + GII + GIII+GIV) = | C34: Moy Gle de la Classe : | F34: Moy du 1er : | I34: Moy du Dernier :
C35: TRIM 1 | D35: TRIM 2 | E35: TRIM 3
B36: Moyennes de l’Elève : | C36: =O33 -> 8.8355 | D36: =P33 -> 0 | E36: =Q33 -> 7.9159483 | F36: MOY ANNUELLE | G36: =(H5+H6+H7+H8+H9+H13+H14+H15+H20+H16+H21+H22+H23+H27+H28+H29+H30)/30 -> 8.452125 | H36: /20 | I36: Rang de l’élève : | L36: /20
B38: v La moyenne Annuelle n’est pas égale à la moyenne arithmétique des trimestres
B39: DECISIONS ET OBSERVATIONS / Décisions And Observations
B40: DISCIPLINE / Disciplin | C40: Appréciation du travail de l’élève | G40: TRAVAIL / Academic Work
B41: Nb d’Heures : | C41: =IF(G36<11,"NA",IF(G36<15,"ECA",IF(G36<18,"A",IF(G36<20,"A+")))) -> NA | D41: =IF(#REF!<11,"NA",IF(#REF!<15,"ECA",IF(#REF!<18,"A",IF(#REF!<20,"A+")))) -> #REF! | F41: =IF(#REF!<11,"NA",IF(#REF!<15,"ECA",IF(#REF!<18,"A",IF(#REF!<20,"A+")))) -> #REF!
B42: Nb de jrnées : | C42: =IF(#REF!<11,"NA",IF(#REF!<15,"ECA",IF(#REF!<18,"A",IF(#REF!<20,"A+")))) -> #REF! | D42: =IF(#REF!<11,"NA",IF(#REF!<15,"ECA",IF(#REF!<18,"A",IF(#REF!<20,"A+")))) -> #REF! | F42: =IF(#REF!<11,"NA",IF(#REF!<15,"ECA",IF(#REF!<18,"A",IF(#REF!<20,"A+")))) -> #REF! | G42: Tableau d’honneur / Honour roll | K42: Observations et Visa du Principal
B43: Exclusions / Suspensions | C43: =IF(#REF!<11,"NA",IF(#REF!<15,"ECA",IF(#REF!<18,"A",IF(#REF!<20,"A+")))) -> #REF! | D43: =IF(#REF!<11,"NA",IF(#REF!<15,"ECA",IF(#REF!<18,"A",IF(#REF!<20,"A+")))) -> #REF! | F43: =IF(#REF!<11,"NA",IF(#REF!<15,"ECA",IF(#REF!<18,"A",IF(#REF!<20,"A+")))) -> #REF! | G43: Encouragements / Encouragements | K43: Observations and Signature of Principal
B44: Blâme / Blame | C44: Observations et Remarques du Professeur Principal | G44: Félicitations / Congratulations
B45: Avertissements / Warnings | G45: Décisions du Conseil de Classe | K45: Yaoundé le
B46: Observations et Remarques du parent de l’élève | K46: Le Principal

Sheet HOTT
B4: MATIERES | C4: ANNUEL | D4: TRIM 1 | E4: TRIM 2 | F4: TRIM 3 | G4: Coef | H4: Moy × Coef | I4: Moy Gle Classe | K4: Rang | L4: Appréciations
B5: Chimie | C5: =(D5+F5+E5)/3 -> 10.933333 | D5: 11.9 | E5: 9.9 | F5: 11 | G5: 3 | H5: =C5*G5 -> 32.8 | L5: ECA | O5: =D5*G5 -> 35.7 | P5: =E5*G5 -> 29.7 | Q5: =G5*F5 -> 33
B6: informatique | C6: =(D6+F6+E6)/3 -> 9.8766667 | D6: 9.5 | E6: 9 | F6: 11.13 | G6: 3 | H6: =C6*G6 -> 29.63 | L6: =IF(C6<11,"NA",IF(C6<15,"ECA",IF(C6<18,"A",IF(C6<20,"A+")))) -> NA | O6: =D6*G6 -> 28.5 | P6: =E6*G6 -> 27 | Q6: =G6*F6 -> 33.39
B7: mathématiques | C7: =(D7+F7+E7)/3 -> 11.556667 | D7: 11.6 | E7: 11.32 | F7: 11.75 | G7: 6 | H7: =C7*G7 -> 69.34 | L7: =IF(C7<11,"NA",IF(C7<15,"ECA",IF(C7<18,"A",IF(C7<20,"A+")))) -> ECA | O7: =D7*G7 -> 69.6 | P7: =E7*G7 -> 67.92 | Q7: =G7*F7 -> 70.5
B8: Physique | C8: =(D8+F8+E8)/3 -> 10.44 | D8: 9.5 | E8: 9.82 | F8: 12 | G8: 3 | H8: =C8*G8 -> 31.32 | L8: ECA | O8: =D8*G8 -> 28.5 | P8: =E8*G8 -> 29.46 | Q8: =G8*F8 -> 36
B9: SVTEEHB | C9: =(D9+F9+E9)/3 -> 11.25 | D9: 14.9 | E9: 8.25 | F9: 10.6 | G9: 3 | H9: =C9*G9 -> 33.75 | L9: =IF(C9<11,"NA",IF(C9<15,"ECA",IF(C9<18,"A",IF(C9<20,"A+")))) -> ECA | O9: =D9*G9 -> 44.7 | P9: =E9*G9 -> 24.75 | Q9: =G9*F9 -> 31.8
B10: Total du GROUPE I :
B11: Moyenne du Groupe : | C11: =(SUM(H5:H9)/SUM(G5:G9)) -> 10.935556 | G11: Rang de l’élève :
B13: ECM | C13: =(D13+F13+E13)/3 -> 12.136667 | D13: 13.5 | E13: 12.53 | F13: 10.38 | G13: 2 | H13: =C13*G13 -> 24.273333 | L13: =IF(C13<11,"NA",IF(C13<15,"ECA",IF(C13<18,"A",IF(C13<20,"A+")))) -> ECA | O13: =D13*G13 -> 27 | P13: =E13*G13 -> 25.06 | Q13: =G13*F13 -> 20.76
B14: Géographie | C14: =(D14+F14+E14)/3 -> 13.583333 | D14: 14.85 | E14: 11.65 | F14: 14.25 | G14: 1.5 | H14: =C14*G14 -> 20.375 | L14: =IF(C14<11,"NA",IF(C14<15,"ECA",IF(C14<18,"A",IF(C14<20,"A+")))) -> ECA | O14: =D14*G14 -> 22.275 | P14: =E14*G14 -> 17.475 | Q14: =G14*F14 -> 21.375
